Workbook
Name AlcCostPerG: 'Cost Analysis'!$C$16
Name AlcoholG: 'Batch Calculator'!$D$58
Name AlcoholUsedG: 'Production Log'!$I$3
Name AuxCostPerG: 'Cost Analysis'!$C$16:$C$26
Name AuxGrams: 'Batch Calculator'!$D$58:$D$68
Name BatchCostSAR: 'Batch Calculator'!$C$24
Name BatchFormat: 'Batch Calculator'!$C$4
Name BatchSize: 'Batch Calculator'!$C$5
Name BatchUnit: 'Batch Calculator'!$C$6
Name BatchVolMl: 'Batch Calculator'!$C$22
Name ConcCostPerG: 'Cost Analysis'!$C$11
Name ConcCostPerGLoaded: 'Cost Analysis'!$C$12
Name ConcG: 'Batch Calculator'!$C$23
Name ConcPct: 'Batch Calculator'!$C$7
Name CostPerMl: 'Batch Calculator'!$C$25
Name CR2ButterPct: 'Batch Calculator'!$G$17
Name CR2CetPct: 'Batch Calculator'!$G$15
Name CR2EwaxPct: 'Batch Calculator'!$G$14
Name CR2GlyPct: 'Batch Calculator'!$G$13
Name CR2OilPct: 'Batch Calculator'!$G$16
Name CR2PresPct: 'Batch Calculator'!$G$18
Name CreamBaseG: 'Batch Calculator'!$D$63
Name D10ActivePct: 'Formula Master'!$I$4
Name DefaultBatchAlcG: Inventory!$K$2
Name DefaultBatchConcG: Inventory!$H$2
Name DPGPricePerG: 'Cost Analysis'!$C$10
Name FinishedDensity: 'Batch Calculator'!$C$8
Name FM_Active: 'Formula Master'!$F$7:$F$31
Name FM_CostG: 'Formula Master'!$H$7:$H$31
Name FM_D10: 'Formula Master'!$D$7:$D$31
Name FM_InputPct: 'Formula Master'!$C$7:$C$31
Name FM_Mat: 'Formula Master'!$B$7:$B$31
Name FormatDefaults: Lists!$A$2:$E$7
Name FormatList: Lists!$A$2:$A$7
Name GlycerinG: 'Batch Calculator'!$D$60
Name IncludeOptionals: 'Formula Master'!$C$4
Name Inv_Dens: Inventory!$E$4:$E$31
Name Inv_GramsBought: Inventory!$F$4:$F$31
Name Inv_LowJoined: Inventory!$R$31
Name Inv_LowNames: Inventory!$Q$4:$Q$31
Name Inv_Mat: Inventory!$A$4:$A$31
Name Inv_OnHand: Inventory!$K$4:$K$31
Name Inv_PackQty: Inventory!$B$4:$B$31
Name Inv_PackUnit: Inventory!$C$4:$C$31
Name Inv_PricePack: Inventory!$G$4:$G$31
Name Inv_PricePerG: Inventory!$I$4:$I$31
Name Inv_Threshold: Inventory!$L$4:$L$31
Name Inv_TotalPaid: Inventory!$H$4:$H$31
Name LogAlcG: 'Production Log'!$H$5:$H$44
Name LogConcG: 'Production Log'!$G$5:$G$44
Name LogEnd: 'Production Log'!$J$5:$J$44
Name LogID: 'Production Log'!$B$5:$B$44
Name LogMacStart: 'Production Log'!$M$5:$M$44
Name LogStart: 'Production Log'!$I$5:$I$44
Name LogStatus: 'Production Log'!$K$5:$K$44
Name MacDays: 'Production Log'!$C$3
Name MaterialsTotalSAR: 'Cost Analysis'!$C$4
Name MistGlyPct: 'Batch Calculator'!$C$13
Name MistWaterPct: 'Batch Calculator'!$C$14
Name OptPctSum: 'Formula Master'!$I$3

Sheet Dashboard
B2: A U R A · 3 7
B3: a signature luxury skin scent · Extrait — Mist — Cream · presence that stays
B6: INVESTED (SAR) | C6: STOCK VALUE (SAR) | D6: CONCENTRATE (SAR/g) | E6: BATCHES LOGGED | F6: MACERATING NOW | G6: LOW-STOCK ITEMS
B7: =TotalCapital -> 2680.35 | C7: =StockValueSAR -> 2329.35 | D7: =ConcCostPerGLoaded -> 5.7391488 | E7: =SUMPRODUCT((LogID<>"")*1) -> 0 | F7: =COUNTIF(LogStatus,"Macerating") -> 0 | G7: =SUMPRODUCT((Inv_OnHand<Inv_Threshold)*1) -> 0
B9: CURRENT BATCH — quick launch | E9: MACERATION MILESTONES
B10: Format | C10: =BatchFormat -> Extrait de Parfum | E10: Next ready window opens | G10: =IF(COUNTIFS(LogStatus,"Macerating",LogStart,"<>")=0,"—",TEXT(MIN(LogMacStart)+28,"yyyy-mm-dd")) -> —
B11: Batch | C11: =BatchSize&" "&BatchUnit -> 50 ml | E11: Next maceration complete | G11: =IF(COUNTIFS(LogStatus,"Macerating",LogStart,"<>")=0,"—",TEXT(MIN(LogMacStart)+MacDays,"yyyy-mm-dd")) -> —
B12: Concentrate to weigh (g) | C12: =ConcG -> 11.9 | E12: Batches in ready window | G12: =SUMPRODUCT((LogStatus="Macerating")*(LogStart<>"")*((TODAY()-LogStart)>=28)) -> 0
B13: Alcohol (g) | C13: =AlcoholG -> 30.6 | E13: Concentrate used to date (g) | G13: =TotalConcUsedG -> 0
B14: Estimated cost (SAR) | C14: =BatchCostSAR -> 74.816424 | E14: Alcohol used to date (g) | G14: =AlcoholUsedG -> 0
B15: Cost per ml (SAR) | C15: =CostPerMl -> 1.4963285 | E15: Maceration target (days) | G15: =MacDays -> 42
B17: INVENTORY ALERTS
B18: =IF($G$7=0,"✓ All materials stocked for at least two default batches.","⚠ Low stock — reorder: "&Inv_LowJoined) -> ✓ All materials stocked for at least two default batches.
B20: WORKFLOW
B21: 1 · Set format, size and concentration in the Batch Calculator — print it and take it to the bench.
B22: 2 · Weigh BASE → HEART → TOP, marry the concentrate 24–48 h, then dilute and start maceration.
B23: 3 · Log the batch in the Production Log — Inventory and the Maceration Tracker update themselves.
B25: ASMR personal production suite · verify against current IFRA standards before any commercial use

Sheet Formula Master
A1: ASMR — MASTER FORMULA
A2: Concentrate = 100% by weight. D10 = weighed as a 10% dilution in DPG — the % shown is the weight of the dilution.
H3: Optionals Σ | I3: =SUMIF($E$7:$E$31,"OPT",$C$7:$C$31) -> 0.015
A4: Include optional materials (Irone Alpha, Javanol): | C4: YES | H4: D10 Σ (active) | I4: =SUMIF($D$7:$D$31,"D10",$F$7:$F$31) -> 0.035
A6: Phase | B6: Material | C6: Input % | D6: D10 | E6: Optional | F6: Active % | G6: Role in the accord | H6: SAR/g (as weighed)
A7: TOP | B7: Bergamot Accord | C7: 0.09 | F7: =IF(IncludeOptionals="YES",C7,IF($E7="OPT",0,C7/(1-OptPctSum))) -> 0.09 | G7: sparkling citrus opening — photosafe accord | H7: =IF($D7="D10",0.1*INDEX(Inv_PricePerG,MATCH($B7,Inv_Mat,0))+0.9*DPGPricePerG,INDEX(Inv_PricePerG,MATCH($B7,Inv_Mat,0))) -> 2.0833333
A8: TOP | B8: Petitgrain Paraguay | C8: 0.015 | F8: =IF(IncludeOptionals="YES",C8,IF($E8="OPT",0,C8/(1-OptPctSum))) -> 0.015 | G8: green-bitter citrus leaf | H8: =IF($D8="D10",0.1*INDEX(Inv_PricePerG,MATCH($B8,Inv_Mat,0))+0.9*DPGPricePerG,INDEX(Inv_PricePerG,MATCH($B8,Inv_Mat,0))) -> 4.8611111
A9: TOP | B9: Neroli Accord | C9: 0.01 | F9: =IF(IncludeOptionals="YES",C9,IF($E9="OPT",0,C9/(1-OptPctSum))) -> 0.01 | G9: orange-flower lift | H9: =IF($D9="D10",0.1*INDEX(Inv_PricePerG,MATCH($B9,Inv_Mat,0))+0.9*DPGPricePerG,INDEX(Inv_PricePerG,MATCH($B9,Inv_Mat,0))) -> 6.0422222
A10: TOP | B10: Pink Peppercorn | C10: 0.005 | D10: D10 | F10: =IF(IncludeOptionals="YES",C10,IF($E10="OPT",0,C10/(1-OptPctSum))) -> 0.005 | G10: rosy-spicy glint | H10: =IF($D10="D10",0.1*INDEX(Inv_PricePerG,MATCH($B10,Inv_Mat,0))+0.9*DPGPricePerG,INDEX(Inv_PricePerG,MATCH($B10,Inv_Mat,0))) -> 1.6594444
A11: TOP | B11: Floralozone | C11: 0.005 | D11: D10 | F11: =IF(IncludeOptionals="YES",C11,IF($E11="OPT",0,C11/(1-OptPctSum))) -> 0.005 | G11: clean air, sea-light transparency | H11: =IF($D11="D10",0.1*INDEX(Inv_PricePerG,MATCH($B11,Inv_Mat,0))+0.9*DPGPricePerG,INDEX(Inv_PricePerG,MATCH($B11,Inv_Mat,0))) -> 0.37
A12: HEART | B12: Hedione (Firmenich) | C12: 0.2 | F12: =IF(IncludeOptionals="YES",C12,IF($E12="OPT",0,C12/(1-OptPctSum))) -> 0.2 | G12: transparent jasmine — the radiance engine | H12: =IF($D12="D10",0.1*INDEX(Inv_PricePerG,MATCH($B12,Inv_Mat,0))+0.9*DPGPricePerG,INDEX(Inv_PricePerG,MATCH($B12,Inv_Mat,0))) -> 0.88518519
A13: HEART | B13: Orange Blossom Tunisia Absolute | C13: 0.025 | F13: =IF(IncludeOptionals="YES",C13,IF($E13="OPT",0,C13/(1-OptPctSum))) -> 0.025 | G13: true white-flower warmth | H13: =IF($D13="D10",0.1*INDEX(Inv_PricePerG,MATCH($B13,Inv_Mat,0))+0.9*DPGPricePerG,INDEX(Inv_PricePerG,MATCH($B13,Inv_Mat,0))) -> 43.5
A14: HEART | B14: Methyl Alpha Ionone Iso | C14: 0.04 | F14: =IF(IncludeOptionals="YES",C14,IF($E14="OPT",0,C14/(1-OptPctSum))) -> 0.04 | G14: powdery orris-violet velvet | H14: =IF($D14="D10",0.1*INDEX(Inv_PricePerG,MATCH($B14,Inv_Mat,0))+0.9*DPGPricePerG,INDEX(Inv_PricePerG,MATCH($B14,Inv_Mat,0))) -> 1.94
A15: HEART | B15: Irone Alpha | C15: 0.01 | D15: D10 | E15: OPT | F15: =IF(IncludeOptionals="YES",C15,IF($E15="OPT",0,C15/(1-OptPctSum))) -> 0.01 | G15: precious orris butter — optional luxury | H15: =IF($D15="D10",0.1*INDEX(Inv_PricePerG,MATCH($B15,Inv_Mat,0))+0.9*DPGPricePerG,INDEX(Inv_PricePerG,MATCH($B15,Inv_Mat,0))) -> 3.84
A16: HEART | B16: Benzyl Salicylate | C16: 0.03 | F16: =IF(IncludeOptionals="YES",C16,IF($E16="OPT",0,C16/(1-OptPctSum))) -> 0.03 | G16: soft balsamic blender | H16: =IF($D16="D10",0.1*INDEX(Inv_PricePerG,MATCH($B16,Inv_Mat,0))+0.9*DPGPricePerG,INDEX(Inv_PricePerG,MATCH($B16,Inv_Mat,0))) -> 1.24
A17: HEART | B17: Linalool | C17: 0.01 | F17: =IF(IncludeOptionals="YES",C17,IF($E17="OPT",0,C17/(1-OptPctSum))) -> 0.01 | G17: fresh floral smoothing | H17: =IF($D17="D10",0.1*INDEX(Inv_PricePerG,MATCH($B17,Inv_Mat,0))+0.9*DPGPricePerG,INDEX(Inv_PricePerG,MATCH($B17,Inv_Mat,0))) -> 1.86
A18: BASE | B18: Iso E Super | C18: 0.15 | F18: =IF(IncludeOptionals="YES",C18,IF($E18="OPT",0,C18/(1-OptPctSum))) -> 0.15 | G18: velvet-wood aura, skin-like halo | H18: =IF($D18="D10",0.1*INDEX(Inv_PricePerG,MATCH($B18,Inv_Mat,0))+0.9*DPGPricePerG,INDEX(Inv_PricePerG,MATCH($B18,Inv_Mat,0))) -> 1.5111111
A19: BASE | B19: Amberxan (Ambroxan) | C19: 0.08 | F19: =IF(IncludeOptionals="YES",C19,IF($E19="OPT",0,C19/(1-OptPctSum))) -> 0.08 | G19: mineral amber radiance — the 'still here' trail | H19: =IF($D19="D10",0.1*INDEX(Inv_PricePerG,MATCH($B19,Inv_Mat,0))+0.9*DPGPricePerG,INDEX(Inv_PricePerG,MATCH($B19,Inv_Mat,0))) -> 13.375
A20: BASE | B20: Cashmeran IFF | C20: 0.025 | F20: =IF(IncludeOptionals="YES",C20,IF($E20="OPT",0,C20/(1-OptPctSum))) -> 0.025 | G20: cashmere musk-wood | H20: =IF($D20="D10",0.1*INDEX(Inv_PricePerG,MATCH($B20,Inv_Mat,0))+0.9*DPGPricePerG,INDEX(Inv_PricePerG,MATCH($B20,Inv_Mat,0))) -> 6.2066667
A21: BASE | B21: Sandal Spicatum Australia | C21: 0.04 | F21: =IF(IncludeOptionals="YES",C21,IF($E21="OPT",0,C21/(1-OptPctSum))) -> 0.04 | G21: creamy natural sandalwood EO | H21: =IF($D21="D10",0.1*INDEX(Inv_PricePerG,MATCH($B21,Inv_Mat,0))+0.9*DPGPricePerG,INDEX(Inv_PricePerG,MATCH($B21,Inv_Mat,0))) -> 17.9
A22: BASE | B22: Sandalore (Givaudan) | C22: 0.03 | F22: =IF(IncludeOptionals="YES",C22,IF($E22="OPT",0,C22/(1-OptPctSum))) -> 0.03 | G22: smooth sandalwood glow | H22: =IF($D22="D10",0.1*INDEX(Inv_PricePerG,MATCH($B22,Inv_Mat,0))+0.9*DPGPricePerG,INDEX(Inv_PricePerG,MATCH($B22,Inv_Mat,0))) -> 2.6155556
A23: BASE | B23: Javanol | C23: 0.005 | D23: D10 | E23: OPT | F23: =IF(IncludeOptionals="YES",C23,IF($E23="OPT",0,C23/(1-OptPctSum))) -> 0.005 | G23: ultra-modern sandalwood — optional | H23: =IF($D23="D10",0.1*INDEX(Inv_PricePerG,MATCH($B23,Inv_Mat,0))+0.9*DPGPricePerG,INDEX(Inv_PricePerG,MATCH($B23,Inv_Mat,0))) -> 0.9
A24: BASE | B24: Globalide (Habanolide) | C24: 0.065 | F24: =IF(IncludeOptionals="YES",C24,IF($E24="OPT",0,C24/(1-OptPctSum))) -> 0.065 | G24: clean airy musk | H24: =IF($D24="D10",0.1*INDEX(Inv_PricePerG,MATCH($B24,Inv_Mat,0))+0.9*DPGPricePerG,INDEX(Inv_PricePerG,MATCH($B24,Inv_Mat,0))) -> 3
A25: BASE | B25: Helvetolide | C25: 0.05 | F25: =IF(IncludeOptionals="YES",C25,IF($E25="OPT",0,C25/(1-OptPctSum))) -> 0.05 | G25: fruity-ambrette musk | H25: =IF($D25="D10",0.1*INDEX(Inv_PricePerG,MATCH($B25,Inv_Mat,0))+0.9*DPGPricePerG,INDEX(Inv_PricePerG,MATCH($B25,Inv_Mat,0))) -> 5.5
A26: BASE | B26: Ambrettolide (Givaudan) | C26: 0.025 | F26: =IF(IncludeOptionals="YES",C26,IF($E26="OPT",0,C26/(1-OptPctSum))) -> 0.025 | G26: seamless skin musk | H26: =IF($D26="D10",0.1*INDEX(Inv_PricePerG,MATCH($B26,Inv_Mat,0))+0.9*DPGPricePerG,INDEX(Inv_PricePerG,MATCH($B26,Inv_Mat,0))) -> 10.23
A27: BASE | B27: Ethylene Brassylate | C27: 0.035 | F27: =IF(IncludeOptionals="YES",C27,IF($E27="OPT",0,C27/(1-OptPctSum))) -> 0.035 | G27: soft powder musk | H27: =IF($D27="D10",0.1*INDEX(Inv_PricePerG,MATCH($B27,Inv_Mat,0))+0.9*DPGPricePerG,INDEX(Inv_PricePerG,MATCH($B27,Inv_Mat,0))) -> 1.1233333
A28: BASE | B28: Exaltolide Total (Firmenich) | C28: 0.02 | F28: =IF(IncludeOptionals="YES",C28,IF($E28="OPT",0,C28/(1-OptPctSum))) -> 0.02 | G28: warm intimate musk | H28: =IF($D28="D10",0.1*INDEX(Inv_PricePerG,MATCH($B28,Inv_Mat,0))+0.9*DPGPricePerG,INDEX(Inv_PricePerG,MATCH($B28,Inv_Mat,0))) -> 3.0588889
A29: BASE | B29: Cedarwood Virginia | C29: 0.02 | F29: =IF(IncludeOptionals="YES",C29,IF($E29="OPT",0,C29/(1-OptPctSum))) -> 0.02 | G29: dry pencil-cedar backbone | H29: =IF($D29="D10",0.1*INDEX(Inv_PricePerG,MATCH($B29,Inv_Mat,0))+0.9*DPGPricePerG,INDEX(Inv_PricePerG,MATCH($B29,Inv_Mat,0))) -> 3.6111111
A30: BASE | B30: Vetyveryle Acetate | C30: 0.005 | F30: =IF(IncludeOptionals="YES",C30,IF($E30="OPT",0,C30/(1-OptPctSum))) -> 0.005 | G30: polished vetiver whisper | H30: =IF($D30="D10",0.1*INDEX(Inv_PricePerG,MATCH($B30,Inv_Mat,0))+0.9*DPGPricePerG,INDEX(Inv_PricePerG,MATCH($B30,Inv_Mat,0))) -> 12.4
A31: BASE | B31: Safraleine | C31: 0.01 | D31: D10 | F31: =IF(IncludeOptionals="YES",C31,IF($E31="OPT",0,C31/(1-OptPctSum))) -> 0.01 | G31: saffron-leather warmth | H31: =IF($D31="D10",0.1*INDEX(Inv_PricePerG,MATCH($B31,Inv_Mat,0))+0.9*DPGPricePerG,INDEX(Inv_PricePerG,MATCH($B31,Inv_Mat,0))) -> 0.9
B33: TOTALS | C33: =SUM(C7:C31) -> 1 | F33: =SUM(F7:F31) -> 1
A34: =IF(AND(ROUND(C33,6)=1,ROUND(F33,6)=1),"✓ BALANCED — input Σ = "&TEXT(C33,"0.00%")&" · active Σ = "&TEXT(F33,"0.00%"),"⚠ FORMULA DOES NOT SUM TO 100% — check the Input % column") -> ✓ BALANCED — input Σ = 100.00% · active Σ = 100.00%
A36: Legend: | B36: OPTIONAL / extra | C36: optional materials are controlled only by the C4 toggle
B37: OVERLAPS another | C37: intentional accord layering — do not remove unless you choose a simpler formula
A38: Every other ingredient is essential to the accord. There are NO wasted materials here — each phase (top / heart / base) needs its members to smell complete.

Sheet Batch Calculator
A1: ASMR — BATCH CALCULATOR
A2: All quantities in grams. Weighing order: BASE → HEART → TOP. Champagne cells are inputs.
A3: 1 · BATCH INPUTS
A4: Product format | C4: Extrait de Parfum | D4: choose one of the six product formats
A5: Batch size | C5: 50 | D5: in the unit chosen below
A6: Size unit (ml / g) | C6: ml | D6: ml is converted to grams with the density cell below
A7: Concentrate % | C7: 0.28 | D7: ="Suggested for this format: "&TEXT(VLOOKUP(BatchFormat,FormatDefaults,2,FALSE),"0.0%")&" (range "&TEXT(VLOOKUP(BatchFormat,FormatDefaults,3,FALSE),"0.0%")&" – "&TEXT(VLOOKUP(BatchFormat,FormatDefaults,4,FALSE),"0.0%")&")" -> Suggested for this format: 28.0% (range 20.0% – 35.0%)
A8: Finished density (g/ml) | C8: 0.85 | D8: ="Typical for this format: "&TEXT(VLOOKUP(BatchFormat,FormatDefaults,5,FALSE),"0.00")&" g/ml" -> Typical for this format: 0.85 g/ml
A9: Optionals included? | C9: =IncludeOptionals -> YES | D9: optionals: Irone Alpha, Javanol — set on Formula Master
A11: 2 · FORMAT PARAMETERS (each is used only by the format named)
A12: Distilled water % (EDP) | C12: 0 | D12: EDP / Extrait — optional, max 3% | E12: CREAM ROUTE 2 — PHASE %
A13: Glycerin % (alc. mist) | C13: 0.02 | D13: Alcohol Body Mist — optional 2–3% | E13: Glycerin (water phase) | G13: 0.03
A14: Water % (alc. mist) | C14: 0.05 | D14: Alcohol Body Mist — optional 5–10% | E14: Emulsifying Wax NF | G14: 0.05
A15: Solubilizer × fragrance | C15: 4 | D15: Water Mist — Polysorbate 20 = 4–6 × fragrance wt | E15: Cetearyl alcohol | G15: 0.02
A16: Glycerin % (W-mist) | C16: 0.025 | D16: Water-Based Mist | E16: Carrier oil (light) | G16: 0.15
A17: Preservative % (W-mist) | C17: 0.008 | D17: Water-Based Mist — broad-spectrum, REQUIRED | E17: Shea / mango butter | G17: 0.05
A18: Vitamin E % (cream 2) | C18: 0.005 | D18: Cream Route 2 — cool-down antioxidant | E18: Preservative | G18: 0.01
A20: 3 · BATCH TOTALS
A21: Total batch mass (g) | C21: =IF(BatchUnit="g",BatchSize,BatchSize*FinishedDensity) -> 42.5 | D21: batch size converted to grams
A22: Batch volume (ml, approx.) | C22: =IF(BatchUnit="ml",BatchSize,BatchSize/FinishedDensity) -> 50 | D22: for cost-per-ml
A23: Fragrance concentrate (g) | C23: =TotalMassG*ConcPct -> 11.9 | D23: total to weigh from the table below
A24: Estimated batch cost (SAR) | C24: =ConcG*ConcCostPerGLoaded+SUMPRODUCT(AuxGrams,AuxCostPerG) -> 74.816424 | D24: materials incl. shipping allocation — see Cost Analysis
A25: Cost per ml (SAR) | C25: =IF(BatchVolMl=0,"",BatchCostSAR/BatchVolMl) -> 1.4963285
A27: 4 · CONCENTRATE WEIGHING (weigh in this order: BASE → HEART → TOP)
A28: Phase | B28: Material | D28: % of conc. | E28: Weigh (g) | F28: Form | G28: Neat (g) | H28: ✓
A29: BASE | B29: Iso E Super | D29: =INDEX(FM_Active,MATCH($B29,FM_Mat,0)) -> 0.15 | E29: =ConcG*D29 -> 1.785 | F29: =IF(INDEX(FM_D10,MATCH($B29,FM_Mat,0))="D10","10% in DPG","neat") -> neat | G29: =E29*IF(INDEX(FM_D10,MATCH($B29,FM_Mat,0))="D10",0.1,1) -> 1.785
A30: BASE | B30: Amberxan (Ambroxan) | D30: =INDEX(FM_Active,MATCH($B30,FM_Mat,0)) -> 0.08 | E30: =ConcG*D30 -> 0.952 | F30: =IF(INDEX(FM_D10,MATCH($B30,FM_Mat,0))="D10","10% in DPG","neat") -> neat | G30: =E30*IF(INDEX(FM_D10,MATCH($B30,FM_Mat,0))="D10",0.1,1) -> 0.952
A31: BASE | B31: Cashmeran IFF | D31: =INDEX(FM_Active,MATCH($B31,FM_Mat,0)) -> 0.025 | E31: =ConcG*D31 -> 0.2975 | F31: =IF(INDEX(FM_D10,MATCH($B31,FM_Mat,0))="D10","10% in DPG","neat") -> neat | G31: =E31*IF(INDEX(FM_D10,MATCH($B31,FM_Mat,0))="D10",0.1,1) -> 0.2975
A32: BASE | B32: Sandal Spicatum Australia | D32: =INDEX(FM_Active,MATCH($B32,FM_Mat,0)) -> 0.04 | E32: =ConcG*D32 -> 0.476 | F32: =IF(INDEX(FM_D10,MATCH($B32,FM_Mat,0))="D10","10% in DPG","neat") -> neat | G32: =E32*IF(INDEX(FM_D10,MATCH($B32,FM_Mat,0))="D10",0.1,1) -> 0.476
A33: BASE | B33: Sandalore (Givaudan) | D33: =INDEX(FM_Active,MATCH($B33,FM_Mat,0)) -> 0.03 | E33: =ConcG*D33 -> 0.357 | F33: =IF(INDEX(FM_D10,MATCH($B33,FM_Mat,0))="D10","10% in DPG","neat") -> neat | G33: =E33*IF(INDEX(FM_D10,MATCH($B33,FM_Mat,0))="D10",0.1,1) -> 0.357
A34: BASE | B34: Javanol | D34: =INDEX(FM_Active,MATCH($B34,FM_Mat,0)) -> 0.005 | E34: =ConcG*D34 -> 0.0595 | F34: =IF(INDEX(FM_D10,MATCH($B34,FM_Mat,0))="D10","10% in DPG","neat") -> 10% in DPG | G34: =E34*IF(INDEX(FM_D10,MATCH($B34,FM_Mat,0))="D10",0.1,1) -> 0.00595
A35: BASE | B35: Globalide (Habanolide) | D35: =INDEX(FM_Active,MATCH($B35,FM_Mat,0)) -> 0.065 | E35: =ConcG*D35 -> 0.7735 | F35: =IF(INDEX(FM_D10,MATCH($B35,FM_Mat,0))="D10","10% in DPG","neat") -> neat | G35: =E35*IF(INDEX(FM_D10,MATCH($B35,FM_Mat,0))="D10",0.1,1) -> 0.7735
A36: BASE | B36: Helvetolide | D36: =INDEX(FM_Active,MATCH($B36,FM_Mat,0)) -> 0.05 | E36: =ConcG*D36 -> 0.595 | F36: =IF(INDEX(FM_D10,MATCH($B36,FM_Mat,0))="D10","10% in DPG","neat") -> neat | G36: =E36*IF(INDEX(FM_D10,MATCH($B36,FM_Mat,0))="D10",0.1,1) -> 0.595
A37: BASE | B37: Ambrettolide (Givaudan) | D37: =INDEX(FM_Active,MATCH($B37,FM_Mat,0)) -> 0.025 | E37: =ConcG*D37 -> 0.2975 | F37: =IF(INDEX(FM_D10,MATCH($B37,FM_Mat,0))="D10","10% in DPG","neat") -> neat | G37: =E37*IF(INDEX(FM_D10,MATCH($B37,FM_Mat,0))="D10",0.1,1) -> 0.2975
A38: BASE | B38: Ethylene Brassylate | D38: =INDEX(FM_Active,MATCH($B38,FM_Mat,0)) -> 0.035 | E38: =ConcG*D38 -> 0.4165 | F38: =IF(INDEX(FM_D10,MATCH($B38,FM_Mat,0))="D10","10% in DPG","neat") -> neat | G38: =E38*IF(INDEX(FM_D10,MATCH($B38,FM_Mat,0))="D10",0.1,1) -> 0.4165
A39: BASE | B39: Exaltolide Total (Firmenich) | D39: =INDEX(FM_Active,MATCH($B39,FM_Mat,0)) -> 0.02 | E39: =ConcG*D39 -> 0.238 | F39: =IF(INDEX(FM_D10,MATCH($B39,FM_Mat,0))="D10","10% in DPG","neat") -> neat | G39: =E39*IF(INDEX(FM_D10,MATCH($B39,FM_Mat,0))="D10",0.1,1) -> 0.238
A40: BASE | B40: Cedarwood Virginia | D40: =INDEX(FM_Active,MATCH($B40,FM_Mat,0)) -> 0.02 | E40: =ConcG*D40 -> 0.238 | F40: =IF(INDEX(FM_D10,MATCH($B40,FM_Mat,0))="D10","10% in DPG","neat") -> neat | G40: =E40*IF(INDEX(FM_D10,MATCH($B40,FM_Mat,0))="D10",0.1,1) -> 0.238
... A53: TOP | B53: Floralozone | D53: =INDEX(FM_Active,MATCH($B53,FM_Mat,0)) -> 0.005 | E53: =ConcG*D53 -> 0.0595 | F53: =IF(INDEX(FM_D10,MATCH($B53,FM_Mat,0))="D10","10% in DPG","neat") -> 10% in DPG | G53: =E53*IF(INDEX(FM_D10,MATCH($B53,FM_Mat,0))="D10",0.1,1) -> 0.00595
A54: CONCENTRATE TOTAL (must equal the concentrate above) | E54: =SUM(E29:E53) -> 11.9 | F54: =IF(ABS(E54-ConcG)<0.005,"✓","⚠") -> ✓ | G54: =SUM(G29:G53) -> 11.52515
A56: 5 · SOLVENT & AUXILIARY COMPONENTS
...

Sheet Dilution Prep (D10)
A1: D10 DILUTIONS — 10% IN DPG
A2: Default batch: 10 g of solution = 1.0 g neat material + 9.0 g DPG. Prepare at least 24 h before blending.
A4: Material | B4: Strength | C4: Batch (g) | D4: Neat (g) | E4: DPG (g) | F4: Date made | G4: Remaining (g) | H4: Label / notes
A5: Pink Peppercorn | B5: 0.1 | C5: 10 | D5: =C5*B5 -> 1 | E5: =C5-D5 -> 9 | H5: ="ASMR · "&A5&" · 10% in DPG · "&IF(F5="","(date)",TEXT(F5,"yyyy-mm-dd")) -> ASMR · Pink Peppercorn · 10% in DPG · (date)
A6: Floralozone | B6: 0.1 | C6: 10 | D6: =C6*B6 -> 1 | E6: =C6-D6 -> 9 | H6: ="ASMR · "&A6&" · 10% in DPG · "&IF(F6="","(date)",TEXT(F6,"yyyy-mm-dd")) -> ASMR · Floralozone · 10% in DPG · (date)
A7: Irone Alpha | B7: 0.1 | C7: 10 | D7: =C7*B7 -> 1 | E7: =C7-D7 -> 9 | H7: ="ASMR · "&A7&" · 10% in DPG · "&IF(F7="","(date)",TEXT(F7,"yyyy-mm-dd")) -> ASMR · Irone Alpha · 10% in DPG · (date)
A8: Javanol | B8: 0.1 | C8: 10 | D8: =C8*B8 -> 1 | E8: =C8-D8 -> 9 | H8: ="ASMR · "&A8&" · 10% in DPG · "&IF(F8="","(date)",TEXT(F8,"yyyy-mm-dd")) -> ASMR · Javanol · 10% in DPG · (date)
A9: Safraleine | B9: 0.1 | C9: 10 | D9: =C9*B9 -> 1 | E9: =C9-D9 -> 9 | H9: ="ASMR · "&A9&" · 10% in DPG · "&IF(F9="","(date)",TEXT(F9,"yyyy-mm-dd")) -> ASMR · Safraleine · 10% in DPG · (date)
A11: 1 · Tare a clean 12–15 ml glass bottle on the scale (0.01 g resolution or better).
A12: 2 · Weigh the NEAT material first, then add DPG up to the total. Cap tightly and shake 1 minute.
A13: 3 · Label with the text in the last column. Store dark and cool. Dilutions keep 12+ months.
A14: 4 · When a dilution runs low, make a fresh 10 g batch and update 'Date made' and 'Remaining'.

Sheet Inventory
A1: INVENTORY
A2: On hand = purchases − usage from the Production Log. Prices & links verified on iterji.com (2026-07). | F2: Conc / batch (g): | H2: =50*0.85*0.28 -> 11.9 | I2: Alcohol / batch (g): | K2: =50*0.85*0.72 -> 30.6
A3: Material | B3: Pack | C3: Unit | D3: Packs | E3: Density g/ml | F3: Grams bought | G3: Price/pack SAR | H3: Paid SAR | I3: SAR/g | J3: Used (g) | K3: On hand (g) | L3: Alert < (g) | M3: Status | N3: Supplier | O3: Product link | P3: 50 ml bottles
A4: Hedione (Firmenich) | B4: 30 | C4: ml | D4: 1 | E4: 0.9 | F4: =IF(C4="ml",B4*D4*E4,B4*D4) -> 27 | G4: 23.9 | H4: =G4*D4 -> 23.9 | I4: =IF(F4=0,0,H4/F4) -> 0.88518519 | J4: =TotalConcUsedG*INDEX(FM_Active,MATCH($A4,FM_Mat,0))*IF(INDEX(FM_D10,MATCH($A4,FM_Mat,0))="D10",0.1,1) -> 0 | K4: =F4-J4 -> 27 | L4: =2*DefaultBatchConcG*INDEX(FM_Active,MATCH($A4,FM_Mat,0))*IF(INDEX(FM_D10,MATCH($A4,FM_Mat,0))="D10",0.1,1) -> 4.76 | M4: =IF(K4<L4,"LOW","OK") -> OK | N4: iterji.com | O4: open ↗ | P4: =IFERROR(FLOOR((MAX(K4,0)/(INDEX(FM_Active,MATCH($A4,FM_Mat,0))*IF(INDEX(FM_D10,MATCH($A4,FM_Mat,0))="D10",0.1,1)))/(50*YC_Density*YC_ConcPct),1),"") -> 11 | Q4: =IF(K4<L4,A4,"") | R4: =Q4
A5: Iso E Super | B5: 10 | C5: ml | D5: 1 | E5: 0.9 | F5: =IF(C5="ml",B5*D5*E5,B5*D5) -> 9 | G5: 13.6 | H5: =G5*D5 -> 13.6 | I5: =IF(F5=0,0,H5/F5) -> 1.5111111 | J5: =TotalConcUsedG*INDEX(FM_Active,MATCH($A5,FM_Mat,0))*IF(INDEX(FM_D10,MATCH($A5,FM_Mat,0))="D10",0.1,1) -> 0 | K5: =F5-J5 -> 9 | L5: =2*DefaultBatchConcG*INDEX(FM_Active,MATCH($A5,FM_Mat,0))*IF(INDEX(FM_D10,MATCH($A5,FM_Mat,0))="D10",0.1,1) -> 3.57 | M5: =IF(K5<L5,"LOW","OK") -> OK | N5: iterji.com | O5: open ↗ | P5: =IFERROR(FLOOR((MAX(K5,0)/(INDEX(FM_Active,MATCH($A5,FM_Mat,0))*IF(INDEX(FM_D10,MATCH($A5,FM_Mat,0))="D10",0.1,1)))/(50*YC_Density*YC_ConcPct),1),"") -> 5 | Q5: =IF(K5<L5,A5,"") | R5: =IF(Q5="",R4,IF(R4="",Q5,R4&", "&Q5))
A6: Amberxan (Ambroxan) | B6: 10 | C6: g | D6: 1 | F6: =IF(C6="ml",B6*D6*E6,B6*D6) -> 10 | G6: 133.75 | H6: =G6*D6 -> 133.75 | I6: =IF(F6=0,0,H6/F6) -> 13.375 | J6: =TotalConcUsedG*INDEX(FM_Active,MATCH($A6,FM_Mat,0))*IF(INDEX(FM_D10,MATCH($A6,FM_Mat,0))="D10",0.1,1) -> 0 | K6: =F6-J6 -> 10 | L6: =2*DefaultBatchConcG*INDEX(FM_Active,MATCH($A6,FM_Mat,0))*IF(INDEX(FM_D10,MATCH($A6,FM_Mat,0))="D10",0.1,1) -> 1.904 | M6: =IF(K6<L6,"LOW","OK") -> OK | N6: iterji.com | O6: open ↗ | P6: =IFERROR(FLOOR((MAX(K6,0)/(INDEX(FM_Active,MATCH($A6,FM_Mat,0))*IF(INDEX(FM_D10,MATCH($A6,FM_Mat,0))="D10",0.1,1)))/(50*YC_Density*YC_ConcPct),1),"") -> 10 | Q6: =IF(K6<L6,A6,"") | R6: =IF(Q6="",R5,IF(R5="",Q6,R5&", "&Q6))
A7: Globalide (Habanolide) | B7: 10 | C7: g | D7: 1 | F7: =IF(C7="ml",B7*D7*E7,B7*D7) -> 10 | G7: 30 | H7: =G7*D7 -> 30 | I7: =IF(F7=0,0,H7/F7) -> 3 | J7: =TotalConcUsedG*INDEX(FM_Active,MATCH($A7,FM_Mat,0))*IF(INDEX(FM_D10,MATCH($A7,FM_Mat,0))="D10",0.1,1) -> 0 | K7: =F7-J7 -> 10 | L7: =2*DefaultBatchConcG*INDEX(FM_Active,MATCH($A7,FM_Mat,0))*IF(INDEX(FM_D10,MATCH($A7,FM_Mat,0))="D10",0.1,1) -> 1.547 | M7: =IF(K7<L7,"LOW","OK") -> OK | N7: Fraterworks (intl) | O7: open ↗ | P7: =IFERROR(FLOOR((MAX(K7,0)/(INDEX(FM_Active,MATCH($A7,FM_Mat,0))*IF(INDEX(FM_D10,MATCH($A7,FM_Mat,0))="D10",0.1,1)))/(50*YC_Density*YC_ConcPct),1),"") -> 12 | Q7: =IF(K7<L7,A7,"") | R7: =IF(Q7="",R6,IF(R6="",Q7,R6&", "&Q7))
A8: Helvetolide | B8: 10 | C8: g | D8: 1 | F8: =IF(C8="ml",B8*D8*E8,B8*D8) -> 10 | G8: 55 | H8: =G8*D8 -> 55 | I8: =IF(F8=0,0,H8/F8) -> 5.5 | J8: =TotalConcUsedG*INDEX(FM_Active,MATCH($A8,FM_Mat,0))*IF(INDEX(FM_D10,MATCH($A8,FM_Mat,0))="D10",0.1,1) -> 0 | K8: =F8-J8 -> 10 | L8: =2*DefaultBatchConcG*INDEX(FM_Active,MATCH($A8,FM_Mat,0))*IF(INDEX(FM_D10,MATCH($A8,FM_Mat,0))="D10",0.1,1) -> 1.19 | M8: =IF(K8<L8,"LOW","OK") -> OK | N8: Fraterworks (intl) | O8: open ↗ | P8: =IFERROR(FLOOR((MAX(K8,0)/(INDEX(FM_Active,MATCH($A8,FM_Mat,0))*IF(INDEX(FM_D10,MATCH($A8,FM_Mat,0))="D10",0.1,1)))/(50*YC_Density*YC_ConcPct),1),"") -> 16 | Q8: =IF(K8<L8,A8,"") | R8: =IF(Q8="",R7,IF(R7="",Q8,R7&", "&Q8))
A9: Ambrettolide (Givaudan) | B9: 10 | C9: ml | D9: 1 | E9: 0.9 | F9: =IF(C9="ml",B9*D9*E9,B9*D9) -> 9 | G9: 92.07 | H9: =G9*D9 -> 92.07 | I9: =IF(F9=0,0,H9/F9) -> 10.23 | J9: =TotalConcUsedG*INDEX(FM_Active,MATCH($A9,FM_Mat,0))*IF(INDEX(FM_D10,MATCH($A9,FM_Mat,0))="D10",0.1,1) -> 0 | K9: =F9-J9 -> 9 | L9: =2*DefaultBatchConcG*INDEX(FM_Active,MATCH($A9,FM_Mat,0))*IF(INDEX(FM_D10,MATCH($A9,FM_Mat,0))="D10",0.1,1) -> 0.595 | M9: =IF(K9<L9,"LOW","OK") -> OK | N9: iterji.com | O9: open ↗ | P9: =IFERROR(FLOOR((MAX(K9,0)/(INDEX(FM_Active,MATCH($A9,FM_Mat,0))*IF(INDEX(FM_D10,MATCH($A9,FM_Mat,0))="D10",0.1,1)))/(50*YC_Density*YC_ConcPct),1),"") -> 30 | Q9: =IF(K9<L9,A9,"") | R9: =IF(Q9="",R8,IF(R8="",Q9,R8&", "&Q9))
A10: Ethylene Brassylate | B10: 10 | C10: ml | D10: 1 | E10: 0.9 | F10: =IF(C10="ml",B10*D10*E10,B10*D10) -> 9 | G10: 10.11 | H10: =G10*D10 -> 10.11 | I10: =IF(F10=0,0,H10/F10) -> 1.1233333 | J10: =TotalConcUsedG*INDEX(FM_Active,MATCH($A10,FM_Mat,0))*IF(INDEX(FM_D10,MATCH($A10,FM_Mat,0))="D10",0.1,1) -> 0 | K10: =F10-J10 -> 9 | L10: =2*DefaultBatchConcG*INDEX(FM_Active,MATCH($A10,FM_Mat,0))*IF(INDEX(FM_D10,MATCH($A10,FM_Mat,0))="D10",0.1,1) -> 0.833 | M10: =IF(K10<L10,"LOW","OK") -> OK | N10: iterji.com | O10: open ↗ | P10: =IFERROR(FLOOR((MAX(K10,0)/(INDEX(FM_Active,MATCH($A10,FM_Mat,0))*IF(INDEX(FM_D10,MATCH($A10,FM_Mat,0))="D10",0.1,1)))/(50*YC_Density*YC_ConcPct),1),"") -> 21 | Q10: =IF(K10<L10,A10,"") | R10: =IF(Q10="",R9,IF(R9="",Q10,R9&", "&Q10))
A11: Exaltolide Total (Firmenich) | B11: 10 | C11: ml | D11: 1 | E11: 0.9 | F11: =IF(C11="ml",B11*D11*E11,B11*D11) -> 9 | G11: 27.53 | H11: =G11*D11 -> 27.53 | I11: =IF(F11=0,0,H11/F11) -> 3.0588889 | J11: =TotalConcUsedG*INDEX(FM_Active,MATCH($A11,FM_Mat,0))*IF(INDEX(FM_D10,MATCH($A11,FM_Mat,0))="D10",0.1,1) -> 0 | K11: =F11-J11 -> 9 | L11: =2*DefaultBatchConcG*INDEX(FM_Active,MATCH($A11,FM_Mat,0))*IF(INDEX(FM_D10,MATCH($A11,FM_Mat,0))="D10",0.1,1) -> 0.476 | M11: =IF(K11<L11,"LOW","OK") -> OK | N11: iterji.com | O11: open ↗ | P11: =IFERROR(FLOOR((MAX(K11,0)/(INDEX(FM_Active,MATCH($A11,FM_Mat,0))*IF(INDEX(FM_D10,MATCH($A11,FM_Mat,0))="D10",0.1,1)))/(50*YC_Density*YC_ConcPct),1),"") -> 37 | Q11: =IF(K11<L11,A11,"") | R11: =IF(Q11="",R10,IF(R10="",Q11,R10&", "&Q11))
A12: Cashmeran IFF | B12: 10 | C12: ml | D12: 1 | E12: 0.9 | F12: =IF(C12="ml",B12*D12*E12,B12*D12) -> 9 | G12: 55.86 | H12: =G12*D12 -> 55.86 | I12: =IF(F12=0,0,H12/F12) -> 6.2066667 | J12: =TotalConcUsedG*INDEX(FM_Active,MATCH($A12,FM_Mat,0))*IF(INDEX(FM_D10,MATCH($A12,FM_Mat,0))="D10",0.1,1) -> 0 | K12: =F12-J12 -> 9 | L12: =2*DefaultBatchConcG*INDEX(FM_Active,MATCH($A12,FM_Mat,0))*IF(INDEX(FM_D10,MATCH($A12,FM_Mat,0))="D10",0.1,1) -> 0.595 | M12: =IF(K12<L12,"LOW","OK") -> OK | N12: iterji.com | O12: open ↗ | P12: =IFERROR(FLOOR((MAX(K12,0)/(INDEX(FM_Active,MATCH($A12,FM_Mat,0))*IF(INDEX(FM_D10,MATCH($A12,FM_Mat,0))="D10",0.1,1)))/(50*YC_Density*YC_ConcPct),1),"") -> 30 | Q12: =IF(K12<L12,A12,"") | R12: =IF(Q12="",R11,IF(R11="",Q12,R11&", "&Q12))
A13: Sandal Spicatum Australia | B13: 10 | C13: g | D13: 1 | F13: =IF(C13="ml",B13*D13*E13,B13*D13) -> 10 | G13: 179 | H13: =G13*D13 -> 179 | I13: =IF(F13=0,0,H13/F13) -> 17.9 | J13: =TotalConcUsedG*INDEX(FM_Active,MATCH($A13,FM_Mat,0))*IF(INDEX(FM_D10,MATCH($A13,FM_Mat,0))="D10",0.1,1) -> 0 | K13: =F13-J13 -> 10 | L13: =2*DefaultBatchConcG*INDEX(FM_Active,MATCH($A13,FM_Mat,0))*IF(INDEX(FM_D10,MATCH($A13,FM_Mat,0))="D10",0.1,1) -> 0.952 | M13: =IF(K13<L13,"LOW","OK") -> OK | N13: Jozoor / mygezor.com (KSA) | O13: open ↗ | P13: =IFERROR(FLOOR((MAX(K13,0)/(INDEX(FM_Active,MATCH($A13,FM_Mat,0))*IF(INDEX(FM_D10,MATCH($A13,FM_Mat,0))="D10",0.1,1)))/(50*YC_Density*YC_ConcPct),1),"") -> 21 | Q13: =IF(K13<L13,A13,"") | R13: =IF(Q13="",R12,IF(R12="",Q13,R12&", "&Q13))
A14: Sandalore (Givaudan) | B14: 10 | C14: ml | D14: 1 | E14: 0.9 | F14: =IF(C14="ml",B14*D14*E14,B14*D14) -> 9 | G14: 23.54 | H14: =G14*D14 -> 23.54 | I14: =IF(F14=0,0,H14/F14) -> 2.6155556 | J14: =TotalConcUsedG*INDEX(FM_Active,MATCH($A14,FM_Mat,0))*IF(INDEX(FM_D10,MATCH($A14,FM_Mat,0))="D10",0.1,1) -> 0 | K14: =F14-J14 -> 9 | L14: =2*DefaultBatchConcG*INDEX(FM_Active,MATCH($A14,FM_Mat,0))*IF(INDEX(FM_D10,MATCH($A14,FM_Mat,0))="D10",0.1,1) -> 0.714 | M14: =IF(K14<L14,"LOW","OK") -> OK | N14: iterji.com | O14: open ↗ | P14: =IFERROR(FLOOR((MAX(K14,0)/(INDEX(FM_Active,MATCH($A14,FM_Mat,0))*IF(INDEX(FM_D10,MATCH($A14,FM_Mat,0))="D10",0.1,1)))/(50*YC_Density*YC_ConcPct),1),"") -> 25 | Q14: =IF(K14<L14,A14,"") | R14: =IF(Q14="",R13,IF(R13="",Q14,R13&", "&Q14))
A15: Javanol | B15: 10 | C15: g | D15: 1 | F15: =IF(C15="ml",B15*D15*E15,B15*D15) -> 10 | G15: 81 | H15: =G15*D15 -> 81 | I15: =IF(F15=0,0,H15/F15) -> 8.1 | J15: =TotalConcUsedG*INDEX(FM_Active,MATCH($A15,FM_Mat,0))*IF(INDEX(FM_D10,MATCH($A15,FM_Mat,0))="D10",0.1,1) -> 0 | K15: =F15-J15 -> 10 | L15: =2*DefaultBatchConcG*INDEX(FM_Active,MATCH($A15,FM_Mat,0))*IF(INDEX(FM_D10,MATCH($A15,FM_Mat,0))="D10",0.1,1) -> 0.0119 | M15: =IF(K15<L15,"LOW","OK") -> OK | N15: Aromology (intl) | O15: open ↗ | P15: =IFERROR(FLOOR((MAX(K15,0)/(INDEX(FM_Active,MATCH($A15,FM_Mat,0))*IF(INDEX(FM_D10,MATCH($A15,FM_Mat,0))="D10",0.1,1)))/(50*YC_Density*YC_ConcPct),1),"") -> 1680 | Q15: =IF(K15<L15,A15,"") | R15: =IF(Q15="",R14,IF(R14="",Q15,R14&", "&Q15))
A16: Cedarwood Virginia | B16: 10 | C16: ml | D16: 1 | E16: 0.9 | F16: =IF(C16="ml",B16*D16*E16,B16*D16) -> 9 | G16: 32.5 | H16: =G16*D16 -> 32.5 | I16: =IF(F16=0,0,H16/F16) -> 3.6111111 | J16: =TotalConcUsedG*INDEX(FM_Active,MATCH($A16,FM_Mat,0))*IF(INDEX(FM_D10,MATCH($A16,FM_Mat,0))="D10",0.1,1) -> 0 | K16: =F16-J16 -> 9 | L16: =2*DefaultBatchConcG*INDEX(FM_Active,MATCH($A16,FM_Mat,0))*IF(INDEX(FM_D10,MATCH($A16,FM_Mat,0))="D10",0.1,1) -> 0.476 | M16: =IF(K16<L16,"LOW","OK") -> OK | N16: iterji.com | O16: open ↗ | P16: =IFERROR(FLOOR((MAX(K16,0)/(INDEX(FM_Active,MATCH($A16,FM_Mat,0))*IF(INDEX(FM_D10,MATCH($A16,FM_Mat,0))="D10",0.1,1)))/(50*YC_Density*YC_ConcPct),1),"") -> 37 | Q16: =IF(K16<L16,A16,"") | R16: =IF(Q16="",R15,IF(R15="",Q16,R15&", "&Q16))
A17: Vetyveryle Acetate | B17: 10 | C17: g | D17: 1 | F17: =IF(C17="ml",B17*D17*E17,B17*D17) -> 10 | G17: 124 | H17: =G17*D17 -> 124 | I17: =IF(F17=0,0,H17/F17) -> 12.4 | J17: =TotalConcUsedG*INDEX(FM_Active,MATCH($A17,FM_Mat,0))*IF(INDEX(FM_D10,MATCH($A17,FM_Mat,0))="D10",0.1,1) -> 0 | K17: =F17-J17 -> 10 | L17: =2*DefaultBatchConcG*INDEX(FM_Active,MATCH($A17,FM_Mat,0))*IF(INDEX(FM_D10,MATCH($A17,FM_Mat,0))="D10",0.1,1) -> 0.119 | M17: =IF(K17<L17,"LOW","OK") -> OK | N17: Perfumer's Apprentice (intl) | O17: open ↗ | P17: =IFERROR(FLOOR((MAX(K17,0)/(INDEX(FM_Active,MATCH($A17,FM_Mat,0))*IF(INDEX(FM_D10,MATCH($A17,FM_Mat,0))="D10",0.1,1)))/(50*YC_Density*YC_ConcPct),1),"") -> 168 | Q17: =IF(K17<L17,A17,"") | R17: =IF(Q17="",R16,IF(R16="",Q17,R16&", "&Q17))
A18: Methyl Alpha Ionone Iso | B18: 10 | C18: ml | D18: 1 | E18: 0.9 | F18: =IF(C18="ml",B18*D18*E18,B18*D18) -> 9 | G18: 17.46 | H18: =G18*D18 -> 17.46 | I18: =IF(F18=0,0,H18/F18) -> 1.94 | J18: =TotalConcUsedG*INDEX(FM_Active,MATCH($A18,FM_Mat,0))*IF(INDEX(FM_D10,MATCH($A18,FM_Mat,0))="D10",0.1,1) -> 0 | K18: =F18-J18 -> 9 | L18: =2*DefaultBatchConcG*INDEX(FM_Active,MATCH($A18,FM_Mat,0))*IF(INDEX(FM_D10,MATCH($A18,FM_Mat,0))="D10",0.1,1) -> 0.952 | M18: =IF(K18<L18,"LOW","OK") -> OK | N18: iterji.com | O18: open ↗ | P18: =IFERROR(FLOOR((MAX(K18,0)/(INDEX(FM_Active,MATCH($A18,FM_Mat,0))*IF(INDEX(FM_D10,MATCH($A18,FM_Mat,0))="D10",0.1,1)))/(50*YC_Density*YC_ConcPct),1),"") -> 18 | Q18: =IF(K18<L18,A18,"") | R18: =IF(Q18="",R17,IF(R17="",Q18,R17&", "&Q18))
A19: Irone Alpha | B19: 10 | C19: g | D19: 1 | F19: =IF(C19="ml",B19*D19*E19,B19*D19) -> 10 | G19: 375 | H19: =G19*D19 -> 375 | I19: =IF(F19=0,0,H19/F19) -> 37.5 | J19: =TotalConcUsedG*INDEX(FM_Active,MATCH($A19,FM_Mat,0))*IF(INDEX(FM_D10,MATCH($A19,FM_Mat,0))="D10",0.1,1) -> 0 | K19: =F19-J19 -> 10 | L19: =2*DefaultBatchConcG*INDEX(FM_Active,MATCH($A19,FM_Mat,0))*IF(INDEX(FM_D10,MATCH($A19,FM_Mat,0))="D10",0.1,1) -> 0.0238 | M19: =IF(K19<L19,"LOW","OK") -> OK | N19: iterji.com | O19: open ↗ | P19: =IFERROR(FLOOR((MAX(K19,0)/(INDEX(FM_Active,MATCH($A19,FM_Mat,0))*IF(INDEX(FM_D10,MATCH($A19,FM_Mat,0))="D10",0.1,1)))/(50*YC_Density*YC_ConcPct),1),"") -> 840 | Q19: =IF(K19<L19,A19,"") | R19: =IF(Q19="",R18,IF(R18="",Q19,R18&", "&Q19))
A20: Benzyl Salicylate | B20: 10 | C20: ml | D20: 1 | E20: 0.9 | F20: =IF(C20="ml",B20*D20*E20,B20*D20) -> 9 | G20: 11.16 | H20: =G20*D20 -> 11.16 | I20: =IF(F20=0,0,H20/F20) -> 1.24 | J20: =TotalConcUsedG*INDEX(FM_Active,MATCH($A20,FM_Mat,0))*IF(INDEX(FM_D10,MATCH($A20,FM_Mat,0))="D10",0.1,1) -> 0 | K20: =F20-J20 -> 9 | L20: =2*DefaultBatchConcG*INDEX(FM_Active,MATCH($A20,FM_Mat,0))*IF(INDEX(FM_D10,MATCH($A20,FM_Mat,0))="D10",0.1,1) -> 0.714 | M20: =IF(K20<L20,"LOW","OK") -> OK | N20: iterji.com | O20: open ↗ | P20: =IFERROR(FLOOR((MAX(K20,0)/(INDEX(FM_Active,MATCH($A20,FM_Mat,0))*IF(INDEX(FM_D10,MATCH($A20,FM_Mat,0))="D10",0.1,1)))/(50*YC_Density*YC_ConcPct),1),"") -> 25 | Q20: =IF(K20<L20,A20,"") | R20: =IF(Q20="",R19,IF(R19="",Q20,R19&", "&Q20))
A21: Linalool | B21: 10 | C21: ml | D21: 1 | E21: 0.9 | F21: =IF(C21="ml",B21*D21*E21,B21*D21) -> 9 | G21: 16.74 | H21: =G21*D21 -> 16.74 | I21: =IF(F21=0,0,H21/F21) -> 1.86 | J21: =TotalConcUsedG*INDEX(FM_Active,MATCH($A21,FM_Mat,0))*IF(INDEX(FM_D10,MATCH($A21,FM_Mat,0))="D10",0.1,1) -> 0 | K21: =F21-J21 -> 9 | L21: =2*DefaultBatchConcG*INDEX(FM_Active,MATCH($A21,FM_Mat,0))*IF(INDEX(FM_D10,MATCH($A21,FM_Mat,0))="D10",0.1,1) -> 0.238 | M21: =IF(K21<L21,"LOW","OK") -> OK | N21: iterji.com | O21: open ↗ | P21: =IFERROR(FLOOR((MAX(K21,0)/(INDEX(FM_Active,MATCH($A21,FM_Mat,0))*IF(INDEX(FM_D10,MATCH($A21,FM_Mat,0))="D10",0.1,1)))/(50*YC_Density*YC_ConcPct),1),"") -> 75 | Q21: =IF(K21<L21,A21,"") | R21: =IF(Q21="",R20,IF(R20="",Q21,R20&", "&Q21))
A22: Neroli Accord | B22: 10 | C22: ml | D22: 1 | E22: 0.9 | F22: =IF(C22="ml",B22*D22*E22,B22*D22) -> 9 | G22: 54.38 | H22: =G22*D22 -> 54.38 | I22: =IF(F22=0,0,H22/F22) -> 6.0422222 | J22: =TotalConcUsedG*INDEX(FM_Active,MATCH($A22,FM_Mat,0))*IF(INDEX(FM_D10,MATCH($A22,FM_Mat,0))="D10",0.1,1) -> 0 | K22: =F22-J22 -> 9 | L22: =2*DefaultBatchConcG*INDEX(FM_Active,MATCH($A22,FM_Mat,0))*IF(INDEX(FM_D10,MATCH($A22,FM_Mat,0))="D10",0.1,1) -> 0.238 | M22: =IF(K22<L22,"LOW","OK") -> OK | N22: iterji.com | O22: open ↗ | P22: =IFERROR(FLOOR((MAX(K22,0)/(INDEX(FM_Active,MATCH($A22,FM_Mat,0))*IF(INDEX(FM_D10,MATCH($A22,FM_Mat,0))="D10",0.1,1)))/(50*YC_Density*YC_ConcPct),1),"") -> 75 | Q22: =IF(K22<L22,A22,"") | R22: =IF(Q22="",R21,IF(R21="",Q22,R21&", "&Q22))
A23: Orange Blossom Tunisia Absolute | B23: 10 | C23: g | D23: 1 | F23: =IF(C23="ml",B23*D23*E23,B23*D23) -> 10 | G23: 435 | H23: =G23*D23 -> 435 | I23: =IF(F23=0,0,H23/F23) -> 43.5 | J23: =TotalConcUsedG*INDEX(FM_Active,MATCH($A23,FM_Mat,0))*IF(INDEX(FM_D10,MATCH($A23,FM_Mat,0))="D10",0.1,1) -> 0 | K23: =F23-J23 -> 10 | L23: =2*DefaultBatchConcG*INDEX(FM_Active,MATCH($A23,FM_Mat,0))*IF(INDEX(FM_D10,MATCH($A23,FM_Mat,0))="D10",0.1,1) -> 0.595 | M23: =IF(K23<L23,"LOW","OK") -> OK | N23: Jozoor / mygezor.com (KSA) | O23: open ↗ | P23: =IFERROR(FLOOR((MAX(K23,0)/(INDEX(FM_Active,MATCH($A23,FM_Mat,0))*IF(INDEX(FM_D10,MATCH($A23,FM_Mat,0))="D10",0.1,1)))/(50*YC_Density*YC_ConcPct),1),"") -> 33 | Q23: =IF(K23<L23,A23,"") | R23: =IF(Q23="",R22,IF(R22="",Q23,R22&", "&Q23))
A24: Petitgrain Paraguay | B24: 10 | C24: ml | D24: 1 | E24: 0.9 | F24: =IF(C24="ml",B24*D24*E24,B24*D24) -> 9 | G24: 43.75 | H24: =G24*D24 -> 43.75 | I24: =IF(F24=0,0,H24/F24) -> 4.8611111 | J24: =TotalConcUsedG*INDEX(FM_Active,MATCH($A24,FM_Mat,0))*IF(INDEX(FM_D10,MATCH($A24,FM_Mat,0))="D10",0.1,1) -> 0 | K24: =F24-J24 -> 9 | L24: =2*DefaultBatchConcG*INDEX(FM_Active,MATCH($A24,FM_Mat,0))*IF(INDEX(FM_D10,MATCH($A24,FM_Mat,0))="D10",0.1,1) -> 0.357 | M24: =IF(K24<L24,"LOW","OK") -> OK | N24: iterji.com | O24: open ↗ | P24: =IFERROR(FLOOR((MAX(K24,0)/(INDEX(FM_Active,MATCH($A24,FM_Mat,0))*IF(INDEX(FM_D10,MATCH($A24,FM_Mat,0))="D10",0.1,1)))/(50*YC_Density*YC_ConcPct),1),"") -> 50 | Q24: =IF(K24<L24,A24,"") | R24: =IF(Q24="",R23,IF(R23="",Q24,R23&", "&Q24))
A25: Pink Peppercorn | B25: 10 | C25: ml | D25: 1 | E25: 0.9 | F25: =IF(C25="ml",B25*D25*E25,B25*D25) -> 9 | G25: 141.25 | H25: =G25*D25 -> 141.25 | I25: =IF(F25=0,0,H25/F25) -> 15.694444 | J25: =TotalConcUsedG*INDEX(FM_Active,MATCH($A25,FM_Mat,0))*IF(INDEX(FM_D10,MATCH($A25,FM_Mat,0))="D10",0.1,1) -> 0 | K25: =F25-J25 -> 9 | L25: =2*DefaultBatchConcG*INDEX(FM_Active,MATCH($A25,FM_Mat,0))*IF(INDEX(FM_D10,MATCH($A25,FM_Mat,0))="D10",0.1,1) -> 0.0119 | M25: =IF(K25<L25,"LOW","OK") -> OK | N25: iterji.com | O25: open ↗ | P25: =IFERROR(FLOOR((MAX(K25,0)/(INDEX(FM_Active,MATCH($A25,FM_Mat,0))*IF(INDEX(FM_D10,MATCH($A25,FM_Mat,0))="D10",0.1,1)))/(50*YC_Density*YC_ConcPct),1),"") -> 1512 | Q25: =IF(K25<L25,A25,"") | R25: =IF(Q25="",R24,IF(R24="",Q25,R24&", "&Q25))
A26: Bergamot Accord | B26: 10 | C26: ml | D26: 1 | E26: 0.9 | F26: =IF(C26="ml",B26*D26*E26,B26*D26) -> 9 | G26: 18.75 | H26: =G26*D26 -> 18.75 | I26: =IF(F26=0,0,H26/F26) -> 2.0833333 | J26: =TotalConcUsedG*INDEX(FM_Active,MATCH($A26,FM_Mat,0))*IF(INDEX(FM_D10,MATCH($A26,FM_Mat,0))="D10",0.1,1) -> 0 | K26: =F26-J26 -> 9 | L26: =2*DefaultBatchConcG*INDEX(FM_Active,MATCH($A26,FM_Mat,0))*IF(INDEX(FM_D10,MATCH($A26,FM_Mat,0))="D10",0.1,1) -> 2.142 | M26: =IF(K26<L26,"LOW","OK") -> OK | N26: iterji.com | O26: open ↗ | P26: =IFERROR(FLOOR((MAX(K26,0)/(INDEX(FM_Active,MATCH($A26,FM_Mat,0))*IF(INDEX(FM_D10,MATCH($A26,FM_Mat,0))="D10",0.1,1)))/(50*YC_Density*YC_ConcPct),1),"") -> 8 | Q26: =IF(K26<L26,A26,"") | R26: =IF(Q26="",R25,IF(R25="",Q26,R25&", "&Q26))
A27: Bergamot Essential Oil | B27: 10 | C27: ml | D27: 1 | E27: 0.9 | F27: =IF(C27="ml",B27*D27*E27,B27*D27) -> 9 | G27: 25 | H27: =G27*D27 -> 25 | I27: =IF(F27=0,0,H27/F27) -> 2.7777778 | J27: 0 | K27: =F27-J27 -> 9 | L27: 0 | M27: =IF(K27<L27,"LOW","OK") -> OK | N27: iterji.com | O27: open ↗ | P27: 0 | Q27: =IF(K27<L27,A27,"") | R27: =IF(Q27="",R26,IF(R26="",Q27,R26&", "&Q27))
A28: Floralozone | B28: 10 | C28: g | D28: 1 | F28: =IF(C28="ml",B28*D28*E28,B28*D28) -> 10 | G28: 28 | H28: =G28*D28 -> 28 | I28: =IF(F28=0,0,H28/F28) -> 2.8 | J28: =TotalConcUsedG*INDEX(FM_Active,MATCH($A28,FM_Mat,0))*IF(INDEX(FM_D10,MATCH($A28,FM_Mat,0))="D10",0.1,1) -> 0 | K28: =F28-J28 -> 10 | L28: =2*DefaultBatchConcG*INDEX(FM_Active,MATCH($A28,FM_Mat,0))*IF(INDEX(FM_D10,MATCH($A28,FM_Mat,0))="D10",0.1,1) -> 0.0119 | M28: =IF(K28<L28,"LOW","OK") -> OK | N28: Perfumer's Apprentice (intl) | O28: open ↗ | P28: =IFERROR(FLOOR((MAX(K28,0)/(INDEX(FM_Active,MATCH($A28,FM_Mat,0))*IF(INDEX(FM_D10,MATCH($A28,FM_Mat,0))="D10",0.1,1)))/(50*YC_Density*YC_ConcPct),1),"") -> 1680 | Q28: =IF(K28<L28,A28,"") | R28: =IF(Q28="",R27,IF(R27="",Q28,R27&", "&Q28))
A29: Safraleine | B29: 10 | C29: g | D29: 1 | F29: =IF(C29="ml",B29*D29*E29,B29*D29) -> 10 | G29: 81 | H29: =G29*D29 -> 81 | I29: =IF(F29=0,0,H29/F29) -> 8.1 | J29: =TotalConcUsedG*INDEX(FM_Active,MATCH($A29,FM_Mat,0))*IF(INDEX(FM_D10,MATCH($A29,FM_Mat,0))="D10",0.1,1) -> 0 | K29: =F29-J29 -> 10 | L29: =2*DefaultBatchConcG*INDEX(FM_Active,MATCH($A29,FM_Mat,0))*IF(INDEX(FM_D10,MATCH($A29,FM_Mat,0))="D10",0.1,1) -> 0.0238 | M29: =IF(K29<L29,"LOW","OK") -> OK | N29: Perfumer's Apprentice (intl) | O29: open ↗ | P29: =IFERROR(FLOOR((MAX(K29,0)/(INDEX(FM_Active,MATCH($A29,FM_Mat,0))*IF(INDEX(FM_D10,MATCH($A29,FM_Mat,0))="D10",0.1,1)))/(50*YC_Density*YC_ConcPct),1),"") -> 840 | Q29: =IF(K29<L29,A29,"") | R29: =IF(Q29="",R28,IF(R28="",Q29,R28&", "&Q29))
A30: DPG (Dipropylene Glycol) | B30: 500 | C30: g | D30: 1 | F30: =IF(C30="ml",B30*D30*E30,B30*D30) -> 500 | G30: 50 | H30: =G30*D30 -> 50 | I30: =IF(F30=0,0,H30/F30) -> 0.1 | J30: =TotalConcUsedG*D10ActivePct*0.9 -> 0 | K30: =F30-J30 -> 500 | L30: =2*DefaultBatchConcG*D10ActivePct*0.9 -> 0.7497 | M30: =IF(K30<L30,"LOW","OK") -> OK | N30: iterji.com | O30: open ↗ | P30: =IFERROR(FLOOR((MAX(K30,0)/(D10ActivePct*0.9))/(50*YC_Density*YC_ConcPct),1),"") -> 1333 | Q30: =IF(K30<L30,A30,"") | R30: =IF(Q30="",R29,IF(R29="",Q30,R29&", "&Q30))
A31: Alcohol 190 proof SDA 40B | B31: 1000 | C31: ml | D31: 1 | E31: 0.81 | F31: =IF(C31="ml",B31*D31*E31,B31*D31) -> 810 | G31: 150 | H31: =G31*D31 -> 150 | I31: =IF(F31=0,0,H31/F31) -> 0.18518519 | J31: =AlcoholUsedG -> 0 | K31: =F31-J31 -> 810 | L31: =2*DefaultBatchAlcG -> 61.2 | M31: =IF(K31<L31,"LOW","OK") -> OK | N31: iterji.com | O31: open ↗ | P31: =IFERROR(FLOOR(MAX(K31,0)/(50*YC_Density*(1-YC_ConcPct)),1),"") -> 26 | Q31: =IF(K31<L31,A31,"") | R31: =IF(Q31="",R30,IF(R30="",Q31,R30&", "&Q31))
A32: TOTAL PAID (SAR) | H32: =SUM(H4:H31) -> 2329.35
A34: Not on iterji | B34: 8 ingredients are NOT sold by iterji.com (checked 2026-07): Globalide/Habanolide, Helvetolide, Javanol, Vetyveryle Acetate, Floralozone, Safraleine (captive synthetics), plus Sandal Spicatum Australia and Orange Blossom Tunisia Absolute. Their Supplier cell is highlighted and the link points to a suggested source.
A35: • The six synthetics (Givaudan/Firmenich/Symrise/IFF captives) have no Saudi retail source — buy from international specialists that ship to KSA: Fraterworks, Aromology, Perfumer's Apprentice, World of Aromas.
A36: • The two naturals (Australian sandalwood, orange-blossom absolute) can often be found at Saudi essential-oil shops: Jozoor / mygezor.com, Brooq (Unaizah) brooqksa.com, or عالم الكيماويات chemicalsmed.com — verify grade before buying.
A37: • Everything else is on iterji.com; click ‘open ↗’ in the Product link column. Prices re-checked 2026-07: Ambroxan and Alpha Irone rose notably, Virginian Cedarwood slightly.

Sheet Inventory Bottles
A1: INVENTORY & BOTTLES
A2: One live view of stock, bottle capacity by size, and which material increases output if you buy more.
A3: Bottle size | B3: 10 | C3: 20 | D3: 30 | E3: 50 | F3: 70 | G3: 100 | H3: Current | I3: Type trial purchase quantities in "Add packs". Projected bottles update immediately. Gold rows are materials where +1 pack can raise the 50 ml output; red rows are the current bottleneck.
B4: =MIN(K7:K34) -> 25 | C4: =MIN(L7:L34) -> 12 | D4: =MIN(M7:M34) -> 8 | E4: =MIN(N7:N34) -> 5 | F4: =MIN(O7:O34) -> 3 | G4: =MIN(P7:P34) -> 2 | H4: Projected
B5: =MIN(Q7:Q34) -> 25 | C5: =MIN(R7:R34) -> 12 | D5: =MIN(S7:S34) -> 8 | E5: =MIN(T7:T34) -> 5 | F5: =MIN(U7:U34) -> 3 | G5: =MIN(V7:V34) -> 2
A6: Material | B6: Pack | C6: Unit | D6: Packs | E6: Add packs | F6: Density | G6: On hand g | H6: Projected g | I6: Active % | J6: Use / g conc | K6: Cur 10 | L6: Cur 20 | M6: Cur 30 | N6: Cur 50 | O6: Cur 70 | P6: Cur 100 | Q6: Proj 10 | R6: Proj 20 | S6: Proj 30 | T6: Proj 50 | U6: Proj 70 | V6: Proj 100 | W6: +50 if +1 pack | X6: Priority | Y6: Product
A7: =Inventory!A4 -> Hedione (Firmenich) | B7: =Inventory!B4 -> 30 | C7: =Inventory!C4 -> ml | D7: =Inventory!D4 -> 1 | E7: 0 | F7: =Inventory!E4 -> 0.9 | G7: =Inventory!K4 -> 27 | H7: =G7+E7*IF(C7="ml",B7*F7,B7) -> 27 | I7: =IF(A7="DPG (Dipropylene Glycol)",D10ActivePct,IFERROR(INDEX(FM_Active,MATCH(A7,FM_Mat,0)),"")) -> 0.2 | J7: =IF(A7="DPG (Dipropylene Glycol)",D10ActivePct*0.9,IF(A7="Alcohol 190 proof SDA 40B","",IFERROR(I7*IF(INDEX(FM_D10,MATCH(A7,FM_Mat,0))="D10",0.1,1),""))) -> 0.2 | K7: =IF($A7="","",IF($A7="DPG (Dipropylene Glycol)",IFERROR(FLOOR((MAX($G7,0)/(D10ActivePct*0.9))/(10*YC_Density*YC_ConcPct),1),""),IF($A7="Alcohol 190 proof SDA 40B",IFERROR(FLOOR(MAX($G7,0)/(10*YC_Density*(1-YC_ConcPct)),1),""),IFERROR(FLOOR((MAX($G7,0)/(INDEX(FM_Active,MATCH($A7,FM_Mat,0))*IF(INDEX(FM_D10,MATCH($A7,FM_Mat,0))="D10",0.1,1)))/(10*YC_Density*YC_ConcPct),1),"")))) -> 56 | L7: =IF($A7="","",IF($A7="DPG (Dipropylene Glycol)",IFERROR(FLOOR((MAX($G7,0)/(D10ActivePct*0.9))/(20*YC_Density*YC_ConcPct),1),""),IF($A7="Alcohol 190 proof SDA 40B",IFERROR(FLOOR(MAX($G7,0)/(20*YC_Density*(1-YC_ConcPct)),1),""),IFERROR(FLOOR((MAX($G7,0)/(INDEX(FM_Active,MATCH($A7,FM_Mat,0))*IF(INDEX(FM_D10,MATCH($A7,FM_Mat,0))="D10",0.1,1)))/(20*YC_Density*YC_ConcPct),1),"")))) -> 28 | M7: =IF($A7="","",IF($A7="DPG (Dipropylene Glycol)",IFERROR(FLOOR((MAX($G7,0)/(D10ActivePct*0.9))/(30*YC_Density*YC_ConcPct),1),""),IF($A7="Alcohol 190 proof SDA 40B",IFERROR(FLOOR(MAX($G7,0)/(30*YC_Density*(1-YC_ConcPct)),1),""),IFERROR(FLOOR((MAX($G7,0)/(INDEX(FM_Active,MATCH($A7,FM_Mat,0))*IF(INDEX(FM_D10,MATCH($A7,FM_Mat,0))="D10",0.1,1)))/(30*YC_Density*YC_ConcPct),1),"")))) -> 18 | N7: =IF($A7="","",IF($A7="DPG (Dipropylene Glycol)",IFERROR(FLOOR((MAX($G7,0)/(D10ActivePct*0.9))/(50*YC_Density*YC_ConcPct),1),""),IF($A7="Alcohol 190 proof SDA 40B",IFERROR(FLOOR(MAX($G7,0)/(50*YC_Density*(1-YC_ConcPct)),1),""),IFERROR(FLOOR((MAX($G7,0)/(INDEX(FM_Active,MATCH($A7,FM_Mat,0))*IF(INDEX(FM_D10,MATCH($A7,FM_Mat,0))="D10",0.1,1)))/(50*YC_Density*YC_ConcPct),1),"")))) -> 11 | O7: =IF($A7="","",IF($A7="DPG (Dipropylene Glycol)",IFERROR(FLOOR((MAX($G7,0)/(D10ActivePct*0.9))/(70*YC_Density*YC_ConcPct),1),""),IF($A7="Alcohol 190 proof SDA 40B",IFERROR(FLOOR(MAX($G7,0)/(70*YC_Density*(1-YC_ConcPct)),1),""),IFERROR(FLOOR((MAX($G7,0)/(INDEX(FM_Active,MATCH($A7,FM_Mat,0))*IF(INDEX(FM_D10,MATCH($A7,FM_Mat,0))="D10",0.1,1)))/(70*YC_Density*YC_ConcPct),1),"")))) -> 8 | P7: =IF($A7="","",IF($A7="DPG (Dipropylene Glycol)",IFERROR(FLOOR((MAX($G7,0)/(D10ActivePct*0.9))/(100*YC_Density*YC_ConcPct),1),""),IF($A7="Alcohol 190 proof SDA 40B",IFERROR(FLOOR(MAX($G7,0)/(100*YC_Density*(1-YC_ConcPct)),1),""),IFERROR(FLOOR((MAX($G7,0)/(INDEX(FM_Active,MATCH($A7,FM_Mat,0))*IF(INDEX(FM_D10,MATCH($A7,FM_Mat,0))="D10",0.1,1)))/(100*YC_Density*YC_ConcPct),1),"")))) -> 5 | Q7: =IF($A7="","",IF($A7="DPG (Dipropylene Glycol)",IFERROR(FLOOR((MAX($H7,0)/(D10ActivePct*0.9))/(10*YC_Density*YC_ConcPct),1),""),IF($A7="Alcohol 190 proof SDA 40B",IFERROR(FLOOR(MAX($H7,0)/(10*YC_Density*(1-YC_ConcPct)),1),""),IFERROR(FLOOR((MAX($H7,0)/(INDEX(FM_Active,MATCH($A7,FM_Mat,0))*IF(INDEX(FM_D10,MATCH($A7,FM_Mat,0))="D10",0.1,1)))/(10*YC_Density*YC_ConcPct),1),"")))) -> 56 | R7: =IF($A7="","",IF($A7="DPG (Dipropylene Glycol)",IFERROR(FLOOR((MAX($H7,0)/(D10ActivePct*0.9))/(20*YC_Density*YC_ConcPct),1),""),IF($A7="Alcohol 190 proof SDA 40B",IFERROR(FLOOR(MAX($H7,0)/(20*YC_Density*(1-YC_ConcPct)),1),""),IFERROR(FLOOR((MAX($H7,0)/(INDEX(FM_Active,MATCH($A7,FM_Mat,0))*IF(INDEX(FM_D10,MATCH($A7,FM_Mat,0))="D10",0.1,1)))/(20*YC_Density*YC_ConcPct),1),"")))) -> 28 | S7: =IF($A7="","",IF($A7="DPG (Dipropylene Glycol)",IFERROR(FLOOR((MAX($H7,0)/(D10ActivePct*0.9))/(30*YC_Density*YC_ConcPct),1),""),IF($A7="Alcohol 190 proof SDA 40B",IFERROR(FLOOR(MAX($H7,0)/(30*YC_Density*(1-YC_ConcPct)),1),""),IFERROR(FLOOR((MAX($H7,0)/(INDEX(FM_Active,MATCH($A7,FM_Mat,0))*IF(INDEX(FM_D10,MATCH($A7,FM_Mat,0))="D10",0.1,1)))/(30*YC_Density*YC_ConcPct),1),"")))) -> 18 | T7: =IF($A7="","",IF($A7="DPG (Dipropylene Glycol)",IFERROR(FLOOR((MAX($H7,0)/(D10ActivePct*0.9))/(50*YC_Density*YC_ConcPct),1),""),IF($A7="Alcohol 190 proof SDA 40B",IFERROR(FLOOR(MAX($H7,0)/(50*YC_Density*(1-YC_ConcPct)),1),""),IFERROR(FLOOR((MAX($H7,0)/(INDEX(FM_Active,MATCH($A7,FM_Mat,0))*IF(INDEX(FM_D10,MATCH($A7,FM_Mat,0))="D10",0.1,1)))/(50*YC_Density*YC_ConcPct),1),"")))) -> 11 | U7: =IF($A7="","",IF($A7="DPG (Dipropylene Glycol)",IFERROR(FLOOR((MAX($H7,0)/(D10ActivePct*0.9))/(70*YC_Density*YC_ConcPct),1),""),IF($A7="Alcohol 190 proof SDA 40B",IFERROR(FLOOR(MAX($H7,0)/(70*YC_Density*(1-YC_ConcPct)),1),""),IFERROR(FLOOR((MAX($H7,0)/(INDEX(FM_Active,MATCH($A7,FM_Mat,0))*IF(INDEX(FM_D10,MATCH($A7,FM_Mat,0))="D10",0.1,1)))/(70*YC_Density*YC_ConcPct),1),"")))) -> 8 | V7: =IF($A7="","",IF($A7="DPG (Dipropylene Glycol)",IFERROR(FLOOR((MAX($H7,0)/(D10ActivePct*0.9))/(100*YC_Density*YC_ConcPct),1),""),IF($A7="Alcohol 190 proof SDA 40B",IFERROR(FLOOR(MAX($H7,0)/(100*YC_Density*(1-YC_ConcPct)),1),""),IFERROR(FLOOR((MAX($H7,0)/(INDEX(FM_Active,MATCH($A7,FM_Mat,0))*IF(INDEX(FM_D10,MATCH($A7,FM_Mat,0))="D10",0.1,1)))/(100*YC_Density*YC_ConcPct),1),"")))) -> 5 | W7: =IF($N7="","",MAX(0,MIN(IF($A7="","",IF($A7="DPG (Dipropylene Glycol)",IFERROR(FLOOR((MAX(($G7+IF($C7="ml",$B7*$F7,$B7)),0)/(D10ActivePct*0.9))/(50*YC_Density*YC_ConcPct),1),""),IF($A7="Alcohol 190 proof SDA 40B",IFERROR(FLOOR(MAX(($G7+IF($C7="ml",$B7*$F7,$B7)),0)/(50*YC_Density*(1-YC_ConcPct)),1),""),IFERROR(FLOOR((MAX(($G7+IF($C7="ml",$B7*$F7,$B7)),0)/(INDEX(FM_Active,MATCH($A7,FM_Mat,0))*IF(INDEX(FM_D10,MATCH($A7,FM_Mat,0))="D10",0.1,1)))/(50*YC_Density*YC_ConcPct),1),"")))),MIN($N$8:$N$34))-$E$4)) -> 0 | X7: =IF(AND(ISNUMBER(W7),W7>0),"BUY MORE - raises output",IF(AND(ISNUMBER(N7),N7=$E$4),"CURRENT BOTTLENECK",IF(AND(ISNUMBER(N7),N7<=$E$4+2),"NEXT LIMIT",""))) | Y7: open
A8: =Inventory!A5 -> Iso E Super | B8: =Inventory!B5 -> 10 | C8: =Inventory!C5 -> ml | D8: =Inventory!D5 -> 1 | E8: 0 | F8: =Inventory!E5 -> 0.9 | G8: =Inventory!K5 -> 9 | H8: =G8+E8*IF(C8="ml",B8*F8,B8) -> 9 | I8: =IF(A8="DPG (Dipropylene Glycol)",D10ActivePct,IFERROR(INDEX(FM_Active,MATCH(A8,FM_Mat,0)),"")) -> 0.15 | J8: =IF(A8="DPG (Dipropylene Glycol)",D10ActivePct*0.9,IF(A8="Alcohol 190 proof SDA 40B","",IFERROR(I8*IF(INDEX(FM_D10,MATCH(A8,FM_Mat,0))="D10",0.1,1),""))) -> 0.15 | K8: =IF($A8="","",IF($A8="DPG (Dipropylene Glycol)",IFERROR(FLOOR((MAX($G8,0)/(D10ActivePct*0.9))/(10*YC_Density*YC_ConcPct),1),""),IF($A8="Alcohol 190 proof SDA 40B",IFERROR(FLOOR(MAX($G8,0)/(10*YC_Density*(1-YC_ConcPct)),1),""),IFERROR(FLOOR((MAX($G8,0)/(INDEX(FM_Active,MATCH($A8,FM_Mat,0))*IF(INDEX(FM_D10,MATCH($A8,FM_Mat,0))="D10",0.1,1)))/(10*YC_Density*YC_ConcPct),1),"")))) -> 25 | L8: =IF($A8="","",IF($A8="DPG (Dipropylene Glycol)",IFERROR(FLOOR((MAX($G8,0)/(D10ActivePct*0.9))/(20*YC_Density*YC_ConcPct),1),""),IF($A8="Alcohol 190 proof SDA 40B",IFERROR(FLOOR(MAX($G8,0)/(20*YC_Density*(1-YC_ConcPct)),1),""),IFERROR(FLOOR((MAX($G8,0)/(INDEX(FM_Active,MATCH($A8,FM_Mat,0))*IF(INDEX(FM_D10,MATCH($A8,FM_Mat,0))="D10",0.1,1)))/(20*YC_Density*YC_ConcPct),1),"")))) -> 12 | M8: =IF($A8="","",IF($A8="DPG (Dipropylene Glycol)",IFERROR(FLOOR((MAX($G8,0)/(D10ActivePct*0.9))/(30*YC_Density*YC_ConcPct),1),""),IF($A8="Alcohol 190 proof SDA 40B",IFERROR(FLOOR(MAX($G8,0)/(30*YC_Density*(1-YC_ConcPct)),1),""),IFERROR(FLOOR((MAX($G8,0)/(INDEX(FM_Active,MATCH($A8,FM_Mat,0))*IF(INDEX(FM_D10,MATCH($A8,FM_Mat,0))="D10",0.1,1)))/(30*YC_Density*YC_ConcPct),1),"")))) -> 8 | N8: =IF($A8="","",IF($A8="DPG (Dipropylene Glycol)",IFERROR(FLOOR((MAX($G8,0)/(D10ActivePct*0.9))/(50*YC_Density*YC_ConcPct),1),""),IF($A8="Alcohol 190 proof SDA 40B",IFERROR(FLOOR(MAX($G8,0)/(50*YC_Density*(1-YC_ConcPct)),1),""),IFERROR(FLOOR((MAX($G8,0)/(INDEX(FM_Active,MATCH($A8,FM_Mat,0))*IF(INDEX(FM_D10,MATCH($A8,FM_Mat,0))="D10",0.1,1)))/(50*YC_Density*YC_ConcPct),1),"")))) -> 5 | O8: =IF($A8="","",IF($A8="DPG (Dipropylene Glycol)",IFERROR(FLOOR((MAX($G8,0)/(D10ActivePct*0.9))/(70*YC_Density*YC_ConcPct),1),""),IF($A8="Alcohol 190 proof SDA 40B",IFERROR(FLOOR(MAX($G8,0)/(70*YC_Density*(1-YC_ConcPct)),1),""),IFERROR(FLOOR((MAX($G8,0)/(INDEX(FM_Active,MATCH($A8,FM_Mat,0))*IF(INDEX(FM_D10,MATCH($A8,FM_Mat,0))="D10",0.1,1)))/(70*YC_Density*YC_ConcPct),1),"")))) -> 3 | P8: =IF($A8="","",IF($A8="DPG (Dipropylene Glycol)",IFERROR(FLOOR((MAX($G8,0)/(D10ActivePct*0.9))/(100*YC_Density*YC_ConcPct),1),""),IF($A8="Alcohol 190 proof SDA 40B",IFERROR(FLOOR(MAX($G8,0)/(100*YC_Density*(1-YC_ConcPct)),1),""),IFERROR(FLOOR((MAX($G8,0)/(INDEX(FM_Active,MATCH($A8,FM_Mat,0))*IF(INDEX(FM_D10,MATCH($A8,FM_Mat,0))="D10",0.1,1)))/(100*YC_Density*YC_ConcPct),1),"")))) -> 2 | Q8: =IF($A8="","",IF($A8="DPG (Dipropylene Glycol)",IFERROR(FLOOR((MAX($H8,0)/(D10ActivePct*0.9))/(10*YC_Density*YC_ConcPct),1),""),IF($A8="Alcohol 190 proof SDA 40B",IFERROR(FLOOR(MAX($H8,0)/(10*YC_Density*(1-YC_ConcPct)),1),""),IFERROR(FLOOR((MAX($H8,0)/(INDEX(FM_Active,MATCH($A8,FM_Mat,0))*IF(INDEX(FM_D10,MATCH($A8,FM_Mat,0))="D10",0.1,1)))/(10*YC_Density*YC_ConcPct),1),"")))) -> 25 | R8: =IF($A8="","",IF($A8="DPG (Dipropylene Glycol)",IFERROR(FLOOR((MAX($H8,0)/(D10ActivePct*0.9))/(20*YC_Density*YC_ConcPct),1),""),IF($A8="Alcohol 190 proof SDA 40B",IFERROR(FLOOR(MAX($H8,0)/(20*YC_Density*(1-YC_ConcPct)),1),""),IFERROR(FLOOR((MAX($H8,0)/(INDEX(FM_Active,MATCH($A8,FM_Mat,0))*IF(INDEX(FM_D10,MATCH($A8,FM_Mat,0))="D10",0.1,1)))/(20*YC_Density*YC_ConcPct),1),"")))) -> 12 | S8: =IF($A8="","",IF($A8="DPG (Dipropylene Glycol)",IFERROR(FLOOR((MAX($H8,0)/(D10ActivePct*0.9))/(30*YC_Density*YC_ConcPct),1),""),IF($A8="Alcohol 190 proof SDA 40B",IFERROR(FLOOR(MAX($H8,0)/(30*YC_Density*(1-YC_ConcPct)),1),""),IFERROR(FLOOR((MAX($H8,0)/(INDEX(FM_Active,MATCH($A8,FM_Mat,0))*IF(INDEX(FM_D10,MATCH($A8,FM_Mat,0))="D10",0.1,1)))/(30*YC_Density*YC_ConcPct),1),"")))) -> 8 | T8: =IF($A8="","",IF($A8="DPG (Dipropylene Glycol)",IFERROR(FLOOR((MAX($H8,0)/(D10ActivePct*0.9))/(50*YC_Density*YC_ConcPct),1),""),IF($A8="Alcohol 190 proof SDA 40B",IFERROR(FLOOR(MAX($H8,0)/(50*YC_Density*(1-YC_ConcPct)),1),""),IFERROR(FLOOR((MAX($H8,0)/(INDEX(FM_Active,MATCH($A8,FM_Mat,0))*IF(INDEX(FM_D10,MATCH($A8,FM_Mat,0))="D10",0.1,1)))/(50*YC_Density*YC_ConcPct),1),"")))) -> 5 | U8: =IF($A8="","",IF($A8="DPG (Dipropylene Glycol)",IFERROR(FLOOR((MAX($H8,0)/(D10ActivePct*0.9))/(70*YC_Density*YC_ConcPct),1),""),IF($A8="Alcohol 190 proof SDA 40B",IFERROR(FLOOR(MAX($H8,0)/(70*YC_Density*(1-YC_ConcPct)),1),""),IFERROR(FLOOR((MAX($H8,0)/(INDEX(FM_Active,MATCH($A8,FM_Mat,0))*IF(INDEX(FM_D10,MATCH($A8,FM_Mat,0))="D10",0.1,1)))/(70*YC_Density*YC_ConcPct),1),"")))) -> 3 | V8: =IF($A8="","",IF($A8="DPG (Dipropylene Glycol)",IFERROR(FLOOR((MAX($H8,0)/(D10ActivePct*0.9))/(100*YC_Density*YC_ConcPct),1),""),IF($A8="Alcohol 190 proof SDA 40B",IFERROR(FLOOR(MAX($H8,0)/(100*YC_Density*(1-YC_ConcPct)),1),""),IFERROR(FLOOR((MAX($H8,0)/(INDEX(FM_Active,MATCH($A8,FM_Mat,0))*IF(INDEX(FM_D10,MATCH($A8,FM_Mat,0))="D10",0.1,1)))/(100*YC_Density*YC_ConcPct),1),"")))) -> 2 | W8: =IF($N8="","",MAX(0,MIN(IF($A8="","",IF($A8="DPG (Dipropylene Glycol)",IFERROR(FLOOR((MAX(($G8+IF($C8="ml",$B8*$F8,$B8)),0)/(D10ActivePct*0.9))/(50*YC_Density*YC_ConcPct),1),""),IF($A8="Alcohol 190 proof SDA 40B",IFERROR(FLOOR(MAX(($G8+IF($C8="ml",$B8*$F8,$B8)),0)/(50*YC_Density*(1-YC_ConcPct)),1),""),IFERROR(FLOOR((MAX(($G8+IF($C8="ml",$B8*$F8,$B8)),0)/(INDEX(FM_Active,MATCH($A8,FM_Mat,0))*IF(INDEX(FM_D10,MATCH($A8,FM_Mat,0))="D10",0.1,1)))/(50*YC_Density*YC_ConcPct),1),"")))),MIN($N$7:$N$7),MIN($N$9:$N$34))-$E$4)) -> 3 | X8: =IF(AND(ISNUMBER(W8),W8>0),"BUY MORE - raises output",IF(AND(ISNUMBER(N8),N8=$E$4),"CURRENT BOTTLENECK",IF(AND(ISNUMBER(N8),N8<=$E$4+2),"NEXT LIMIT",""))) -> BUY MORE - raises output | Y8: open
