Workbook
Name AlcCostPerG: 'Cost Analysis'!$C$16
Name AlcoholG: 'Batch Calculator'!$D$58
Name AlcoholUsedG: 'Production Log'!$I$3
Name AuxCostPerG: 'Cost Analysis'!$C$16:$C$26
Name AuxGrams: 'Batch Calculator'!$D$58:$D$68
Name BatchCostSAR: 'Batch Calculator'!$C$24
Name BatchFormat: 'Batch Calculator'!$C$4
Name BatchSize: 'Batch Calculator'!$C$5
Name BatchUnit: 'Batch Calculator'!$C$6
Name BatchVolMl: 'Batch Calculator'!$C$22
Name ConcCostPerG: 'Cost Analysis'!$C$11
Name ConcCostPerGLoaded: 'Cost Analysis'!$C$12
Name ConcG: 'Batch Calculator'!$C$23
Name ConcPct: 'Batch Calculator'!$C$7
Name CostPerMl: 'Batch Calculator'!$C$25
Name CR2ButterPct: 'Batch Calculator'!$G$17
Name CR2CetPct: 'Batch Calculator'!$G$15
Name CR2EwaxPct: 'Batch Calculator'!$G$14
Name CR2GlyPct: 'Batch Calculator'!$G$13
Name CR2OilPct: 'Batch Calculator'!$G$16
Name CR2PresPct: 'Batch Calculator'!$G$18
Name CreamBaseG: 'Batch Calculator'!$D$63
Name D10ActivePct: 'Formula Master'!$I$4
Name DefaultBatchAlcG: Inventory!$K$2
Name DefaultBatchConcG: Inventory!$H$2
Name DPGPricePerG: 'Cost Analysis'!$C$10
Name FinishedDensity: 'Batch Calculator'!$C$8
Name FM_Active: 'Formula Master'!$F$7:$F$31
Name FM_CostG: 'Formula Master'!$H$7:$H$31
Name FM_D10: 'Formula Master'!$D$7:$D$31
Name FM_InputPct: 'Formula Master'!$C$7:$C$31
Name FM_Mat: 'Formula Master'!$B$7:$B$31
Name FormatDefaults: Lists!$A$2:$E$7
Name FormatList: Lists!$A$2:$A$7
Name GlycerinG: 'Batch Calculator'!$D$60
Name IncludeOptionals: 'Formula Master'!$C$4
Name Inv_GramsBought: Inventory!$F$4:$F$30
Name Inv_LowJoined: Inventory!$Q$30
Name Inv_LowNames: Inventory!$P$4:$P$30
Name Inv_Mat: Inventory!$A$4:$A$30
Name Inv_OnHand: Inventory!$K$4:$K$30
Name Inv_PricePerG: Inventory!$I$4:$I$30
Name Inv_Threshold: Inventory!$L$4:$L$30
Name Inv_TotalPaid: Inventory!$H$4:$H$30
Name LogAlcG: 'Production Log'!$H$5:$H$44
Name LogConcG: 'Production Log'!$G$5:$G$44
Name LogEnd: 'Production Log'!$J$5:$J$44
Name LogID: 'Production Log'!$B$5:$B$44
Name LogMacStart: 'Production Log'!$M$5:$M$44
Name LogStart: 'Production Log'!$I$5:$I$44
Name LogStatus: 'Production Log'!$K$5:$K$44
Name MacDays: 'Production Log'!$C$3
Name MaterialsTotalSAR: 'Cost Analysis'!$C$4
Name MistGlyPct: 'Batch Calculator'!$C$13
Name MistWaterPct: 'Batch Calculator'!$C$14
Name OptPctSum: 'Formula Master'!$I$3
Name PolysorbateG: 'Batch Calculator'!$D$61
Name PR_ConcPct: 'Pricing & Sales'!$C$4
Name PR_Density: 'Pricing & Sales'!$C$5
Name PR_Labour: 'Pricing & Sales'!$C$6

Sheet Dashboard
B2: S A M R
B3: سَمَر · evening warmth, vanilla, white flowers, warm musk · made for her skin
B6: INVESTED (SAR) | C6: STOCK VALUE (SAR) | D6: CONCENTRATE (SAR/g) | E6: BATCHES LOGGED | F6: MACERATING NOW | G6: LOW-STOCK ITEMS
B7: =TotalCapital -> 1577.87 | C7: =StockValueSAR -> 1226.87 | D7: =ConcCostPerGLoaded -> 3.3703177 | E7: =SUMPRODUCT((LogID<>"")*1) -> 0 | F7: =COUNTIF(LogStatus,"Macerating") -> 0 | G7: =SUMPRODUCT((Inv_OnHand<Inv_Threshold)*1) -> 0
B9: CURRENT BATCH — quick launch | E9: MACERATION MILESTONES
B10: Format | C10: =BatchFormat -> Extrait de Parfum | E10: Next ready window opens | G10: =IF(COUNTIFS(LogStatus,"Macerating",LogStart,"<>")=0,"—",TEXT(MIN(LogMacStart)+28,"yyyy-mm-dd")) -> —
B11: Batch | C11: =BatchSize&" "&BatchUnit -> 50 ml | E11: Next maceration complete | G11: =IF(COUNTIFS(LogStatus,"Macerating",LogStart,"<>")=0,"—",TEXT(MIN(LogMacStart)+MacDays,"yyyy-mm-dd")) -> —
B12: Concentrate to weigh (g) | C12: =ConcG -> 11.9 | E12: Batches in ready window | G12: =SUMPRODUCT((LogStatus="Macerating")*(LogStart<>"")*((TODAY()-LogStart)>=28)) -> 0
B13: Alcohol (g) | C13: =AlcoholG -> 30.6 | E13: Concentrate used to date (g) | G13: =TotalConcUsedG -> 0
B14: Estimated cost (SAR) | C14: =BatchCostSAR -> 41.564354 | E14: Alcohol used to date (g) | G14: =AlcoholUsedG -> 0
B15: Cost per ml (SAR) | C15: =CostPerMl -> 0.83128708 | E15: Maceration target (days) | G15: =MacDays -> 42
B17: INVENTORY ALERTS
B18: =IF($G$7=0,"✓ All materials stocked for at least two default batches.","⚠ Low stock — reorder: "&Inv_LowJoined) -> ✓ All materials stocked for at least two default batches.
B20: WORKFLOW
B21: 1 · Set format, size and concentration in the Batch Calculator — print it and take it to the bench.
B22: 2 · Weigh BASE → HEART → TOP, marry the concentrate 24–48 h, then dilute and start maceration.
B23: 3 · Log the batch in the Production Log — Inventory and the Maceration Tracker update themselves.
B25: SAMR personal production suite · verify against current IFRA standards before any commercial use

Sheet The Scent
B2: S A M R
B3: Extrait de Parfum 28% · Gourmand Amber Floral · a warm-skin scent
B6: THE NAME
B7: SAMR — سَمَر — comes from Samrae and from the Arabic idea of late-night conversation: warmth after sunset, closeness, and the voice you want to keep hearing. The brand mark keeps the name short, intimate, and easy to put on a bottle while still carrying her name inside it.
B9: THE IDEA
B10: SAMR is a private extrait built around warmth on skin: soft fruit at the opening, white flowers at body temperature, vanilla, tonka, ambergris radiance, velvet woods, and a five-layer musk trail. The goal is not room-filling noise; it is a close, memorable signature that feels personal when someone is allowed near.
B12: THE OPENING — the first glance
B13: Sun-warmed bergamot and a spark of pink pepper sit over ripe peach skin and raspberry gloss. Bright, juicy, and playful, the opening lasts long enough to catch attention, then melts into the warmer heart.
B15: THE HEART — the embrace
B16: A cloud of Hedione makes the heart luminous while jasmine and tuberose bring creamy white flower warmth. Violet-iris powder softens the edges, and benzyl salicylate gives a solar, skin-in-the-sun glow. This is the center of SAMR: radiant, feminine, and close.
B18: THE DRYDOWN — the addiction
B19: The base is where SAMR becomes memorable. A double vanilla — vanillin anchored by its creamier ethyl echo — melts into tonka and a caramelised-sugar halo, warmed by almond heliotrope and a single breath of coconut cream. Ambroxan throws its radiant, mineral ambergris aura for hours; Iso E Super and cashmeran wrap it in velvet wood, sandalwood glows underneath, and three musks — clean, powdery, intimate — fuse it all to her skin. The optional glints are plum-rose damascone and a saffron-suede whisper.
... B29: Concentrate = 100% on the Formula Master tab. Weighing, dilutions, maceration and bottling: Batch Calculator + Process Reference.

Sheet Formula Master
A1: SAMR — MASTER FORMULA
A2: Concentrate = 100% by weight. D10 = weighed as a 10% dilution in DPG — the % shown is the weight of the dilution.
H3: Optionals Σ | I3: =SUMIF($E$7:$E$31,"OPT",$C$7:$C$31) -> 0.008
A4: Include optional materials (Damascone Beta, Saffron Accord): | C4: YES | H4: D10 Σ (active) | I4: =SUMIF($D$7:$D$31,"D10",$F$7:$F$31) -> 0.048
A6: Phase | B6: Material | C6: Input % | D6: D10 | E6: Optional | F6: Active % | G6: Role in the accord | H6: SAR/g (as weighed)
A7: TOP | B7: Bergamot Accord | C7: 0.045 | F7: =IF(IncludeOptionals="YES",C7,IF($E7="OPT",0,C7/(1-OptPctSum))) -> 0.045 | G7: sun-warmed citrus — the first glance across the room | H7: =IF($D7="D10",0.1*INDEX(Inv_PricePerG,MATCH($B7,Inv_Mat,0))+0.9*DPGPricePerG,INDEX(Inv_PricePerG,MATCH($B7,Inv_Mat,0))) -> 2.0833333
A8: TOP | B8: Pink Peppercorn | C8: 0.01 | D8: D10 | F8: =IF(IncludeOptionals="YES",C8,IF($E8="OPT",0,C8/(1-OptPctSum))) -> 0.01 | G8: rosy-spicy spark over the opening | H8: =IF($D8="D10",0.1*INDEX(Inv_PricePerG,MATCH($B8,Inv_Mat,0))+0.9*DPGPricePerG,INDEX(Inv_PricePerG,MATCH($B8,Inv_Mat,0))) -> 1.6576797
A9: TOP | B9: Aldehyde C-14 Peach | C9: 0.02 | F9: =IF(IncludeOptionals="YES",C9,IF($E9="OPT",0,C9/(1-OptPctSum))) -> 0.02 | G9: ripe peach skin — velvet, juicy, warm | H9: =IF($D9="D10",0.1*INDEX(Inv_PricePerG,MATCH($B9,Inv_Mat,0))+0.9*DPGPricePerG,INDEX(Inv_PricePerG,MATCH($B9,Inv_Mat,0))) -> 1.86
A10: TOP | B10: Raspberry Accord | C10: 0.01 | F10: =IF(IncludeOptionals="YES",C10,IF($E10="OPT",0,C10/(1-OptPctSum))) -> 0.01 | G10: lip-gloss fruit — playful, kissable | H10: =IF($D10="D10",0.1*INDEX(Inv_PricePerG,MATCH($B10,Inv_Mat,0))+0.9*DPGPricePerG,INDEX(Inv_PricePerG,MATCH($B10,Inv_Mat,0))) -> 2.5
A11: HEART | B11: Hedione (Firmenich) | C11: 0.147 | F11: =IF(IncludeOptionals="YES",C11,IF($E11="OPT",0,C11/(1-OptPctSum))) -> 0.147 | G11: radiant jasmine air — she fills the room | H11: =IF($D11="D10",0.1*INDEX(Inv_PricePerG,MATCH($B11,Inv_Mat,0))+0.9*DPGPricePerG,INDEX(Inv_PricePerG,MATCH($B11,Inv_Mat,0))) -> 0.88518519
A12: HEART | B12: Jasmin Absolute Accord | C12: 0.03 | F12: =IF(IncludeOptionals="YES",C12,IF($E12="OPT",0,C12/(1-OptPctSum))) -> 0.03 | G12: the carnal white flower at body heat | H12: =IF($D12="D10",0.1*INDEX(Inv_PricePerG,MATCH($B12,Inv_Mat,0))+0.9*DPGPricePerG,INDEX(Inv_PricePerG,MATCH($B12,Inv_Mat,0))) -> 5
A13: HEART | B13: Tuberose Accord | C13: 0.015 | F13: =IF(IncludeOptionals="YES",C13,IF($E13="OPT",0,C13/(1-OptPctSum))) -> 0.015 | G13: creamy narcotic petals | H13: =IF($D13="D10",0.1*INDEX(Inv_PricePerG,MATCH($B13,Inv_Mat,0))+0.9*DPGPricePerG,INDEX(Inv_PricePerG,MATCH($B13,Inv_Mat,0))) -> 3.9588889
A14: HEART | B14: Methyl Alpha Ionone Iso | C14: 0.04 | F14: =IF(IncludeOptionals="YES",C14,IF($E14="OPT",0,C14/(1-OptPctSum))) -> 0.04 | G14: violet-iris powder — bare shoulders under silk | H14: =IF($D14="D10",0.1*INDEX(Inv_PricePerG,MATCH($B14,Inv_Mat,0))+0.9*DPGPricePerG,INDEX(Inv_PricePerG,MATCH($B14,Inv_Mat,0))) -> 1.94
A15: HEART | B15: Benzyl Salicylate | C15: 0.07 | F15: =IF(IncludeOptionals="YES",C15,IF($E15="OPT",0,C15/(1-OptPctSum))) -> 0.07 | G15: solar balsamic glow — skin in the sun | H15: =IF($D15="D10",0.1*INDEX(Inv_PricePerG,MATCH($B15,Inv_Mat,0))+0.9*DPGPricePerG,INDEX(Inv_PricePerG,MATCH($B15,Inv_Mat,0))) -> 1.24
A16: HEART | B16: Linalool | C16: 0.015 | F16: =IF(IncludeOptionals="YES",C16,IF($E16="OPT",0,C16/(1-OptPctSum))) -> 0.015 | G16: soft floral smoothing | H16: =IF($D16="D10",0.1*INDEX(Inv_PricePerG,MATCH($B16,Inv_Mat,0))+0.9*DPGPricePerG,INDEX(Inv_PricePerG,MATCH($B16,Inv_Mat,0))) -> 1.86
A17: HEART | B17: Damascone Beta | C17: 0.003 | D17: D10 | E17: OPT | F17: =IF(IncludeOptionals="YES",C17,IF($E17="OPT",0,C17/(1-OptPctSum))) -> 0.003 | G17: velvet plum-rose glint — optional luxury | H17: =IF($D17="D10",0.1*INDEX(Inv_PricePerG,MATCH($B17,Inv_Mat,0))+0.9*DPGPricePerG,INDEX(Inv_PricePerG,MATCH($B17,Inv_Mat,0))) -> 1.1854575
A18: BASE | B18: Vanillin Crystals | C18: 0.065 | F18: =IF(IncludeOptionals="YES",C18,IF($E18="OPT",0,C18/(1-OptPctSum))) -> 0.065 | G18: warm vanilla — the addiction itself | H18: =IF($D18="D10",0.1*INDEX(Inv_PricePerG,MATCH($B18,Inv_Mat,0))+0.9*DPGPricePerG,INDEX(Inv_PricePerG,MATCH($B18,Inv_Mat,0))) -> 1.465
A19: BASE | B19: Ethyl Vanillin | C19: 0.025 | F19: =IF(IncludeOptionals="YES",C19,IF($E19="OPT",0,C19/(1-OptPctSum))) -> 0.025 | G19: deeper, creamier vanilla echo | H19: =IF($D19="D10",0.1*INDEX(Inv_PricePerG,MATCH($B19,Inv_Mat,0))+0.9*DPGPricePerG,INDEX(Inv_PricePerG,MATCH($B19,Inv_Mat,0))) -> 1.569
A20: BASE | B20: Maltol (Crystals) | C20: 0.02 | D20: D10 | F20: =IF(IncludeOptionals="YES",C20,IF($E20="OPT",0,C20/(1-OptPctSum))) -> 0.02 | G20: caramelised-sugar halo | H20: =IF($D20="D10",0.1*INDEX(Inv_PricePerG,MATCH($B20,Inv_Mat,0))+0.9*DPGPricePerG,INDEX(Inv_PricePerG,MATCH($B20,Inv_Mat,0))) -> 0.35333529
A21: BASE | B21: Coumarin | C21: 0.05 | F21: =IF(IncludeOptionals="YES",C21,IF($E21="OPT",0,C21/(1-OptPctSum))) -> 0.05 | G21: tonka warmth — almond-hay softness | H21: =IF($D21="D10",0.1*INDEX(Inv_PricePerG,MATCH($B21,Inv_Mat,0))+0.9*DPGPricePerG,INDEX(Inv_PricePerG,MATCH($B21,Inv_Mat,0))) -> 0.3
A22: BASE | B22: Heliotrope Accord | C22: 0.025 | F22: =IF(IncludeOptionals="YES",C22,IF($E22="OPT",0,C22/(1-OptPctSum))) -> 0.025 | G22: almond-powder tenderness | H22: =IF($D22="D10",0.1*INDEX(Inv_PricePerG,MATCH($B22,Inv_Mat,0))+0.9*DPGPricePerG,INDEX(Inv_PricePerG,MATCH($B22,Inv_Mat,0))) -> 3.75
A23: BASE | B23: Aldehyde C-18 Coconut | C23: 0.015 | D23: D10 | F23: =IF(IncludeOptionals="YES",C23,IF($E23="OPT",0,C23/(1-OptPctSum))) -> 0.015 | G23: a breath of coconut cream on skin | H23: =IF($D23="D10",0.1*INDEX(Inv_PricePerG,MATCH($B23,Inv_Mat,0))+0.9*DPGPricePerG,INDEX(Inv_PricePerG,MATCH($B23,Inv_Mat,0))) -> 0.23545752
A24: BASE | B24: Ambroxan | C24: 0.075 | F24: =IF(IncludeOptionals="YES",C24,IF($E24="OPT",0,C24/(1-OptPctSum))) -> 0.075 | G24: ambergris radiance — the 'come closer' trail | H24: =IF($D24="D10",0.1*INDEX(Inv_PricePerG,MATCH($B24,Inv_Mat,0))+0.9*DPGPricePerG,INDEX(Inv_PricePerG,MATCH($B24,Inv_Mat,0))) -> 13.375
A25: BASE | B25: Iso E Super | C25: 0.095 | F25: =IF(IncludeOptionals="YES",C25,IF($E25="OPT",0,C25/(1-OptPctSum))) -> 0.095 | G25: velvet-wood aura, second-skin halo | H25: =IF($D25="D10",0.1*INDEX(Inv_PricePerG,MATCH($B25,Inv_Mat,0))+0.9*DPGPricePerG,INDEX(Inv_PricePerG,MATCH($B25,Inv_Mat,0))) -> 1.5111111
A26: BASE | B26: Cashmeran IFF | C26: 0.03 | F26: =IF(IncludeOptionals="YES",C26,IF($E26="OPT",0,C26/(1-OptPctSum))) -> 0.03 | G26: cashmere warmth — bedsheets and skin | H26: =IF($D26="D10",0.1*INDEX(Inv_PricePerG,MATCH($B26,Inv_Mat,0))+0.9*DPGPricePerG,INDEX(Inv_PricePerG,MATCH($B26,Inv_Mat,0))) -> 6.2066667
A27: BASE | B27: Sandalore (Givaudan) | C27: 0.035 | F27: =IF(IncludeOptionals="YES",C27,IF($E27="OPT",0,C27/(1-OptPctSum))) -> 0.035 | G27: creamy sandalwood glow | H27: =IF($D27="D10",0.1*INDEX(Inv_PricePerG,MATCH($B27,Inv_Mat,0))+0.9*DPGPricePerG,INDEX(Inv_PricePerG,MATCH($B27,Inv_Mat,0))) -> 2.6155556
A28: BASE | B28: Ethylene Brassylate | C28: 0.075 | F28: =IF(IncludeOptionals="YES",C28,IF($E28="OPT",0,C28/(1-OptPctSum))) -> 0.075 | G28: powdery intimate musk | H28: =IF($D28="D10",0.1*INDEX(Inv_PricePerG,MATCH($B28,Inv_Mat,0))+0.9*DPGPricePerG,INDEX(Inv_PricePerG,MATCH($B28,Inv_Mat,0))) -> 1.1233333
A29: BASE | B29: Galaxolide | C29: 0.055 | F29: =IF(IncludeOptionals="YES",C29,IF($E29="OPT",0,C29/(1-OptPctSum))) -> 0.055 | G29: clean 'her skin' musk — freshly showered | H29: =IF($D29="D10",0.1*INDEX(Inv_PricePerG,MATCH($B29,Inv_Mat,0))+0.9*DPGPricePerG,INDEX(Inv_PricePerG,MATCH($B29,Inv_Mat,0))) -> 1
A30: BASE | B30: Exaltolide Total (Firmenich) | C30: 0.025 | F30: =IF(IncludeOptionals="YES",C30,IF($E30="OPT",0,C30/(1-OptPctSum))) -> 0.025 | G30: warm skin-musk — the lingering embrace | H30: =IF($D30="D10",0.1*INDEX(Inv_PricePerG,MATCH($B30,Inv_Mat,0))+0.9*DPGPricePerG,INDEX(Inv_PricePerG,MATCH($B30,Inv_Mat,0))) -> 3.0588889
A31: BASE | B31: Saffron Accord | C31: 0.005 | E31: OPT | F31: =IF(IncludeOptionals="YES",C31,IF($E31="OPT",0,C31/(1-OptPctSum))) -> 0.005 | G31: saffron-suede whisper — optional luxury | H31: =IF($D31="D10",0.1*INDEX(Inv_PricePerG,MATCH($B31,Inv_Mat,0))+0.9*DPGPricePerG,INDEX(Inv_PricePerG,MATCH($B31,Inv_Mat,0))) -> 3.75
B33: TOTALS | C33: =SUM(C7:C31) -> 1 | F33: =SUM(F7:F31) -> 1
A34: =IF(AND(ROUND(C33,6)=1,ROUND(F33,6)=1),"✓ BALANCED — input Σ = "&TEXT(C33,"0.00%")&" · active Σ = "&TEXT(F33,"0.00%"),"⚠ FORMULA DOES NOT SUM TO 100% — check the Input % column") -> ✓ BALANCED — input Σ = 100.00% · active Σ = 100.00%
A36: Legend: | B36: OPTIONAL / extra | C36: optional materials are controlled only by the C4 toggle
B37: OVERLAPS another | C37: intentional accord layering — do not remove unless you choose a simpler formula
A38: Every other ingredient is essential to the accord. There are NO wasted materials here — each phase (top / heart / base) needs its members to smell complete.

Sheet Batch Calculator
A1: SAMR — BATCH CALCULATOR
A2: All quantities in grams. Weighing order: BASE → HEART → TOP. Champagne cells are inputs.
A3: 1 · BATCH INPUTS
A4: Product format | C4: Extrait de Parfum | D4: choose one of the six product formats
A5: Batch size | C5: 50 | D5: in the unit chosen below
A6: Size unit (ml / g) | C6: ml | D6: ml is converted to grams with the density cell below
A7: Concentrate % | C7: 0.28 | D7: ="Suggested for this format: "&TEXT(VLOOKUP(BatchFormat,FormatDefaults,2,FALSE),"0.0%")&" (range "&TEXT(VLOOKUP(BatchFormat,FormatDefaults,3,FALSE),"0.0%")&" – "&TEXT(VLOOKUP(BatchFormat,FormatDefaults,4,FALSE),"0.0%")&")" -> Suggested for this format: 28.0% (range 20.0% – 35.0%)
A8: Finished density (g/ml) | C8: 0.85 | D8: ="Typical for this format: "&TEXT(VLOOKUP(BatchFormat,FormatDefaults,5,FALSE),"0.00")&" g/ml" -> Typical for this format: 0.85 g/ml
A9: Optionals included? | C9: =IncludeOptionals -> YES | D9: optionals: Damascone Beta, Saffron Accord — set on Formula Master
A11: 2 · FORMAT PARAMETERS (each is used only by the format named)
A12: Distilled water % (EDP) | C12: 0 | D12: EDP / Extrait — optional, max 3% | E12: CREAM ROUTE 2 — PHASE %
A13: Glycerin % (alc. mist) | C13: 0.02 | D13: Alcohol Body Mist — optional 2–3% | E13: Glycerin (water phase) | G13: 0.03
A14: Water % (alc. mist) | C14: 0.05 | D14: Alcohol Body Mist — optional 5–10% | E14: Emulsifying Wax NF | G14: 0.05
A15: Solubilizer × fragrance | C15: 4 | D15: Water Mist — Polysorbate 20 = 4–6 × fragrance wt | E15: Cetearyl alcohol | G15: 0.02
A16: Glycerin % (W-mist) | C16: 0.025 | D16: Water-Based Mist | E16: Carrier oil (light) | G16: 0.15
A17: Preservative % (W-mist) | C17: 0.008 | D17: Water-Based Mist — broad-spectrum, REQUIRED | E17: Shea / mango butter | G17: 0.05
A18: Vitamin E % (cream 2) | C18: 0.005 | D18: Cream Route 2 — cool-down antioxidant | E18: Preservative | G18: 0.01
A20: 3 · BATCH TOTALS
A21: Total batch mass (g) | C21: =IF(BatchUnit="g",BatchSize,BatchSize*FinishedDensity) -> 42.5 | D21: batch size converted to grams
A22: Batch volume (ml, approx.) | C22: =IF(BatchUnit="ml",BatchSize,BatchSize/FinishedDensity) -> 50 | D22: for cost-per-ml
A23: Fragrance concentrate (g) | C23: =TotalMassG*ConcPct -> 11.9 | D23: total to weigh from the table below
A24: Estimated batch cost (SAR) | C24: =ConcG*ConcCostPerGLoaded+SUMPRODUCT(AuxGrams,AuxCostPerG) -> 41.564354 | D24: materials incl. shipping allocation — see Cost Analysis
A25: Cost per ml (SAR) | C25: =IF(BatchVolMl=0,"",BatchCostSAR/BatchVolMl) -> 0.83128708
A27: 4 · CONCENTRATE WEIGHING (weigh in this order: BASE → HEART → TOP)
A28: Phase | B28: Material | D28: % of conc. | E28: Weigh (g) | F28: Form | G28: Neat (g) | H28: ✓
A29: BASE | B29: Vanillin Crystals | D29: =INDEX(FM_Active,MATCH($B29,FM_Mat,0)) -> 0.065 | E29: =ConcG*D29 -> 0.7735 | F29: =IF(INDEX(FM_D10,MATCH($B29,FM_Mat,0))="D10","10% in DPG","neat") -> neat | G29: =E29*IF(INDEX(FM_D10,MATCH($B29,FM_Mat,0))="D10",0.1,1) -> 0.7735
A30: BASE | B30: Ethyl Vanillin | D30: =INDEX(FM_Active,MATCH($B30,FM_Mat,0)) -> 0.025 | E30: =ConcG*D30 -> 0.2975 | F30: =IF(INDEX(FM_D10,MATCH($B30,FM_Mat,0))="D10","10% in DPG","neat") -> neat | G30: =E30*IF(INDEX(FM_D10,MATCH($B30,FM_Mat,0))="D10",0.1,1) -> 0.2975
A31: BASE | B31: Maltol (Crystals) | D31: =INDEX(FM_Active,MATCH($B31,FM_Mat,0)) -> 0.02 | E31: =ConcG*D31 -> 0.238 | F31: =IF(INDEX(FM_D10,MATCH($B31,FM_Mat,0))="D10","10% in DPG","neat") -> 10% in DPG | G31: =E31*IF(INDEX(FM_D10,MATCH($B31,FM_Mat,0))="D10",0.1,1) -> 0.0238
A32: BASE | B32: Coumarin | D32: =INDEX(FM_Active,MATCH($B32,FM_Mat,0)) -> 0.05 | E32: =ConcG*D32 -> 0.595 | F32: =IF(INDEX(FM_D10,MATCH($B32,FM_Mat,0))="D10","10% in DPG","neat") -> neat | G32: =E32*IF(INDEX(FM_D10,MATCH($B32,FM_Mat,0))="D10",0.1,1) -> 0.595
A33: BASE | B33: Heliotrope Accord | D33: =INDEX(FM_Active,MATCH($B33,FM_Mat,0)) -> 0.025 | E33: =ConcG*D33 -> 0.2975 | F33: =IF(INDEX(FM_D10,MATCH($B33,FM_Mat,0))="D10","10% in DPG","neat") -> neat | G33: =E33*IF(INDEX(FM_D10,MATCH($B33,FM_Mat,0))="D10",0.1,1) -> 0.2975
A34: BASE | B34: Aldehyde C-18 Coconut | D34: =INDEX(FM_Active,MATCH($B34,FM_Mat,0)) -> 0.015 | E34: =ConcG*D34 -> 0.1785 | F34: =IF(INDEX(FM_D10,MATCH($B34,FM_Mat,0))="D10","10% in DPG","neat") -> 10% in DPG | G34: =E34*IF(INDEX(FM_D10,MATCH($B34,FM_Mat,0))="D10",0.1,1) -> 0.01785
A35: BASE | B35: Ambroxan | D35: =INDEX(FM_Active,MATCH($B35,FM_Mat,0)) -> 0.075 | E35: =ConcG*D35 -> 0.8925 | F35: =IF(INDEX(FM_D10,MATCH($B35,FM_Mat,0))="D10","10% in DPG","neat") -> neat | G35: =E35*IF(INDEX(FM_D10,MATCH($B35,FM_Mat,0))="D10",0.1,1) -> 0.8925
A36: BASE | B36: Iso E Super | D36: =INDEX(FM_Active,MATCH($B36,FM_Mat,0)) -> 0.095 | E36: =ConcG*D36 -> 1.1305 | F36: =IF(INDEX(FM_D10,MATCH($B36,FM_Mat,0))="D10","10% in DPG","neat") -> neat | G36: =E36*IF(INDEX(FM_D10,MATCH($B36,FM_Mat,0))="D10",0.1,1) -> 1.1305
A37: BASE | B37: Cashmeran IFF | D37: =INDEX(FM_Active,MATCH($B37,FM_Mat,0)) -> 0.03 | E37: =ConcG*D37 -> 0.357 | F37: =IF(INDEX(FM_D10,MATCH($B37,FM_Mat,0))="D10","10% in DPG","neat") -> neat | G37: =E37*IF(INDEX(FM_D10,MATCH($B37,FM_Mat,0))="D10",0.1,1) -> 0.357
A38: BASE | B38: Sandalore (Givaudan) | D38: =INDEX(FM_Active,MATCH($B38,FM_Mat,0)) -> 0.035 | E38: =ConcG*D38 -> 0.4165 | F38: =IF(INDEX(FM_D10,MATCH($B38,FM_Mat,0))="D10","10% in DPG","neat") -> neat | G38: =E38*IF(INDEX(FM_D10,MATCH($B38,FM_Mat,0))="D10",0.1,1) -> 0.4165
A39: BASE | B39: Ethylene Brassylate | D39: =INDEX(FM_Active,MATCH($B39,FM_Mat,0)) -> 0.075 | E39: =ConcG*D39 -> 0.8925 | F39: =IF(INDEX(FM_D10,MATCH($B39,FM_Mat,0))="D10","10% in DPG","neat") -> neat | G39: =E39*IF(INDEX(FM_D10,MATCH($B39,FM_Mat,0))="D10",0.1,1) -> 0.8925
A40: BASE | B40: Galaxolide | D40: =INDEX(FM_Active,MATCH($B40,FM_Mat,0)) -> 0.055 | E40: =ConcG*D40 -> 0.6545 | F40: =IF(INDEX(FM_D10,MATCH($B40,FM_Mat,0))="D10","10% in DPG","neat") -> neat | G40: =E40*IF(INDEX(FM_D10,MATCH($B40,FM_Mat,0))="D10",0.1,1) -> 0.6545
... A53: TOP | B53: Raspberry Accord | D53: =INDEX(FM_Active,MATCH($B53,FM_Mat,0)) -> 0.01 | E53: =ConcG*D53 -> 0.119 | F53: =IF(INDEX(FM_D10,MATCH($B53,FM_Mat,0))="D10","10% in DPG","neat") -> neat | G53: =E53*IF(INDEX(FM_D10,MATCH($B53,FM_Mat,0))="D10",0.1,1) -> 0.119
A54: CONCENTRATE TOTAL (must equal the concentrate above) | E54: =SUM(E29:E53) -> 11.9 | F54: =IF(ABS(E54-ConcG)<0.005,"✓","⚠") -> ✓ | G54: =SUM(G29:G53) -> 11.38592
A56: 5 · SOLVENT & AUXILIARY COMPONENTS
...

Sheet Dilution Prep (D10)
A1: D10 DILUTIONS — 10% IN DPG
A2: Default batch: 10 g of solution = 1.0 g neat material + 9.0 g DPG. Prepare at least 24 h before blending.
A4: Material | B4: Strength | C4: Batch (g) | D4: Neat (g) | E4: DPG (g) | F4: Date made | G4: Remaining (g) | H4: Label / notes
A5: Pink Peppercorn | B5: 0.1 | C5: 10 | D5: =C5*B5 -> 1 | E5: =C5-D5 -> 9 | H5: ="SAMR · "&A5&" · 10% in DPG · "&IF(F5="","(date)",TEXT(F5,"yyyy-mm-dd")) -> SAMR · Pink Peppercorn · 10% in DPG · (date)
A6: Damascone Beta | B6: 0.1 | C6: 10 | D6: =C6*B6 -> 1 | E6: =C6-D6 -> 9 | H6: ="SAMR · "&A6&" · 10% in DPG · "&IF(F6="","(date)",TEXT(F6,"yyyy-mm-dd")) -> SAMR · Damascone Beta · 10% in DPG · (date)
A7: Maltol (Crystals) | B7: 0.1 | C7: 10 | D7: =C7*B7 -> 1 | E7: =C7-D7 -> 9 | H7: ="SAMR · "&A7&" · 10% in DPG · "&IF(F7="","(date)",TEXT(F7,"yyyy-mm-dd")) -> SAMR · Maltol (Crystals) · 10% in DPG · (date)
A8: Aldehyde C-18 Coconut | B8: 0.1 | C8: 10 | D8: =C8*B8 -> 1 | E8: =C8-D8 -> 9 | H8: ="SAMR · "&A8&" · 10% in DPG · "&IF(F8="","(date)",TEXT(F8,"yyyy-mm-dd")) -> SAMR · Aldehyde C-18 Coconut · 10% in DPG · (date)
A11: 1 · Tare a clean 12–15 ml glass bottle on the scale (0.01 g resolution or better).
A12: 2 · Weigh the NEAT material first, then add DPG up to the total. Cap tightly and shake 1 minute.
A13: 3 · Label with the text in the last column. Store dark and cool. Dilutions keep 12+ months.
A14: 4 · When a dilution runs low, make a fresh 10 g batch and update 'Date made' and 'Remaining'.

Sheet Inventory
A1: INVENTORY
A2: On hand = purchases − usage from the Production Log. SAMR shares several jars with ASMR — each workbook tracks its own usage, so split the stock or deduct shared use manually. | F2: Conc / batch (g): | H2: =50*0.85*0.28 -> 11.9 | I2: Alcohol / batch (g): | K2: =50*0.85*0.72 -> 30.6
A3: Material | B3: Pack | C3: Unit | D3: Packs | E3: Density g/ml | F3: Grams bought | G3: Price/pack SAR | H3: Paid SAR | I3: SAR/g | J3: Used (g) | K3: On hand (g) | L3: Alert < (g) | M3: Status | N3: Product Link | O3: 50 ml bottles
A4: Bergamot Accord | B4: 10 | C4: ml | D4: 1 | E4: 0.9 | F4: =IF(C4="ml",B4*D4*E4,B4*D4) -> 9 | G4: 18.75 | H4: =G4*D4 -> 18.75 | I4: =IF(F4=0,0,H4/F4) -> 2.0833333 | J4: =TotalConcUsedG*INDEX(FM_Active,MATCH($A4,FM_Mat,0))*IF(INDEX(FM_D10,MATCH($A4,FM_Mat,0))="D10",0.1,1) -> 0 | K4: =F4-J4 -> 9 | L4: =2*DefaultBatchConcG*INDEX(FM_Active,MATCH($A4,FM_Mat,0))*IF(INDEX(FM_D10,MATCH($A4,FM_Mat,0))="D10",0.1,1) -> 1.071 | M4: =IF(K4<L4,"LOW","OK") -> OK | N4: iterji.com ↗ | O4: =IFERROR(FLOOR((MAX(K4,0)/(INDEX(FM_Active,MATCH($A4,FM_Mat,0))*IF(INDEX(FM_D10,MATCH($A4,FM_Mat,0))="D10",0.1,1)))/(50*YC_Density*YC_ConcPct),1),"") -> 16 | P4: =IF(K4<L4,A4,"") | Q4: =P4
A5: Pink Peppercorn | B5: 10 | C5: ml | D5: 1 | E5: 0.9 | F5: =IF(C5="ml",B5*D5*E5,B5*D5) -> 9 | G5: 141.25 | H5: =G5*D5 -> 141.25 | I5: =IF(F5=0,0,H5/F5) -> 15.694444 | J5: =TotalConcUsedG*INDEX(FM_Active,MATCH($A5,FM_Mat,0))*IF(INDEX(FM_D10,MATCH($A5,FM_Mat,0))="D10",0.1,1) -> 0 | K5: =F5-J5 -> 9 | L5: =2*DefaultBatchConcG*INDEX(FM_Active,MATCH($A5,FM_Mat,0))*IF(INDEX(FM_D10,MATCH($A5,FM_Mat,0))="D10",0.1,1) -> 0.0238 | M5: =IF(K5<L5,"LOW","OK") -> OK | N5: iterji.com ↗ | O5: =IFERROR(FLOOR((MAX(K5,0)/(INDEX(FM_Active,MATCH($A5,FM_Mat,0))*IF(INDEX(FM_D10,MATCH($A5,FM_Mat,0))="D10",0.1,1)))/(50*YC_Density*YC_ConcPct),1),"") -> 756 | P5: =IF(K5<L5,A5,"") | Q5: =IF(P5="",Q4,IF(Q4="",P5,Q4&", "&P5))
A6: Aldehyde C-14 Peach | B6: 10 | C6: ml | D6: 1 | E6: 0.9 | F6: =IF(C6="ml",B6*D6*E6,B6*D6) -> 9 | G6: 16.74 | H6: =G6*D6 -> 16.74 | I6: =IF(F6=0,0,H6/F6) -> 1.86 | J6: =TotalConcUsedG*INDEX(FM_Active,MATCH($A6,FM_Mat,0))*IF(INDEX(FM_D10,MATCH($A6,FM_Mat,0))="D10",0.1,1) -> 0 | K6: =F6-J6 -> 9 | L6: =2*DefaultBatchConcG*INDEX(FM_Active,MATCH($A6,FM_Mat,0))*IF(INDEX(FM_D10,MATCH($A6,FM_Mat,0))="D10",0.1,1) -> 0.476 | M6: =IF(K6<L6,"LOW","OK") -> OK | N6: iterji.com ↗ | O6: =IFERROR(FLOOR((MAX(K6,0)/(INDEX(FM_Active,MATCH($A6,FM_Mat,0))*IF(INDEX(FM_D10,MATCH($A6,FM_Mat,0))="D10",0.1,1)))/(50*YC_Density*YC_ConcPct),1),"") -> 37 | P6: =IF(K6<L6,A6,"") | Q6: =IF(P6="",Q5,IF(Q5="",P6,Q5&", "&P6))
A7: Raspberry Accord | B7: 10 | C7: ml | D7: 1 | E7: 0.9 | F7: =IF(C7="ml",B7*D7*E7,B7*D7) -> 9 | G7: 22.5 | H7: =G7*D7 -> 22.5 | I7: =IF(F7=0,0,H7/F7) -> 2.5 | J7: =TotalConcUsedG*INDEX(FM_Active,MATCH($A7,FM_Mat,0))*IF(INDEX(FM_D10,MATCH($A7,FM_Mat,0))="D10",0.1,1) -> 0 | K7: =F7-J7 -> 9 | L7: =2*DefaultBatchConcG*INDEX(FM_Active,MATCH($A7,FM_Mat,0))*IF(INDEX(FM_D10,MATCH($A7,FM_Mat,0))="D10",0.1,1) -> 0.238 | M7: =IF(K7<L7,"LOW","OK") -> OK | N7: iterji.com ↗ | O7: =IFERROR(FLOOR((MAX(K7,0)/(INDEX(FM_Active,MATCH($A7,FM_Mat,0))*IF(INDEX(FM_D10,MATCH($A7,FM_Mat,0))="D10",0.1,1)))/(50*YC_Density*YC_ConcPct),1),"") -> 75 | P7: =IF(K7<L7,A7,"") | Q7: =IF(P7="",Q6,IF(Q6="",P7,Q6&", "&P7))
A8: Hedione (Firmenich) | B8: 30 | C8: ml | D8: 1 | E8: 0.9 | F8: =IF(C8="ml",B8*D8*E8,B8*D8) -> 27 | G8: 23.9 | H8: =G8*D8 -> 23.9 | I8: =IF(F8=0,0,H8/F8) -> 0.88518519 | J8: =TotalConcUsedG*INDEX(FM_Active,MATCH($A8,FM_Mat,0))*IF(INDEX(FM_D10,MATCH($A8,FM_Mat,0))="D10",0.1,1) -> 0 | K8: =F8-J8 -> 27 | L8: =2*DefaultBatchConcG*INDEX(FM_Active,MATCH($A8,FM_Mat,0))*IF(INDEX(FM_D10,MATCH($A8,FM_Mat,0))="D10",0.1,1) -> 3.4986 | M8: =IF(K8<L8,"LOW","OK") -> OK | N8: iterji.com ↗ | O8: =IFERROR(FLOOR((MAX(K8,0)/(INDEX(FM_Active,MATCH($A8,FM_Mat,0))*IF(INDEX(FM_D10,MATCH($A8,FM_Mat,0))="D10",0.1,1)))/(50*YC_Density*YC_ConcPct),1),"") -> 15 | P8: =IF(K8<L8,A8,"") | Q8: =IF(P8="",Q7,IF(Q7="",P8,Q7&", "&P8))
A9: Jasmin Absolute Accord | B9: 10 | C9: ml | D9: 1 | E9: 0.9 | F9: =IF(C9="ml",B9*D9*E9,B9*D9) -> 9 | G9: 45 | H9: =G9*D9 -> 45 | I9: =IF(F9=0,0,H9/F9) -> 5 | J9: =TotalConcUsedG*INDEX(FM_Active,MATCH($A9,FM_Mat,0))*IF(INDEX(FM_D10,MATCH($A9,FM_Mat,0))="D10",0.1,1) -> 0 | K9: =F9-J9 -> 9 | L9: =2*DefaultBatchConcG*INDEX(FM_Active,MATCH($A9,FM_Mat,0))*IF(INDEX(FM_D10,MATCH($A9,FM_Mat,0))="D10",0.1,1) -> 0.714 | M9: =IF(K9<L9,"LOW","OK") -> OK | N9: iterji.com ↗ | O9: =IFERROR(FLOOR((MAX(K9,0)/(INDEX(FM_Active,MATCH($A9,FM_Mat,0))*IF(INDEX(FM_D10,MATCH($A9,FM_Mat,0))="D10",0.1,1)))/(50*YC_Density*YC_ConcPct),1),"") -> 25 | P9: =IF(K9<L9,A9,"") | Q9: =IF(P9="",Q8,IF(Q8="",P9,Q8&", "&P9))
A10: Tuberose Accord | B10: 10 | C10: ml | D10: 1 | E10: 0.9 | F10: =IF(C10="ml",B10*D10*E10,B10*D10) -> 9 | G10: 35.63 | H10: =G10*D10 -> 35.63 | I10: =IF(F10=0,0,H10/F10) -> 3.9588889 | J10: =TotalConcUsedG*INDEX(FM_Active,MATCH($A10,FM_Mat,0))*IF(INDEX(FM_D10,MATCH($A10,FM_Mat,0))="D10",0.1,1) -> 0 | K10: =F10-J10 -> 9 | L10: =2*DefaultBatchConcG*INDEX(FM_Active,MATCH($A10,FM_Mat,0))*IF(INDEX(FM_D10,MATCH($A10,FM_Mat,0))="D10",0.1,1) -> 0.357 | M10: =IF(K10<L10,"LOW","OK") -> OK | N10: iterji.com ↗ | O10: =IFERROR(FLOOR((MAX(K10,0)/(INDEX(FM_Active,MATCH($A10,FM_Mat,0))*IF(INDEX(FM_D10,MATCH($A10,FM_Mat,0))="D10",0.1,1)))/(50*YC_Density*YC_ConcPct),1),"") -> 50 | P10: =IF(K10<L10,A10,"") | Q10: =IF(P10="",Q9,IF(Q9="",P10,Q9&", "&P10))
A11: Methyl Alpha Ionone Iso | B11: 10 | C11: ml | D11: 1 | E11: 0.9 | F11: =IF(C11="ml",B11*D11*E11,B11*D11) -> 9 | G11: 17.46 | H11: =G11*D11 -> 17.46 | I11: =IF(F11=0,0,H11/F11) -> 1.94 | J11: =TotalConcUsedG*INDEX(FM_Active,MATCH($A11,FM_Mat,0))*IF(INDEX(FM_D10,MATCH($A11,FM_Mat,0))="D10",0.1,1) -> 0 | K11: =F11-J11 -> 9 | L11: =2*DefaultBatchConcG*INDEX(FM_Active,MATCH($A11,FM_Mat,0))*IF(INDEX(FM_D10,MATCH($A11,FM_Mat,0))="D10",0.1,1) -> 0.952 | M11: =IF(K11<L11,"LOW","OK") -> OK | N11: iterji.com ↗ | O11: =IFERROR(FLOOR((MAX(K11,0)/(INDEX(FM_Active,MATCH($A11,FM_Mat,0))*IF(INDEX(FM_D10,MATCH($A11,FM_Mat,0))="D10",0.1,1)))/(50*YC_Density*YC_ConcPct),1),"") -> 18 | P11: =IF(K11<L11,A11,"") | Q11: =IF(P11="",Q10,IF(Q10="",P11,Q10&", "&P11))
A12: Benzyl Salicylate | B12: 10 | C12: ml | D12: 1 | E12: 0.9 | F12: =IF(C12="ml",B12*D12*E12,B12*D12) -> 9 | G12: 11.16 | H12: =G12*D12 -> 11.16 | I12: =IF(F12=0,0,H12/F12) -> 1.24 | J12: =TotalConcUsedG*INDEX(FM_Active,MATCH($A12,FM_Mat,0))*IF(INDEX(FM_D10,MATCH($A12,FM_Mat,0))="D10",0.1,1) -> 0 | K12: =F12-J12 -> 9 | L12: =2*DefaultBatchConcG*INDEX(FM_Active,MATCH($A12,FM_Mat,0))*IF(INDEX(FM_D10,MATCH($A12,FM_Mat,0))="D10",0.1,1) -> 1.666 | M12: =IF(K12<L12,"LOW","OK") -> OK | N12: iterji.com ↗ | O12: =IFERROR(FLOOR((MAX(K12,0)/(INDEX(FM_Active,MATCH($A12,FM_Mat,0))*IF(INDEX(FM_D10,MATCH($A12,FM_Mat,0))="D10",0.1,1)))/(50*YC_Density*YC_ConcPct),1),"") -> 10 | P12: =IF(K12<L12,A12,"") | Q12: =IF(P12="",Q11,IF(Q11="",P12,Q11&", "&P12))
A13: Linalool | B13: 10 | C13: ml | D13: 1 | E13: 0.9 | F13: =IF(C13="ml",B13*D13*E13,B13*D13) -> 9 | G13: 16.74 | H13: =G13*D13 -> 16.74 | I13: =IF(F13=0,0,H13/F13) -> 1.86 | J13: =TotalConcUsedG*INDEX(FM_Active,MATCH($A13,FM_Mat,0))*IF(INDEX(FM_D10,MATCH($A13,FM_Mat,0))="D10",0.1,1) -> 0 | K13: =F13-J13 -> 9 | L13: =2*DefaultBatchConcG*INDEX(FM_Active,MATCH($A13,FM_Mat,0))*IF(INDEX(FM_D10,MATCH($A13,FM_Mat,0))="D10",0.1,1) -> 0.357 | M13: =IF(K13<L13,"LOW","OK") -> OK | N13: iterji.com ↗ | O13: =IFERROR(FLOOR((MAX(K13,0)/(INDEX(FM_Active,MATCH($A13,FM_Mat,0))*IF(INDEX(FM_D10,MATCH($A13,FM_Mat,0))="D10",0.1,1)))/(50*YC_Density*YC_ConcPct),1),"") -> 50 | P13: =IF(K13<L13,A13,"") | Q13: =IF(P13="",Q12,IF(Q12="",P13,Q12&", "&P13))
A14: Damascone Beta | B14: 10 | C14: ml | D14: 1 | E14: 0.9 | F14: =IF(C14="ml",B14*D14*E14,B14*D14) -> 9 | G14: 98.75 | H14: =G14*D14 -> 98.75 | I14: =IF(F14=0,0,H14/F14) -> 10.972222 | J14: =TotalConcUsedG*INDEX(FM_Active,MATCH($A14,FM_Mat,0))*IF(INDEX(FM_D10,MATCH($A14,FM_Mat,0))="D10",0.1,1) -> 0 | K14: =F14-J14 -> 9 | L14: =2*DefaultBatchConcG*INDEX(FM_Active,MATCH($A14,FM_Mat,0))*IF(INDEX(FM_D10,MATCH($A14,FM_Mat,0))="D10",0.1,1) -> 0.00714 | M14: =IF(K14<L14,"LOW","OK") -> OK | N14: iterji.com ↗ | O14: =IFERROR(FLOOR((MAX(K14,0)/(INDEX(FM_Active,MATCH($A14,FM_Mat,0))*IF(INDEX(FM_D10,MATCH($A14,FM_Mat,0))="D10",0.1,1)))/(50*YC_Density*YC_ConcPct),1),"") -> 2521 | P14: =IF(K14<L14,A14,"") | Q14: =IF(P14="",Q13,IF(Q13="",P14,Q13&", "&P14))
A15: Vanillin Crystals | B15: 10 | C15: g | D15: 1 | F15: =IF(C15="ml",B15*D15*E15,B15*D15) -> 10 | G15: 14.65 | H15: =G15*D15 -> 14.65 | I15: =IF(F15=0,0,H15/F15) -> 1.465 | J15: =TotalConcUsedG*INDEX(FM_Active,MATCH($A15,FM_Mat,0))*IF(INDEX(FM_D10,MATCH($A15,FM_Mat,0))="D10",0.1,1) -> 0 | K15: =F15-J15 -> 10 | L15: =2*DefaultBatchConcG*INDEX(FM_Active,MATCH($A15,FM_Mat,0))*IF(INDEX(FM_D10,MATCH($A15,FM_Mat,0))="D10",0.1,1) -> 1.547 | M15: =IF(K15<L15,"LOW","OK") -> OK | N15: iterji.com ↗ | O15: =IFERROR(FLOOR((MAX(K15,0)/(INDEX(FM_Active,MATCH($A15,FM_Mat,0))*IF(INDEX(FM_D10,MATCH($A15,FM_Mat,0))="D10",0.1,1)))/(50*YC_Density*YC_ConcPct),1),"") -> 12 | P15: =IF(K15<L15,A15,"") | Q15: =IF(P15="",Q14,IF(Q14="",P15,Q14&", "&P15))
A16: Ethyl Vanillin | B16: 10 | C16: g | D16: 1 | F16: =IF(C16="ml",B16*D16*E16,B16*D16) -> 10 | G16: 15.69 | H16: =G16*D16 -> 15.69 | I16: =IF(F16=0,0,H16/F16) -> 1.569 | J16: =TotalConcUsedG*INDEX(FM_Active,MATCH($A16,FM_Mat,0))*IF(INDEX(FM_D10,MATCH($A16,FM_Mat,0))="D10",0.1,1) -> 0 | K16: =F16-J16 -> 10 | L16: =2*DefaultBatchConcG*INDEX(FM_Active,MATCH($A16,FM_Mat,0))*IF(INDEX(FM_D10,MATCH($A16,FM_Mat,0))="D10",0.1,1) -> 0.595 | M16: =IF(K16<L16,"LOW","OK") -> OK | N16: iterji.com ↗ | O16: =IFERROR(FLOOR((MAX(K16,0)/(INDEX(FM_Active,MATCH($A16,FM_Mat,0))*IF(INDEX(FM_D10,MATCH($A16,FM_Mat,0))="D10",0.1,1)))/(50*YC_Density*YC_ConcPct),1),"") -> 33 | P16: =IF(K16<L16,A16,"") | Q16: =IF(P16="",Q15,IF(Q15="",P16,Q15&", "&P16))
A17: Maltol (Crystals) | B17: 10 | C17: g | D17: 1 | F17: =IF(C17="ml",B17*D17*E17,B17*D17) -> 10 | G17: 26.51 | H17: =G17*D17 -> 26.51 | I17: =IF(F17=0,0,H17/F17) -> 2.651 | J17: =TotalConcUsedG*INDEX(FM_Active,MATCH($A17,FM_Mat,0))*IF(INDEX(FM_D10,MATCH($A17,FM_Mat,0))="D10",0.1,1) -> 0 | K17: =F17-J17 -> 10 | L17: =2*DefaultBatchConcG*INDEX(FM_Active,MATCH($A17,FM_Mat,0))*IF(INDEX(FM_D10,MATCH($A17,FM_Mat,0))="D10",0.1,1) -> 0.0476 | M17: =IF(K17<L17,"LOW","OK") -> OK | N17: iterji.com ↗ | O17: =IFERROR(FLOOR((MAX(K17,0)/(INDEX(FM_Active,MATCH($A17,FM_Mat,0))*IF(INDEX(FM_D10,MATCH($A17,FM_Mat,0))="D10",0.1,1)))/(50*YC_Density*YC_ConcPct),1),"") -> 420 | P17: =IF(K17<L17,A17,"") | Q17: =IF(P17="",Q16,IF(Q16="",P17,Q16&", "&P17))
A18: Coumarin | B18: 500 | C18: g | D18: 1 | F18: =IF(C18="ml",B18*D18*E18,B18*D18) -> 500 | G18: 150 | H18: =G18*D18 -> 150 | I18: =IF(F18=0,0,H18/F18) -> 0.3 | J18: =TotalConcUsedG*INDEX(FM_Active,MATCH($A18,FM_Mat,0))*IF(INDEX(FM_D10,MATCH($A18,FM_Mat,0))="D10",0.1,1) -> 0 | K18: =F18-J18 -> 500 | L18: =2*DefaultBatchConcG*INDEX(FM_Active,MATCH($A18,FM_Mat,0))*IF(INDEX(FM_D10,MATCH($A18,FM_Mat,0))="D10",0.1,1) -> 1.19 | M18: =IF(K18<L18,"LOW","OK") -> OK | N18: iterji.com ↗ | O18: =IFERROR(FLOOR((MAX(K18,0)/(INDEX(FM_Active,MATCH($A18,FM_Mat,0))*IF(INDEX(FM_D10,MATCH($A18,FM_Mat,0))="D10",0.1,1)))/(50*YC_Density*YC_ConcPct),1),"") -> 840 | P18: =IF(K18<L18,A18,"") | Q18: =IF(P18="",Q17,IF(Q17="",P18,Q17&", "&P18))
A19: Heliotrope Accord | B19: 10 | C19: ml | D19: 1 | E19: 0.9 | F19: =IF(C19="ml",B19*D19*E19,B19*D19) -> 9 | G19: 33.75 | H19: =G19*D19 -> 33.75 | I19: =IF(F19=0,0,H19/F19) -> 3.75 | J19: =TotalConcUsedG*INDEX(FM_Active,MATCH($A19,FM_Mat,0))*IF(INDEX(FM_D10,MATCH($A19,FM_Mat,0))="D10",0.1,1) -> 0 | K19: =F19-J19 -> 9 | L19: =2*DefaultBatchConcG*INDEX(FM_Active,MATCH($A19,FM_Mat,0))*IF(INDEX(FM_D10,MATCH($A19,FM_Mat,0))="D10",0.1,1) -> 0.595 | M19: =IF(K19<L19,"LOW","OK") -> OK | N19: iterji.com ↗ | O19: =IFERROR(FLOOR((MAX(K19,0)/(INDEX(FM_Active,MATCH($A19,FM_Mat,0))*IF(INDEX(FM_D10,MATCH($A19,FM_Mat,0))="D10",0.1,1)))/(50*YC_Density*YC_ConcPct),1),"") -> 30 | P19: =IF(K19<L19,A19,"") | Q19: =IF(P19="",Q18,IF(Q18="",P19,Q18&", "&P19))
A20: Aldehyde C-18 Coconut | B20: 10 | C20: ml | D20: 1 | E20: 0.9 | F20: =IF(C20="ml",B20*D20*E20,B20*D20) -> 9 | G20: 13.25 | H20: =G20*D20 -> 13.25 | I20: =IF(F20=0,0,H20/F20) -> 1.4722222 | J20: =TotalConcUsedG*INDEX(FM_Active,MATCH($A20,FM_Mat,0))*IF(INDEX(FM_D10,MATCH($A20,FM_Mat,0))="D10",0.1,1) -> 0 | K20: =F20-J20 -> 9 | L20: =2*DefaultBatchConcG*INDEX(FM_Active,MATCH($A20,FM_Mat,0))*IF(INDEX(FM_D10,MATCH($A20,FM_Mat,0))="D10",0.1,1) -> 0.0357 | M20: =IF(K20<L20,"LOW","OK") -> OK | N20: iterji.com ↗ | O20: =IFERROR(FLOOR((MAX(K20,0)/(INDEX(FM_Active,MATCH($A20,FM_Mat,0))*IF(INDEX(FM_D10,MATCH($A20,FM_Mat,0))="D10",0.1,1)))/(50*YC_Density*YC_ConcPct),1),"") -> 504 | P20: =IF(K20<L20,A20,"") | Q20: =IF(P20="",Q19,IF(Q19="",P20,Q19&", "&P20))
A21: Ambroxan | B21: 10 | C21: g | D21: 1 | F21: =IF(C21="ml",B21*D21*E21,B21*D21) -> 10 | G21: 133.75 | H21: =G21*D21 -> 133.75 | I21: =IF(F21=0,0,H21/F21) -> 13.375 | J21: =TotalConcUsedG*INDEX(FM_Active,MATCH($A21,FM_Mat,0))*IF(INDEX(FM_D10,MATCH($A21,FM_Mat,0))="D10",0.1,1) -> 0 | K21: =F21-J21 -> 10 | L21: =2*DefaultBatchConcG*INDEX(FM_Active,MATCH($A21,FM_Mat,0))*IF(INDEX(FM_D10,MATCH($A21,FM_Mat,0))="D10",0.1,1) -> 1.785 | M21: =IF(K21<L21,"LOW","OK") -> OK | N21: iterji.com ↗ | O21: =IFERROR(FLOOR((MAX(K21,0)/(INDEX(FM_Active,MATCH($A21,FM_Mat,0))*IF(INDEX(FM_D10,MATCH($A21,FM_Mat,0))="D10",0.1,1)))/(50*YC_Density*YC_ConcPct),1),"") -> 11 | P21: =IF(K21<L21,A21,"") | Q21: =IF(P21="",Q20,IF(Q20="",P21,Q20&", "&P21))
A22: Iso E Super | B22: 10 | C22: ml | D22: 1 | E22: 0.9 | F22: =IF(C22="ml",B22*D22*E22,B22*D22) -> 9 | G22: 13.6 | H22: =G22*D22 -> 13.6 | I22: =IF(F22=0,0,H22/F22) -> 1.5111111 | J22: =TotalConcUsedG*INDEX(FM_Active,MATCH($A22,FM_Mat,0))*IF(INDEX(FM_D10,MATCH($A22,FM_Mat,0))="D10",0.1,1) -> 0 | K22: =F22-J22 -> 9 | L22: =2*DefaultBatchConcG*INDEX(FM_Active,MATCH($A22,FM_Mat,0))*IF(INDEX(FM_D10,MATCH($A22,FM_Mat,0))="D10",0.1,1) -> 2.261 | M22: =IF(K22<L22,"LOW","OK") -> OK | N22: iterji.com ↗ | O22: =IFERROR(FLOOR((MAX(K22,0)/(INDEX(FM_Active,MATCH($A22,FM_Mat,0))*IF(INDEX(FM_D10,MATCH($A22,FM_Mat,0))="D10",0.1,1)))/(50*YC_Density*YC_ConcPct),1),"") -> 7 | P22: =IF(K22<L22,A22,"") | Q22: =IF(P22="",Q21,IF(Q21="",P22,Q21&", "&P22))
A23: Cashmeran IFF | B23: 10 | C23: ml | D23: 1 | E23: 0.9 | F23: =IF(C23="ml",B23*D23*E23,B23*D23) -> 9 | G23: 55.86 | H23: =G23*D23 -> 55.86 | I23: =IF(F23=0,0,H23/F23) -> 6.2066667 | J23: =TotalConcUsedG*INDEX(FM_Active,MATCH($A23,FM_Mat,0))*IF(INDEX(FM_D10,MATCH($A23,FM_Mat,0))="D10",0.1,1) -> 0 | K23: =F23-J23 -> 9 | L23: =2*DefaultBatchConcG*INDEX(FM_Active,MATCH($A23,FM_Mat,0))*IF(INDEX(FM_D10,MATCH($A23,FM_Mat,0))="D10",0.1,1) -> 0.714 | M23: =IF(K23<L23,"LOW","OK") -> OK | N23: iterji.com ↗ | O23: =IFERROR(FLOOR((MAX(K23,0)/(INDEX(FM_Active,MATCH($A23,FM_Mat,0))*IF(INDEX(FM_D10,MATCH($A23,FM_Mat,0))="D10",0.1,1)))/(50*YC_Density*YC_ConcPct),1),"") -> 25 | P23: =IF(K23<L23,A23,"") | Q23: =IF(P23="",Q22,IF(Q22="",P23,Q22&", "&P23))
A24: Sandalore (Givaudan) | B24: 10 | C24: ml | D24: 1 | E24: 0.9 | F24: =IF(C24="ml",B24*D24*E24,B24*D24) -> 9 | G24: 23.54 | H24: =G24*D24 -> 23.54 | I24: =IF(F24=0,0,H24/F24) -> 2.6155556 | J24: =TotalConcUsedG*INDEX(FM_Active,MATCH($A24,FM_Mat,0))*IF(INDEX(FM_D10,MATCH($A24,FM_Mat,0))="D10",0.1,1) -> 0 | K24: =F24-J24 -> 9 | L24: =2*DefaultBatchConcG*INDEX(FM_Active,MATCH($A24,FM_Mat,0))*IF(INDEX(FM_D10,MATCH($A24,FM_Mat,0))="D10",0.1,1) -> 0.833 | M24: =IF(K24<L24,"LOW","OK") -> OK | N24: iterji.com ↗ | O24: =IFERROR(FLOOR((MAX(K24,0)/(INDEX(FM_Active,MATCH($A24,FM_Mat,0))*IF(INDEX(FM_D10,MATCH($A24,FM_Mat,0))="D10",0.1,1)))/(50*YC_Density*YC_ConcPct),1),"") -> 21 | P24: =IF(K24<L24,A24,"") | Q24: =IF(P24="",Q23,IF(Q23="",P24,Q23&", "&P24))
A25: Ethylene Brassylate | B25: 10 | C25: ml | D25: 1 | E25: 0.9 | F25: =IF(C25="ml",B25*D25*E25,B25*D25) -> 9 | G25: 10.11 | H25: =G25*D25 -> 10.11 | I25: =IF(F25=0,0,H25/F25) -> 1.1233333 | J25: =TotalConcUsedG*INDEX(FM_Active,MATCH($A25,FM_Mat,0))*IF(INDEX(FM_D10,MATCH($A25,FM_Mat,0))="D10",0.1,1) -> 0 | K25: =F25-J25 -> 9 | L25: =2*DefaultBatchConcG*INDEX(FM_Active,MATCH($A25,FM_Mat,0))*IF(INDEX(FM_D10,MATCH($A25,FM_Mat,0))="D10",0.1,1) -> 1.785 | M25: =IF(K25<L25,"LOW","OK") -> OK | N25: iterji.com ↗ | O25: =IFERROR(FLOOR((MAX(K25,0)/(INDEX(FM_Active,MATCH($A25,FM_Mat,0))*IF(INDEX(FM_D10,MATCH($A25,FM_Mat,0))="D10",0.1,1)))/(50*YC_Density*YC_ConcPct),1),"") -> 10 | P25: =IF(K25<L25,A25,"") | Q25: =IF(P25="",Q24,IF(Q24="",P25,Q24&", "&P25))
A26: Galaxolide | B26: 30 | C26: ml | D26: 1 | E26: 0.9 | F26: =IF(C26="ml",B26*D26*E26,B26*D26) -> 27 | G26: 27 | H26: =G26*D26 -> 27 | I26: =IF(F26=0,0,H26/F26) -> 1 | J26: =TotalConcUsedG*INDEX(FM_Active,MATCH($A26,FM_Mat,0))*IF(INDEX(FM_D10,MATCH($A26,FM_Mat,0))="D10",0.1,1) -> 0 | K26: =F26-J26 -> 27 | L26: =2*DefaultBatchConcG*INDEX(FM_Active,MATCH($A26,FM_Mat,0))*IF(INDEX(FM_D10,MATCH($A26,FM_Mat,0))="D10",0.1,1) -> 1.309 | M26: =IF(K26<L26,"LOW","OK") -> OK | N26: iterji.com ↗ | O26: =IFERROR(FLOOR((MAX(K26,0)/(INDEX(FM_Active,MATCH($A26,FM_Mat,0))*IF(INDEX(FM_D10,MATCH($A26,FM_Mat,0))="D10",0.1,1)))/(50*YC_Density*YC_ConcPct),1),"") -> 41 | P26: =IF(K26<L26,A26,"") | Q26: =IF(P26="",Q25,IF(Q25="",P26,Q25&", "&P26))
A27: Exaltolide Total (Firmenich) | B27: 10 | C27: ml | D27: 1 | E27: 0.9 | F27: =IF(C27="ml",B27*D27*E27,B27*D27) -> 9 | G27: 27.53 | H27: =G27*D27 -> 27.53 | I27: =IF(F27=0,0,H27/F27) -> 3.0588889 | J27: =TotalConcUsedG*INDEX(FM_Active,MATCH($A27,FM_Mat,0))*IF(INDEX(FM_D10,MATCH($A27,FM_Mat,0))="D10",0.1,1) -> 0 | K27: =F27-J27 -> 9 | L27: =2*DefaultBatchConcG*INDEX(FM_Active,MATCH($A27,FM_Mat,0))*IF(INDEX(FM_D10,MATCH($A27,FM_Mat,0))="D10",0.1,1) -> 0.595 | M27: =IF(K27<L27,"LOW","OK") -> OK | N27: iterji.com ↗ | O27: =IFERROR(FLOOR((MAX(K27,0)/(INDEX(FM_Active,MATCH($A27,FM_Mat,0))*IF(INDEX(FM_D10,MATCH($A27,FM_Mat,0))="D10",0.1,1)))/(50*YC_Density*YC_ConcPct),1),"") -> 30 | P27: =IF(K27<L27,A27,"") | Q27: =IF(P27="",Q26,IF(Q26="",P27,Q26&", "&P27))
A28: Saffron Accord | B28: 10 | C28: ml | D28: 1 | E28: 0.9 | F28: =IF(C28="ml",B28*D28*E28,B28*D28) -> 9 | G28: 33.75 | H28: =G28*D28 -> 33.75 | I28: =IF(F28=0,0,H28/F28) -> 3.75 | J28: =TotalConcUsedG*INDEX(FM_Active,MATCH($A28,FM_Mat,0))*IF(INDEX(FM_D10,MATCH($A28,FM_Mat,0))="D10",0.1,1) -> 0 | K28: =F28-J28 -> 9 | L28: =2*DefaultBatchConcG*INDEX(FM_Active,MATCH($A28,FM_Mat,0))*IF(INDEX(FM_D10,MATCH($A28,FM_Mat,0))="D10",0.1,1) -> 0.119 | M28: =IF(K28<L28,"LOW","OK") -> OK | N28: iterji.com ↗ | O28: =IFERROR(FLOOR((MAX(K28,0)/(INDEX(FM_Active,MATCH($A28,FM_Mat,0))*IF(INDEX(FM_D10,MATCH($A28,FM_Mat,0))="D10",0.1,1)))/(50*YC_Density*YC_ConcPct),1),"") -> 151 | P28: =IF(K28<L28,A28,"") | Q28: =IF(P28="",Q27,IF(Q27="",P28,Q27&", "&P28))
A29: DPG (Dipropylene Glycol) | B29: 500 | C29: ml | D29: 1 | E29: 1.02 | F29: =IF(C29="ml",B29*D29*E29,B29*D29) -> 510 | G29: 50 | H29: =G29*D29 -> 50 | I29: =IF(F29=0,0,H29/F29) -> 0.098039216 | J29: =TotalConcUsedG*D10ActivePct*0.9 -> 0 | K29: =F29-J29 -> 510 | L29: =2*DefaultBatchConcG*D10ActivePct*0.9 -> 1.02816 | M29: =IF(K29<L29,"LOW","OK") -> OK | N29: iterji.com ↗ | O29: =IFERROR(FLOOR((MAX(K29,0)/(D10ActivePct*0.9))/(50*YC_Density*YC_ConcPct),1),"") -> 992 | P29: =IF(K29<L29,A29,"") | Q29: =IF(P29="",Q28,IF(Q28="",P29,Q28&", "&P29))
A30: Alcohol 190 proof SDA 40B | B30: 5000 | C30: ml | D30: 1 | E30: 0.81 | F30: =IF(C30="ml",B30*D30*E30,B30*D30) -> 4050 | G30: 150 | H30: =G30*D30 -> 150 | I30: =IF(F30=0,0,H30/F30) -> 0.037037037 | J30: =AlcoholUsedG -> 0 | K30: =F30-J30 -> 4050 | L30: =2*DefaultBatchAlcG -> 61.2 | M30: =IF(K30<L30,"LOW","OK") -> OK | N30: iterji.com ↗ | O30: =IFERROR(FLOOR(MAX(K30,0)/(50*YC_Density*(1-YC_ConcPct)),1),"") -> 132 | P30: =IF(K30<L30,A30,"") | Q30: =IF(P30="",Q29,IF(Q29="",P30,Q29&", "&P30))
A31: TOTAL PAID (SAR) | H31: =SUM(H4:H30) -> 1226.87

Sheet Inventory Bottles
A1: INVENTORY & BOTTLES
A2: One live view of stock, bottle capacity by size, and which material increases output if you buy more.
A3: Bottle size | B3: 10 | C3: 20 | D3: 30 | E3: 50 | F3: 70 | G3: 100 | H3: Current | I3: Type trial purchase quantities in "Add packs". Projected bottles update immediately. Gold rows are materials where +1 pack can raise the 50 ml output; red rows are the current bottleneck.
B4: =MIN(K7:K33) -> 39 | C4: =MIN(L7:L33) -> 19 | D4: =MIN(M7:M33) -> 13 | E4: =MIN(N7:N33) -> 7 | F4: =MIN(O7:O33) -> 5 | G4: =MIN(P7:P33) -> 3 | H4: Projected
B5: =MIN(Q7:Q33) -> 39 | C5: =MIN(R7:R33) -> 19 | D5: =MIN(S7:S33) -> 13 | E5: =MIN(T7:T33) -> 7 | F5: =MIN(U7:U33) -> 5 | G5: =MIN(V7:V33) -> 3
A6: Material | B6: Pack | C6: Unit | D6: Packs | E6: Add packs | F6: Density | G6: On hand g | H6: Projected g | I6: Active % | J6: Use / g conc | K6: Cur 10 | L6: Cur 20 | M6: Cur 30 | N6: Cur 50 | O6: Cur 70 | P6: Cur 100 | Q6: Proj 10 | R6: Proj 20 | S6: Proj 30 | T6: Proj 50 | U6: Proj 70 | V6: Proj 100 | W6: +50 if +1 pack | X6: Priority | Y6: Product
A7: =Inventory!A4 -> Bergamot Accord | B7: =Inventory!B4 -> 10 | C7: =Inventory!C4 -> ml | D7: =Inventory!D4 -> 1 | E7: 0 | F7: =Inventory!E4 -> 0.9 | G7: =Inventory!K4 -> 9 | H7: =G7+E7*IF(C7="ml",B7*F7,B7) -> 9 | I7: =IF(A7="DPG (Dipropylene Glycol)",D10ActivePct,IFERROR(INDEX(FM_Active,MATCH(A7,FM_Mat,0)),"")) -> 0.045 | J7: =IF(A7="DPG (Dipropylene Glycol)",D10ActivePct*0.9,IF(A7="Alcohol 190 proof SDA 40B","",IFERROR(I7*IF(INDEX(FM_D10,MATCH(A7,FM_Mat,0))="D10",0.1,1),""))) -> 0.045 | K7: =IF($A7="","",IF($A7="DPG (Dipropylene Glycol)",IFERROR(FLOOR((MAX($G7,0)/(D10ActivePct*0.9))/(10*YC_Density*YC_ConcPct),1),""),IF($A7="Alcohol 190 proof SDA 40B",IFERROR(FLOOR(MAX($G7,0)/(10*YC_Density*(1-YC_ConcPct)),1),""),IFERROR(FLOOR((MAX($G7,0)/(INDEX(FM_Active,MATCH($A7,FM_Mat,0))*IF(INDEX(FM_D10,MATCH($A7,FM_Mat,0))="D10",0.1,1)))/(10*YC_Density*YC_ConcPct),1),"")))) -> 84 | L7: =IF($A7="","",IF($A7="DPG (Dipropylene Glycol)",IFERROR(FLOOR((MAX($G7,0)/(D10ActivePct*0.9))/(20*YC_Density*YC_ConcPct),1),""),IF($A7="Alcohol 190 proof SDA 40B",IFERROR(FLOOR(MAX($G7,0)/(20*YC_Density*(1-YC_ConcPct)),1),""),IFERROR(FLOOR((MAX($G7,0)/(INDEX(FM_Active,MATCH($A7,FM_Mat,0))*IF(INDEX(FM_D10,MATCH($A7,FM_Mat,0))="D10",0.1,1)))/(20*YC_Density*YC_ConcPct),1),"")))) -> 42 | M7: =IF($A7="","",IF($A7="DPG (Dipropylene Glycol)",IFERROR(FLOOR((MAX($G7,0)/(D10ActivePct*0.9))/(30*YC_Density*YC_ConcPct),1),""),IF($A7="Alcohol 190 proof SDA 40B",IFERROR(FLOOR(MAX($G7,0)/(30*YC_Density*(1-YC_ConcPct)),1),""),IFERROR(FLOOR((MAX($G7,0)/(INDEX(FM_Active,MATCH($A7,FM_Mat,0))*IF(INDEX(FM_D10,MATCH($A7,FM_Mat,0))="D10",0.1,1)))/(30*YC_Density*YC_ConcPct),1),"")))) -> 28 | N7: =IF($A7="","",IF($A7="DPG (Dipropylene Glycol)",IFERROR(FLOOR((MAX($G7,0)/(D10ActivePct*0.9))/(50*YC_Density*YC_ConcPct),1),""),IF($A7="Alcohol 190 proof SDA 40B",IFERROR(FLOOR(MAX($G7,0)/(50*YC_Density*(1-YC_ConcPct)),1),""),IFERROR(FLOOR((MAX($G7,0)/(INDEX(FM_Active,MATCH($A7,FM_Mat,0))*IF(INDEX(FM_D10,MATCH($A7,FM_Mat,0))="D10",0.1,1)))/(50*YC_Density*YC_ConcPct),1),"")))) -> 16 | O7: =IF($A7="","",IF($A7="DPG (Dipropylene Glycol)",IFERROR(FLOOR((MAX($G7,0)/(D10ActivePct*0.9))/(70*YC_Density*YC_ConcPct),1),""),IF($A7="Alcohol 190 proof SDA 40B",IFERROR(FLOOR(MAX($G7,0)/(70*YC_Density*(1-YC_ConcPct)),1),""),IFERROR(FLOOR((MAX($G7,0)/(INDEX(FM_Active,MATCH($A7,FM_Mat,0))*IF(INDEX(FM_D10,MATCH($A7,FM_Mat,0))="D10",0.1,1)))/(70*YC_Density*YC_ConcPct),1),"")))) -> 12 | P7: =IF($A7="","",IF($A7="DPG (Dipropylene Glycol)",IFERROR(FLOOR((MAX($G7,0)/(D10ActivePct*0.9))/(100*YC_Density*YC_ConcPct),1),""),IF($A7="Alcohol 190 proof SDA 40B",IFERROR(FLOOR(MAX($G7,0)/(100*YC_Density*(1-YC_ConcPct)),1),""),IFERROR(FLOOR((MAX($G7,0)/(INDEX(FM_Active,MATCH($A7,FM_Mat,0))*IF(INDEX(FM_D10,MATCH($A7,FM_Mat,0))="D10",0.1,1)))/(100*YC_Density*YC_ConcPct),1),"")))) -> 8 | Q7: =IF($A7="","",IF($A7="DPG (Dipropylene Glycol)",IFERROR(FLOOR((MAX($H7,0)/(D10ActivePct*0.9))/(10*YC_Density*YC_ConcPct),1),""),IF($A7="Alcohol 190 proof SDA 40B",IFERROR(FLOOR(MAX($H7,0)/(10*YC_Density*(1-YC_ConcPct)),1),""),IFERROR(FLOOR((MAX($H7,0)/(INDEX(FM_Active,MATCH($A7,FM_Mat,0))*IF(INDEX(FM_D10,MATCH($A7,FM_Mat,0))="D10",0.1,1)))/(10*YC_Density*YC_ConcPct),1),"")))) -> 84 | R7: =IF($A7="","",IF($A7="DPG (Dipropylene Glycol)",IFERROR(FLOOR((MAX($H7,0)/(D10ActivePct*0.9))/(20*YC_Density*YC_ConcPct),1),""),IF($A7="Alcohol 190 proof SDA 40B",IFERROR(FLOOR(MAX($H7,0)/(20*YC_Density*(1-YC_ConcPct)),1),""),IFERROR(FLOOR((MAX($H7,0)/(INDEX(FM_Active,MATCH($A7,FM_Mat,0))*IF(INDEX(FM_D10,MATCH($A7,FM_Mat,0))="D10",0.1,1)))/(20*YC_Density*YC_ConcPct),1),"")))) -> 42 | S7: =IF($A7="","",IF($A7="DPG (Dipropylene Glycol)",IFERROR(FLOOR((MAX($H7,0)/(D10ActivePct*0.9))/(30*YC_Density*YC_ConcPct),1),""),IF($A7="Alcohol 190 proof SDA 40B",IFERROR(FLOOR(MAX($H7,0)/(30*YC_Density*(1-YC_ConcPct)),1),""),IFERROR(FLOOR((MAX($H7,0)/(INDEX(FM_Active,MATCH($A7,FM_Mat,0))*IF(INDEX(FM_D10,MATCH($A7,FM_Mat,0))="D10",0.1,1)))/(30*YC_Density*YC_ConcPct),1),"")))) -> 28 | T7: =IF($A7="","",IF($A7="DPG (Dipropylene Glycol)",IFERROR(FLOOR((MAX($H7,0)/(D10ActivePct*0.9))/(50*YC_Density*YC_ConcPct),1),""),IF($A7="Alcohol 190 proof SDA 40B",IFERROR(FLOOR(MAX($H7,0)/(50*YC_Density*(1-YC_ConcPct)),1),""),IFERROR(FLOOR((MAX($H7,0)/(INDEX(FM_Active,MATCH($A7,FM_Mat,0))*IF(INDEX(FM_D10,MATCH($A7,FM_Mat,0))="D10",0.1,1)))/(50*YC_Density*YC_ConcPct),1),"")))) -> 16 | U7: =IF($A7="","",IF($A7="DPG (Dipropylene Glycol)",IFERROR(FLOOR((MAX($H7,0)/(D10ActivePct*0.9))/(70*YC_Density*YC_ConcPct),1),""),IF($A7="Alcohol 190 proof SDA 40B",IFERROR(FLOOR(MAX($H7,0)/(70*YC_Density*(1-YC_ConcPct)),1),""),IFERROR(FLOOR((MAX($H7,0)/(INDEX(FM_Active,MATCH($A7,FM_Mat,0))*IF(INDEX(FM_D10,MATCH($A7,FM_Mat,0))="D10",0.1,1)))/(70*YC_Density*YC_ConcPct),1),"")))) -> 12 | V7: =IF($A7="","",IF($A7="DPG (Dipropylene Glycol)",IFERROR(FLOOR((MAX($H7,0)/(D10ActivePct*0.9))/(100*YC_Density*YC_ConcPct),1),""),IF($A7="Alcohol 190 proof SDA 40B",IFERROR(FLOOR(MAX($H7,0)/(100*YC_Density*(1-YC_ConcPct)),1),""),IFERROR(FLOOR((MAX($H7,0)/(INDEX(FM_Active,MATCH($A7,FM_Mat,0))*IF(INDEX(FM_D10,MATCH($A7,FM_Mat,0))="D10",0.1,1)))/(100*YC_Density*YC_ConcPct),1),"")))) -> 8 | W7: =IF($N7="","",MAX(0,MIN(IF($A7="","",IF($A7="DPG (Dipropylene Glycol)",IFERROR(FLOOR((MAX(($G7+IF($C7="ml",$B7*$F7,$B7)),0)/(D10ActivePct*0.9))/(50*YC_Density*YC_ConcPct),1),""),IF($A7="Alcohol 190 proof SDA 40B",IFERROR(FLOOR(MAX(($G7+IF($C7="ml",$B7*$F7,$B7)),0)/(50*YC_Density*(1-YC_ConcPct)),1),""),IFERROR(FLOOR((MAX(($G7+IF($C7="ml",$B7*$F7,$B7)),0)/(INDEX(FM_Active,MATCH($A7,FM_Mat,0))*IF(INDEX(FM_D10,MATCH($A7,FM_Mat,0))="D10",0.1,1)))/(50*YC_Density*YC_ConcPct),1),"")))),MIN($N$8:$N$33))-$E$4)) -> 0 | X7: =IF(AND(ISNUMBER(W7),W7>0),"BUY MORE - raises output",IF(AND(ISNUMBER(N7),N7=$E$4),"CURRENT BOTTLENECK",IF(AND(ISNUMBER(N7),N7<=$E$4+2),"NEXT LIMIT",""))) | Y7: open
A8: =Inventory!A5 -> Pink Peppercorn | B8: =Inventory!B5 -> 10 | C8: =Inventory!C5 -> ml | D8: =Inventory!D5 -> 1 | E8: 0 | F8: =Inventory!E5 -> 0.9 | G8: =Inventory!K5 -> 9 | H8: =G8+E8*IF(C8="ml",B8*F8,B8) -> 9 | I8: =IF(A8="DPG (Dipropylene Glycol)",D10ActivePct,IFERROR(INDEX(FM_Active,MATCH(A8,FM_Mat,0)),"")) -> 0.01 | J8: =IF(A8="DPG (Dipropylene Glycol)",D10ActivePct*0.9,IF(A8="Alcohol 190 proof SDA 40B","",IFERROR(I8*IF(INDEX(FM_D10,MATCH(A8,FM_Mat,0))="D10",0.1,1),""))) -> 0.001 | K8: =IF($A8="","",IF($A8="DPG (Dipropylene Glycol)",IFERROR(FLOOR((MAX($G8,0)/(D10ActivePct*0.9))/(10*YC_Density*YC_ConcPct),1),""),IF($A8="Alcohol 190 proof SDA 40B",IFERROR(FLOOR(MAX($G8,0)/(10*YC_Density*(1-YC_ConcPct)),1),""),IFERROR(FLOOR((MAX($G8,0)/(INDEX(FM_Active,MATCH($A8,FM_Mat,0))*IF(INDEX(FM_D10,MATCH($A8,FM_Mat,0))="D10",0.1,1)))/(10*YC_Density*YC_ConcPct),1),"")))) -> 3781 | L8: =IF($A8="","",IF($A8="DPG (Dipropylene Glycol)",IFERROR(FLOOR((MAX($G8,0)/(D10ActivePct*0.9))/(20*YC_Density*YC_ConcPct),1),""),IF($A8="Alcohol 190 proof SDA 40B",IFERROR(FLOOR(MAX($G8,0)/(20*YC_Density*(1-YC_ConcPct)),1),""),IFERROR(FLOOR((MAX($G8,0)/(INDEX(FM_Active,MATCH($A8,FM_Mat,0))*IF(INDEX(FM_D10,MATCH($A8,FM_Mat,0))="D10",0.1,1)))/(20*YC_Density*YC_ConcPct),1),"")))) -> 1890 | M8: =IF($A8="","",IF($A8="DPG (Dipropylene Glycol)",IFERROR(FLOOR((MAX($G8,0)/(D10ActivePct*0.9))/(30*YC_Density*YC_ConcPct),1),""),IF($A8="Alcohol 190 proof SDA 40B",IFERROR(FLOOR(MAX($G8,0)/(30*YC_Density*(1-YC_ConcPct)),1),""),IFERROR(FLOOR((MAX($G8,0)/(INDEX(FM_Active,MATCH($A8,FM_Mat,0))*IF(INDEX(FM_D10,MATCH($A8,FM_Mat,0))="D10",0.1,1)))/(30*YC_Density*YC_ConcPct),1),"")))) -> 1260 | N8: =IF($A8="","",IF($A8="DPG (Dipropylene Glycol)",IFERROR(FLOOR((MAX($G8,0)/(D10ActivePct*0.9))/(50*YC_Density*YC_ConcPct),1),""),IF($A8="Alcohol 190 proof SDA 40B",IFERROR(FLOOR(MAX($G8,0)/(50*YC_Density*(1-YC_ConcPct)),1),""),IFERROR(FLOOR((MAX($G8,0)/(INDEX(FM_Active,MATCH($A8,FM_Mat,0))*IF(INDEX(FM_D10,MATCH($A8,FM_Mat,0))="D10",0.1,1)))/(50*YC_Density*YC_ConcPct),1),"")))) -> 756 | O8: =IF($A8="","",IF($A8="DPG (Dipropylene Glycol)",IFERROR(FLOOR((MAX($G8,0)/(D10ActivePct*0.9))/(70*YC_Density*YC_ConcPct),1),""),IF($A8="Alcohol 190 proof SDA 40B",IFERROR(FLOOR(MAX($G8,0)/(70*YC_Density*(1-YC_ConcPct)),1),""),IFERROR(FLOOR((MAX($G8,0)/(INDEX(FM_Active,MATCH($A8,FM_Mat,0))*IF(INDEX(FM_D10,MATCH($A8,FM_Mat,0))="D10",0.1,1)))/(70*YC_Density*YC_ConcPct),1),"")))) -> 540 | P8: =IF($A8="","",IF($A8="DPG (Dipropylene Glycol)",IFERROR(FLOOR((MAX($G8,0)/(D10ActivePct*0.9))/(100*YC_Density*YC_ConcPct),1),""),IF($A8="Alcohol 190 proof SDA 40B",IFERROR(FLOOR(MAX($G8,0)/(100*YC_Density*(1-YC_ConcPct)),1),""),IFERROR(FLOOR((MAX($G8,0)/(INDEX(FM_Active,MATCH($A8,FM_Mat,0))*IF(INDEX(FM_D10,MATCH($A8,FM_Mat,0))="D10",0.1,1)))/(100*YC_Density*YC_ConcPct),1),"")))) -> 378 | Q8: =IF($A8="","",IF($A8="DPG (Dipropylene Glycol)",IFERROR(FLOOR((MAX($H8,0)/(D10ActivePct*0.9))/(10*YC_Density*YC_ConcPct),1),""),IF($A8="Alcohol 190 proof SDA 40B",IFERROR(FLOOR(MAX($H8,0)/(10*YC_Density*(1-YC_ConcPct)),1),""),IFERROR(FLOOR((MAX($H8,0)/(INDEX(FM_Active,MATCH($A8,FM_Mat,0))*IF(INDEX(FM_D10,MATCH($A8,FM_Mat,0))="D10",0.1,1)))/(10*YC_Density*YC_ConcPct),1),"")))) -> 3781 | R8: =IF($A8="","",IF($A8="DPG (Dipropylene Glycol)",IFERROR(FLOOR((MAX($H8,0)/(D10ActivePct*0.9))/(20*YC_Density*YC_ConcPct),1),""),IF($A8="Alcohol 190 proof SDA 40B",IFERROR(FLOOR(MAX($H8,0)/(20*YC_Density*(1-YC_ConcPct)),1),""),IFERROR(FLOOR((MAX($H8,0)/(INDEX(FM_Active,MATCH($A8,FM_Mat,0))*IF(INDEX(FM_D10,MATCH($A8,FM_Mat,0))="D10",0.1,1)))/(20*YC_Density*YC_ConcPct),1),"")))) -> 1890 | S8: =IF($A8="","",IF($A8="DPG (Dipropylene Glycol)",IFERROR(FLOOR((MAX($H8,0)/(D10ActivePct*0.9))/(30*YC_Density*YC_ConcPct),1),""),IF($A8="Alcohol 190 proof SDA 40B",IFERROR(FLOOR(MAX($H8,0)/(30*YC_Density*(1-YC_ConcPct)),1),""),IFERROR(FLOOR((MAX($H8,0)/(INDEX(FM_Active,MATCH($A8,FM_Mat,0))*IF(INDEX(FM_D10,MATCH($A8,FM_Mat,0))="D10",0.1,1)))/(30*YC_Density*YC_ConcPct),1),"")))) -> 1260 | T8: =IF($A8="","",IF($A8="DPG (Dipropylene Glycol)",IFERROR(FLOOR((MAX($H8,0)/(D10ActivePct*0.9))/(50*YC_Density*YC_ConcPct),1),""),IF($A8="Alcohol 190 proof SDA 40B",IFERROR(FLOOR(MAX($H8,0)/(50*YC_Density*(1-YC_ConcPct)),1),""),IFERROR(FLOOR((MAX($H8,0)/(INDEX(FM_Active,MATCH($A8,FM_Mat,0))*IF(INDEX(FM_D10,MATCH($A8,FM_Mat,0))="D10",0.1,1)))/(50*YC_Density*YC_ConcPct),1),"")))) -> 756 | U8: =IF($A8="","",IF($A8="DPG (Dipropylene Glycol)",IFERROR(FLOOR((MAX($H8,0)/(D10ActivePct*0.9))/(70*YC_Density*YC_ConcPct),1),""),IF($A8="Alcohol 190 proof SDA 40B",IFERROR(FLOOR(MAX($H8,0)/(70*YC_Density*(1-YC_ConcPct)),1),""),IFERROR(FLOOR((MAX($H8,0)/(INDEX(FM_Active,MATCH($A8,FM_Mat,0))*IF(INDEX(FM_D10,MATCH($A8,FM_Mat,0))="D10",0.1,1)))/(70*YC_Density*YC_ConcPct),1),"")))) -> 540 | V8: =IF($A8="","",IF($A8="DPG (Dipropylene Glycol)",IFERROR(FLOOR((MAX($H8,0)/(D10ActivePct*0.9))/(100*YC_Density*YC_ConcPct),1),""),IF($A8="Alcohol 190 proof SDA 40B",IFERROR(FLOOR(MAX($H8,0)/(100*YC_Density*(1-YC_ConcPct)),1),""),IFERROR(FLOOR((MAX($H8,0)/(INDEX(FM_Active,MATCH($A8,FM_Mat,0))*IF(INDEX(FM_D10,MATCH($A8,FM_Mat,0))="D10",0.1,1)))/(100*YC_Density*YC_ConcPct),1),"")))) -> 378 | W8: =IF($N8="","",MAX(0,MIN(IF($A8="","",IF($A8="DPG (Dipropylene Glycol)",IFERROR(FLOOR((MAX(($G8+IF($C8="ml",$B8*$F8,$B8)),0)/(D10ActivePct*0.9))/(50*YC_Density*YC_ConcPct),1),""),IF($A8="Alcohol 190 proof SDA 40B",IFERROR(FLOOR(MAX(($G8+IF($C8="ml",$B8*$F8,$B8)),0)/(50*YC_Density*(1-YC_ConcPct)),1),""),IFERROR(FLOOR((MAX(($G8+IF($C8="ml",$B8*$F8,$B8)),0)/(INDEX(FM_Active,MATCH($A8,FM_Mat,0))*IF(INDEX(FM_D10,MATCH($A8,FM_Mat,0))="D10",0.1,1)))/(50*YC_Density*YC_ConcPct),1),"")))),MIN($N$7:$N$7),MIN($N$9:$N$33))-$E$4)) -> 0 | X8: =IF(AND(ISNUMBER(W8),W8>0),"BUY MORE - raises output",IF(AND(ISNUMBER(N8),N8=$E$4),"CURRENT BOTTLENECK",IF(AND(ISNUMBER(N8),N8<=$E$4+2),"NEXT LIMIT",""))) | Y8: open
