Workbook
Name AlcCostPerG: 'Cost Analysis'!$C$16
Name AlcoholG: 'Batch Calculator'!$D$58
Name AlcoholUsedG: 'Production Log'!$I$3
Name AuxCostPerG: 'Cost Analysis'!$C$16:$C$26
Name AuxGrams: 'Batch Calculator'!$D$58:$D$68
Name BatchCostSAR: 'Batch Calculator'!$C$24
Name BatchFormat: 'Batch Calculator'!$C$4
Name BatchSize: 'Batch Calculator'!$C$5
Name BatchUnit: 'Batch Calculator'!$C$6
Name BatchVolMl: 'Batch Calculator'!$C$22
Name ConcCostPerG: 'Cost Analysis'!$C$11
Name ConcCostPerGLoaded: 'Cost Analysis'!$C$12
Name ConcG: 'Batch Calculator'!$C$23
Name ConcPct: 'Batch Calculator'!$C$7
Name CostPerMl: 'Batch Calculator'!$C$25
Name CR2ButterPct: 'Batch Calculator'!$G$17
Name CR2CetPct: 'Batch Calculator'!$G$15
Name CR2EwaxPct: 'Batch Calculator'!$G$14
Name CR2GlyPct: 'Batch Calculator'!$G$13
Name CR2OilPct: 'Batch Calculator'!$G$16
Name CR2PresPct: 'Batch Calculator'!$G$18
Name CreamBaseG: 'Batch Calculator'!$D$63
Name D10ActivePct: 'Formula Master'!$I$4
Name DefaultBatchAlcG: Inventory!$K$2
Name DefaultBatchConcG: Inventory!$H$2
Name DPGPricePerG: 'Cost Analysis'!$C$10
Name FinishedDensity: 'Batch Calculator'!$C$8
Name FM_Active: 'Formula Master'!$F$7:$F$31
Name FM_CostG: 'Formula Master'!$H$7:$H$31
Name FM_D10: 'Formula Master'!$D$7:$D$31
Name FM_InputPct: 'Formula Master'!$C$7:$C$31
Name FM_Mat: 'Formula Master'!$B$7:$B$31
Name FormatDefaults: Lists!$A$2:$E$7
Name FormatList: Lists!$A$2:$A$7
Name GlycerinG: 'Batch Calculator'!$D$60
Name IncludeOptionals: 'Formula Master'!$C$4
Name Inv_GramsBought: Inventory!$F$4:$F$30
Name Inv_LowJoined: Inventory!$Q$30
Name Inv_LowNames: Inventory!$P$4:$P$30
Name Inv_Mat: Inventory!$A$4:$A$30
Name Inv_OnHand: Inventory!$K$4:$K$30
Name Inv_PricePerG: Inventory!$I$4:$I$30
Name Inv_Threshold: Inventory!$L$4:$L$30
Name Inv_TotalPaid: Inventory!$H$4:$H$30
Name LogAlcG: 'Production Log'!$H$5:$H$44
Name LogConcG: 'Production Log'!$G$5:$G$44
Name LogEnd: 'Production Log'!$J$5:$J$44
Name LogID: 'Production Log'!$B$5:$B$44
Name LogMacStart: 'Production Log'!$M$5:$M$44
Name LogStart: 'Production Log'!$I$5:$I$44
Name LogStatus: 'Production Log'!$K$5:$K$44
Name MacDays: 'Production Log'!$C$3
Name MaterialsTotalSAR: 'Cost Analysis'!$C$4
Name MistGlyPct: 'Batch Calculator'!$C$13
Name MistWaterPct: 'Batch Calculator'!$C$14
Name OptPctSum: 'Formula Master'!$I$3
Name PolysorbateG: 'Batch Calculator'!$D$61
Name PR_ConcPct: 'Pricing & Sales'!$C$4
Name PR_Density: 'Pricing & Sales'!$C$5
Name PR_Labour: 'Pricing & Sales'!$C$6

Sheet Dashboard
B2: S A M R
B3: سَمَر · evening warmth, vanilla, white flowers, warm musk · made for her skin
B6: INVESTED (SAR) | C6: STOCK VALUE (SAR) | D6: CONCENTRATE (SAR/g) | E6: BATCHES LOGGED | F6: MACERATING NOW | G6: LOW-STOCK ITEMS
B7: =TotalCapital -> 2043.83 | C7: =StockValueSAR -> 1692.83 | D7: =ConcCostPerGLoaded -> 3.0355201 | E7: =SUMPRODUCT((LogID<>"")*1) -> 0 | F7: =COUNTIF(LogStatus,"Macerating") -> 0 | G7: =SUMPRODUCT((Inv_OnHand<Inv_Threshold)*1) -> 0
B9: CURRENT BATCH — quick launch | E9: MACERATION MILESTONES
B10: Format | C10: =BatchFormat -> Eau de Parfum | E10: Next ready window opens | G10: =IF(COUNTIFS(LogStatus,"Macerating",LogStart,"<>")=0,"—",TEXT(MIN(LogMacStart)+28,"yyyy-mm-dd")) -> —
B11: Batch | C11: =BatchSize&" "&BatchUnit -> 50 ml | E11: Next maceration complete | G11: =IF(COUNTIFS(LogStatus,"Macerating",LogStart,"<>")=0,"—",TEXT(MIN(LogMacStart)+MacDays,"yyyy-mm-dd")) -> —
B12: Concentrate to weigh (g) | C12: =ConcG -> 8.5 | E12: Batches in ready window | G12: =SUMPRODUCT((LogStatus="Macerating")*(LogStart<>"")*((TODAY()-LogStart)>=28)) -> 0
B13: Alcohol (g) | C13: =AlcoholG -> 34 | E13: Concentrate used to date (g) | G13: =TotalConcUsedG -> 0
B14: Estimated cost (SAR) | C14: =BatchCostSAR -> 27.322281 | E14: Alcohol used to date (g) | G14: =AlcoholUsedG -> 0
B15: Cost per ml (SAR) | C15: =CostPerMl -> 0.54644562 | E15: Maceration target (days) | G15: =MacDays -> 42
B17: INVENTORY ALERTS
B18: =IF($G$7=0,"✓ All materials stocked for at least two default batches.","⚠ Low stock — reorder: "&Inv_LowJoined) -> ✓ All materials stocked for at least two default batches.
B20: WORKFLOW
B21: 1 · Set format, size and concentration in the Batch Calculator — print it and take it to the bench.
B22: 2 · Weigh BASE → HEART → TOP, marry the concentrate 24–48 h, then dilute and start maceration.
B23: 3 · Log the batch in the Production Log — Inventory and the Maceration Tracker update themselves.
B25: SAMR personal production suite · verify against current IFRA standards before any commercial use

Sheet The Scent
B2: S A M R
B3: Eau de Parfum 20% · Gourmand Amber Floral · a warm-skin scent
B6: THE NAME
B7: SAMR — سَمَر — comes from Samrae and from the Arabic idea of late-night conversation: warmth after sunset, closeness, and the voice you want to keep hearing. The brand mark keeps the name short, intimate, and easy to put on a bottle while still carrying her name inside it.
B9: THE IDEA
B10: SAMR is a private EDP built around warmth on skin: soft fruit at the opening, white flowers at body temperature, vanilla, tonka, ambergris radiance, velvet woods, and a five-layer musk trail. The goal is not room-filling noise; it is a close, memorable signature that feels personal when someone is allowed near.
B12: THE OPENING — the first glance
B13: Sun-warmed bergamot and a spark of pink pepper sit over ripe peach skin and raspberry gloss. Bright, juicy, and playful, the opening lasts long enough to catch attention, then melts into the warmer heart.
B15: THE HEART — the embrace
B16: A cloud of Hedione makes the heart luminous while jasmine and tuberose bring creamy white flower warmth. Violet-iris powder softens the edges, and benzyl salicylate gives a solar, skin-in-the-sun glow. This is the center of SAMR: radiant, feminine, and close.
B18: THE DRYDOWN — the addiction
B19: The base is where SAMR becomes memorable. A double vanilla — vanillin anchored by its creamier ethyl echo — melts into tonka and a caramelised-sugar halo, warmed by almond heliotrope and a single breath of coconut cream. Ambroxan throws its radiant, mineral ambergris aura for hours; Iso E Super and cashmeran wrap it in velvet wood, sandalwood glows underneath, and three musks — clean, powdery, intimate — fuse it all to her skin. The optional glints are plum-rose damascone and a saffron-suede whisper.
... B29: Concentrate = 100% on the Formula Master tab. Weighing, dilutions, maceration and bottling: Batch Calculator + Process Reference.

Sheet Formula Master
A1: SAMR — MASTER FORMULA
A2: Concentrate = 100% by weight. D10 = weighed as a 10% dilution in DPG — the % shown is the weight of the dilution.
H3: Optionals Σ | I3: =SUMIF($E$7:$E$31,"OPT",$C$7:$C$31) -> 0.008
A4: Include optional materials (Damascone Beta, Saffron Accord): | C4: YES | H4: D10 Σ (active) | I4: =SUMIF($D$7:$D$31,"D10",$F$7:$F$31) -> 0.048
A6: Phase | B6: Material | C6: Input % | D6: D10 | E6: Optional | F6: Active % | G6: Role in the accord | H6: SAR/g (as weighed)
A7: TOP | B7: Bergamot Accord | C7: 0.045 | F7: =IF(IncludeOptionals="YES",C7,IF($E7="OPT",0,C7/(1-OptPctSum))) -> 0.045 | G7: sun-warmed citrus — the first glance across the room | H7: =IF($D7="D10",0.1*INDEX(Inv_PricePerG,MATCH($B7,Inv_Mat,0))+0.9*DPGPricePerG,INDEX(Inv_PricePerG,MATCH($B7,Inv_Mat,0))) -> 2
A8: TOP | B8: Pink Peppercorn | C8: 0.01 | D8: D10 | F8: =IF(IncludeOptionals="YES",C8,IF($E8="OPT",0,C8/(1-OptPctSum))) -> 0.01 | G8: rosy-spicy spark over the opening | H8: =IF($D8="D10",0.1*INDEX(Inv_PricePerG,MATCH($B8,Inv_Mat,0))+0.9*DPGPricePerG,INDEX(Inv_PricePerG,MATCH($B8,Inv_Mat,0))) -> 1.6576797
A9: TOP | B9: Aldehyde C-14 Peach | C9: 0.02 | F9: =IF(IncludeOptionals="YES",C9,IF($E9="OPT",0,C9/(1-OptPctSum))) -> 0.02 | G9: ripe peach skin — velvet, juicy, warm | H9: =IF($D9="D10",0.1*INDEX(Inv_PricePerG,MATCH($B9,Inv_Mat,0))+0.9*DPGPricePerG,INDEX(Inv_PricePerG,MATCH($B9,Inv_Mat,0))) -> 1.86
A10: TOP | B10: Raspberry Accord | C10: 0.01 | F10: =IF(IncludeOptionals="YES",C10,IF($E10="OPT",0,C10/(1-OptPctSum))) -> 0.01 | G10: lip-gloss fruit — playful, kissable | H10: =IF($D10="D10",0.1*INDEX(Inv_PricePerG,MATCH($B10,Inv_Mat,0))+0.9*DPGPricePerG,INDEX(Inv_PricePerG,MATCH($B10,Inv_Mat,0))) -> 2.5
A11: HEART | B11: Hedione (Firmenich) | C11: 0.147 | F11: =IF(IncludeOptionals="YES",C11,IF($E11="OPT",0,C11/(1-OptPctSum))) -> 0.147 | G11: radiant jasmine air — she fills the room | H11: =IF($D11="D10",0.1*INDEX(Inv_PricePerG,MATCH($B11,Inv_Mat,0))+0.9*DPGPricePerG,INDEX(Inv_PricePerG,MATCH($B11,Inv_Mat,0))) -> 0.44266667
A12: HEART | B12: Jasmin Absolute Accord | C12: 0.03 | F12: =IF(IncludeOptionals="YES",C12,IF($E12="OPT",0,C12/(1-OptPctSum))) -> 0.03 | G12: the carnal white flower at body heat | H12: =IF($D12="D10",0.1*INDEX(Inv_PricePerG,MATCH($B12,Inv_Mat,0))+0.9*DPGPricePerG,INDEX(Inv_PricePerG,MATCH($B12,Inv_Mat,0))) -> 5
A13: HEART | B13: Tuberose Accord | C13: 0.015 | F13: =IF(IncludeOptionals="YES",C13,IF($E13="OPT",0,C13/(1-OptPctSum))) -> 0.015 | G13: creamy narcotic petals | H13: =IF($D13="D10",0.1*INDEX(Inv_PricePerG,MATCH($B13,Inv_Mat,0))+0.9*DPGPricePerG,INDEX(Inv_PricePerG,MATCH($B13,Inv_Mat,0))) -> 3.9588889
A14: HEART | B14: Methyl Alpha Ionone Iso | C14: 0.04 | F14: =IF(IncludeOptionals="YES",C14,IF($E14="OPT",0,C14/(1-OptPctSum))) -> 0.04 | G14: violet-iris powder — bare shoulders under silk | H14: =IF($D14="D10",0.1*INDEX(Inv_PricePerG,MATCH($B14,Inv_Mat,0))+0.9*DPGPricePerG,INDEX(Inv_PricePerG,MATCH($B14,Inv_Mat,0))) -> 1.8618519
A15: HEART | B15: Benzyl Salicylate | C15: 0.07 | F15: =IF(IncludeOptionals="YES",C15,IF($E15="OPT",0,C15/(1-OptPctSum))) -> 0.07 | G15: solar balsamic glow — skin in the sun | H15: =IF($D15="D10",0.1*INDEX(Inv_PricePerG,MATCH($B15,Inv_Mat,0))+0.9*DPGPricePerG,INDEX(Inv_PricePerG,MATCH($B15,Inv_Mat,0))) -> 1.1903704
A16: HEART | B16: Linalool | C16: 0.015 | F16: =IF(IncludeOptionals="YES",C16,IF($E16="OPT",0,C16/(1-OptPctSum))) -> 0.015 | G16: soft floral smoothing | H16: =IF($D16="D10",0.1*INDEX(Inv_PricePerG,MATCH($B16,Inv_Mat,0))+0.9*DPGPricePerG,INDEX(Inv_PricePerG,MATCH($B16,Inv_Mat,0))) -> 1.86
A17: HEART | B17: Damascone Beta | C17: 0.003 | D17: D10 | E17: OPT | F17: =IF(IncludeOptionals="YES",C17,IF($E17="OPT",0,C17/(1-OptPctSum))) -> 0.003 | G17: velvet plum-rose glint — optional luxury | H17: =IF($D17="D10",0.1*INDEX(Inv_PricePerG,MATCH($B17,Inv_Mat,0))+0.9*DPGPricePerG,INDEX(Inv_PricePerG,MATCH($B17,Inv_Mat,0))) -> 1.1854575
A18: BASE | B18: Vanillin Crystals | C18: 0.07 | F18: =IF(IncludeOptionals="YES",C18,IF($E18="OPT",0,C18/(1-OptPctSum))) -> 0.07 | G18: warm vanilla — the addiction itself | H18: =IF($D18="D10",0.1*INDEX(Inv_PricePerG,MATCH($B18,Inv_Mat,0))+0.9*DPGPricePerG,INDEX(Inv_PricePerG,MATCH($B18,Inv_Mat,0))) -> 1.406
A19: BASE | B19: Ethyl Vanillin | C19: 0.025 | F19: =IF(IncludeOptionals="YES",C19,IF($E19="OPT",0,C19/(1-OptPctSum))) -> 0.025 | G19: deeper, creamier vanilla echo | H19: =IF($D19="D10",0.1*INDEX(Inv_PricePerG,MATCH($B19,Inv_Mat,0))+0.9*DPGPricePerG,INDEX(Inv_PricePerG,MATCH($B19,Inv_Mat,0))) -> 1.569
A20: BASE | B20: Maltol (Crystals) | C20: 0.02 | D20: D10 | F20: =IF(IncludeOptionals="YES",C20,IF($E20="OPT",0,C20/(1-OptPctSum))) -> 0.02 | G20: caramelised-sugar halo | H20: =IF($D20="D10",0.1*INDEX(Inv_PricePerG,MATCH($B20,Inv_Mat,0))+0.9*DPGPricePerG,INDEX(Inv_PricePerG,MATCH($B20,Inv_Mat,0))) -> 0.35333529
A21: BASE | B21: Coumarin | C21: 0.045 | F21: =IF(IncludeOptionals="YES",C21,IF($E21="OPT",0,C21/(1-OptPctSum))) -> 0.045 | G21: tonka warmth — almond-hay softness | H21: =IF($D21="D10",0.1*INDEX(Inv_PricePerG,MATCH($B21,Inv_Mat,0))+0.9*DPGPricePerG,INDEX(Inv_PricePerG,MATCH($B21,Inv_Mat,0))) -> 0.3
A22: BASE | B22: Heliotrope Accord | C22: 0.025 | F22: =IF(IncludeOptionals="YES",C22,IF($E22="OPT",0,C22/(1-OptPctSum))) -> 0.025 | G22: almond-powder tenderness | H22: =IF($D22="D10",0.1*INDEX(Inv_PricePerG,MATCH($B22,Inv_Mat,0))+0.9*DPGPricePerG,INDEX(Inv_PricePerG,MATCH($B22,Inv_Mat,0))) -> 3.75
A23: BASE | B23: Aldehyde C-18 Coconut | C23: 0.015 | D23: D10 | F23: =IF(IncludeOptionals="YES",C23,IF($E23="OPT",0,C23/(1-OptPctSum))) -> 0.015 | G23: a breath of coconut cream on skin | H23: =IF($D23="D10",0.1*INDEX(Inv_PricePerG,MATCH($B23,Inv_Mat,0))+0.9*DPGPricePerG,INDEX(Inv_PricePerG,MATCH($B23,Inv_Mat,0))) -> 0.23545752
A24: BASE | B24: Ambroxan | C24: 0.075 | F24: =IF(IncludeOptionals="YES",C24,IF($E24="OPT",0,C24/(1-OptPctSum))) -> 0.075 | G24: ambergris radiance — the 'come closer' trail | H24: =IF($D24="D10",0.1*INDEX(Inv_PricePerG,MATCH($B24,Inv_Mat,0))+0.9*DPGPricePerG,INDEX(Inv_PricePerG,MATCH($B24,Inv_Mat,0))) -> 13.375
A25: BASE | B25: Iso E Super | C25: 0.095 | F25: =IF(IncludeOptionals="YES",C25,IF($E25="OPT",0,C25/(1-OptPctSum))) -> 0.095 | G25: velvet-wood aura, second-skin halo | H25: =IF($D25="D10",0.1*INDEX(Inv_PricePerG,MATCH($B25,Inv_Mat,0))+0.9*DPGPricePerG,INDEX(Inv_PricePerG,MATCH($B25,Inv_Mat,0))) -> 1.4507407
A26: BASE | B26: Cashmeran IFF | C26: 0.03 | F26: =IF(IncludeOptionals="YES",C26,IF($E26="OPT",0,C26/(1-OptPctSum))) -> 0.03 | G26: cashmere warmth — bedsheets and skin | H26: =IF($D26="D10",0.1*INDEX(Inv_PricePerG,MATCH($B26,Inv_Mat,0))+0.9*DPGPricePerG,INDEX(Inv_PricePerG,MATCH($B26,Inv_Mat,0))) -> 6.2066667
A27: BASE | B27: Sandalore (Givaudan) | C27: 0.035 | F27: =IF(IncludeOptionals="YES",C27,IF($E27="OPT",0,C27/(1-OptPctSum))) -> 0.035 | G27: creamy sandalwood glow | H27: =IF($D27="D10",0.1*INDEX(Inv_PricePerG,MATCH($B27,Inv_Mat,0))+0.9*DPGPricePerG,INDEX(Inv_PricePerG,MATCH($B27,Inv_Mat,0))) -> 2.6155556
A28: BASE | B28: Ethylene Brassylate | C28: 0.075 | F28: =IF(IncludeOptionals="YES",C28,IF($E28="OPT",0,C28/(1-OptPctSum))) -> 0.075 | G28: powdery intimate musk | H28: =IF($D28="D10",0.1*INDEX(Inv_PricePerG,MATCH($B28,Inv_Mat,0))+0.9*DPGPricePerG,INDEX(Inv_PricePerG,MATCH($B28,Inv_Mat,0))) -> 0.76422222
A29: BASE | B29: Galaxolide | C29: 0.055 | F29: =IF(IncludeOptionals="YES",C29,IF($E29="OPT",0,C29/(1-OptPctSum))) -> 0.055 | G29: clean 'her skin' musk — freshly showered | H29: =IF($D29="D10",0.1*INDEX(Inv_PricePerG,MATCH($B29,Inv_Mat,0))+0.9*DPGPricePerG,INDEX(Inv_PricePerG,MATCH($B29,Inv_Mat,0))) -> 1
A30: BASE | B30: Exaltolide Total (Firmenich) | C30: 0.025 | F30: =IF(IncludeOptionals="YES",C30,IF($E30="OPT",0,C30/(1-OptPctSum))) -> 0.025 | G30: warm skin-musk — the lingering embrace | H30: =IF($D30="D10",0.1*INDEX(Inv_PricePerG,MATCH($B30,Inv_Mat,0))+0.9*DPGPricePerG,INDEX(Inv_PricePerG,MATCH($B30,Inv_Mat,0))) -> 3.0588889
A31: BASE | B31: Saffron Accord | C31: 0.005 | E31: OPT | F31: =IF(IncludeOptionals="YES",C31,IF($E31="OPT",0,C31/(1-OptPctSum))) -> 0.005 | G31: saffron-suede whisper — optional luxury | H31: =IF($D31="D10",0.1*INDEX(Inv_PricePerG,MATCH($B31,Inv_Mat,0))+0.9*DPGPricePerG,INDEX(Inv_PricePerG,MATCH($B31,Inv_Mat,0))) -> 3.75
B33: TOTALS | C33: =SUM(C7:C31) -> 1 | F33: =SUM(F7:F31) -> 1
A34: =IF(AND(ROUND(C33,6)=1,ROUND(F33,6)=1),"✓ BALANCED — input Σ = "&TEXT(C33,"0.00%")&" · active Σ = "&TEXT(F33,"0.00%"),"⚠ FORMULA DOES NOT SUM TO 100% — check the Input % column") -> ✓ BALANCED — input Σ = 100.00% · active Σ = 100.00%
A36: Legend: | B36: OPTIONAL / extra | C36: optional materials are controlled only by the C4 toggle
B37: OVERLAPS another | C37: intentional accord layering — do not remove unless you choose a simpler formula
A38: Every other ingredient is essential to the accord. There are NO wasted materials here — each phase (top / heart / base) needs its members to smell complete.

Sheet SAHAR 28% Formula
A1: SAHAR سَهَر - 28% Concentration Formula
A3: Formula name | B3: SAHAR سَهَر
A4: Style | B4: night-spice peach rose, creamy white flowers, vanilla amber skin musk
A5: Concentration | B5: 0.28
A6: Bottle size ml | B6: 50
A7: Fill density g/ml | B7: 0.85
A8: Finished bottle mass g | B8: =B6*B7 -> 42.5
A9: Concentrate per bottle g | B9: =B8*B5 -> 11.9
A10: Alcohol per bottle g | B10: =B8-B9 -> 30.6
A11: DPG carrier for D10 g | B11: =SUM(J22:J46) -> 0.48195
A12: Est. material cost SAR | B12: =SUM(N22:N46)+B11*B14+B10*B15 -> 36.688121
A13: Est. cost per ml SAR | B13: =B12/B6 -> 0.73376241
A14: DPG SAR/g | B14: =IFERROR(INDEX(Inventory!$I$4:$I$30,MATCH("DPG (Dipropylene Glycol)",Inventory!$A$4:$A$30,0)),0) -> 0.098039216
A15: Alcohol SAR/g | B15: =IFERROR(INDEX(Inventory!$I$4:$I$30,MATCH("Alcohol 190 proof SDA 40B",Inventory!$A$4:$A$30,0)),0) -> 0.037037037
A16: Inventory-limited bottles | B16: =MIN(P22:P46,IF(B11>0,IFERROR(INDEX(Inventory!$K$4:$K$30,MATCH("DPG (Dipropylene Glycol)",Inventory!$A$4:$A$30,0))/B11,1E+99),1E+99),IFERROR(INDEX(Inventory!$K$4:$K$30,MATCH("Alcohol 190 proof SDA 40B",Inventory!$A$4:$A$30,0))/B10,1E+99)) -> 12.605042
A17: Main fragrance bottleneck | B17: =INDEX(B22:B46,MATCH(MIN(P22:P46),P22:P46,0)) -> Heliotrope Accord
A21: Phase | B21: Material | C21: Input % | D21: Prep | E21: Optional | F21: Role in the accord | G21: Concentrate g | H21: Weighed g | I21: Active raw g | J21: DPG carrier g | K21: Inventory on hand | L21: Raw SAR/g | M21: Weighed SAR/g | N21: Cost SAR | O21: Finished % | P21: Bottle limit @ size
A22: TOP | B22: Bergamot Accord | C22: 0.032 | F22: bright citrus lift, cleaner and sharper than SAMR | G22: =$B$9*C22 -> 0.3808 | H22: =G22 -> 0.3808 | I22: =IF(D22="D10",H22*0.1,H22) -> 0.3808 | J22: =IF(D22="D10",H22*0.9,0) -> 0 | K22: =IFERROR(INDEX(Inventory!$K$4:$K$30,MATCH(B22,Inventory!$A$4:$A$30,0)),"") -> 27 | L22: =IFERROR(INDEX(Inventory!$I$4:$I$30,MATCH(B22,Inventory!$A$4:$A$30,0)),0) -> 2 | M22: =IF(D22="D10",0.1*L22+0.9*$B$14,L22) -> 2 | N22: =H22*M22 -> 0.7616 | O22: =C22*$B$5 -> 0.00896 | P22: =IFERROR(K22/I22,"") -> 70.903361
A23: TOP | B23: Pink Peppercorn | C23: 0.01 | D23: D10 | F23: rosy spice spark at the opening | G23: =$B$9*C23 -> 0.119 | H23: =G23 -> 0.119 | I23: =IF(D23="D10",H23*0.1,H23) -> 0.0119 | J23: =IF(D23="D10",H23*0.9,0) -> 0.1071 | K23: =IFERROR(INDEX(Inventory!$K$4:$K$30,MATCH(B23,Inventory!$A$4:$A$30,0)),"") -> 9 | L23: =IFERROR(INDEX(Inventory!$I$4:$I$30,MATCH(B23,Inventory!$A$4:$A$30,0)),0) -> 15.694444 | M23: =IF(D23="D10",0.1*L23+0.9*$B$14,L23) -> 1.6576797 | N23: =H23*M23 -> 0.19726389 | O23: =C23*$B$5 -> 0.0028 | P23: =IFERROR(K23/I23,"") -> 756.30252
A24: TOP | B24: Aldehyde C-14 Peach | C24: 0.028 | F24: velvet peach skin, more flirtatious fruit | G24: =$B$9*C24 -> 0.3332 | H24: =G24 -> 0.3332 | I24: =IF(D24="D10",H24*0.1,H24) -> 0.3332 | J24: =IF(D24="D10",H24*0.9,0) -> 0 | K24: =IFERROR(INDEX(Inventory!$K$4:$K$30,MATCH(B24,Inventory!$A$4:$A$30,0)),"") -> 18 | L24: =IFERROR(INDEX(Inventory!$I$4:$I$30,MATCH(B24,Inventory!$A$4:$A$30,0)),0) -> 1.86 | M24: =IF(D24="D10",0.1*L24+0.9*$B$14,L24) -> 1.86 | N24: =H24*M24 -> 0.619752 | O24: =C24*$B$5 -> 0.00784 | P24: =IFERROR(K24/I24,"") -> 54.021609
A25: TOP | B25: Raspberry Accord | C25: 0.02 | F25: red-fruit pulse for desire | G25: =$B$9*C25 -> 0.238 | H25: =G25 -> 0.238 | I25: =IF(D25="D10",H25*0.1,H25) -> 0.238 | J25: =IF(D25="D10",H25*0.9,0) -> 0 | K25: =IFERROR(INDEX(Inventory!$K$4:$K$30,MATCH(B25,Inventory!$A$4:$A$30,0)),"") -> 9 | L25: =IFERROR(INDEX(Inventory!$I$4:$I$30,MATCH(B25,Inventory!$A$4:$A$30,0)),0) -> 2.5 | M25: =IF(D25="D10",0.1*L25+0.9*$B$14,L25) -> 2.5 | N25: =H25*M25 -> 0.595 | O25: =C25*$B$5 -> 0.0056 | P25: =IFERROR(K25/I25,"") -> 37.815126
A26: TOP | B26: Saffron Accord | C26: 0.015 | E26: OPT | F26: suede spice, optional luxury heat | G26: =$B$9*C26 -> 0.1785 | H26: =G26 -> 0.1785 | I26: =IF(D26="D10",H26*0.1,H26) -> 0.1785 | J26: =IF(D26="D10",H26*0.9,0) -> 0 | K26: =IFERROR(INDEX(Inventory!$K$4:$K$30,MATCH(B26,Inventory!$A$4:$A$30,0)),"") -> 9 | L26: =IFERROR(INDEX(Inventory!$I$4:$I$30,MATCH(B26,Inventory!$A$4:$A$30,0)),0) -> 3.75 | M26: =IF(D26="D10",0.1*L26+0.9*$B$14,L26) -> 3.75 | N26: =H26*M26 -> 0.669375 | O26: =C26*$B$5 -> 0.0042 | P26: =IFERROR(K26/I26,"") -> 50.420168
A27: TOP | B27: Aldehyde C-18 Coconut | C27: 0.013 | D27: D10 | F27: soft coconut cream around the fruit | G27: =$B$9*C27 -> 0.1547 | H27: =G27 -> 0.1547 | I27: =IF(D27="D10",H27*0.1,H27) -> 0.01547 | J27: =IF(D27="D10",H27*0.9,0) -> 0.13923 | K27: =IFERROR(INDEX(Inventory!$K$4:$K$30,MATCH(B27,Inventory!$A$4:$A$30,0)),"") -> 9 | L27: =IFERROR(INDEX(Inventory!$I$4:$I$30,MATCH(B27,Inventory!$A$4:$A$30,0)),0) -> 1.4722222 | M27: =IF(D27="D10",0.1*L27+0.9*$B$14,L27) -> 0.23545752 | N27: =H27*M27 -> 0.036425278 | O27: =C27*$B$5 -> 0.00364 | P27: =IFERROR(K27/I27,"") -> 581.77117
A28: HEART | B28: Damascone Beta | C28: 0.002 | D28: D10 | E28: OPT | F28: plum-rose shadow, kept very low for control | G28: =$B$9*C28 -> 0.0238 | H28: =G28 -> 0.0238 | I28: =IF(D28="D10",H28*0.1,H28) -> 0.00238 | J28: =IF(D28="D10",H28*0.9,0) -> 0.02142 | K28: =IFERROR(INDEX(Inventory!$K$4:$K$30,MATCH(B28,Inventory!$A$4:$A$30,0)),"") -> 9 | L28: =IFERROR(INDEX(Inventory!$I$4:$I$30,MATCH(B28,Inventory!$A$4:$A$30,0)),0) -> 10.972222 | M28: =IF(D28="D10",0.1*L28+0.9*$B$14,L28) -> 1.1854575 | N28: =H28*M28 -> 0.028213889 | O28: =C28*$B$5 -> 0.00056 | P28: =IFERROR(K28/I28,"") -> 3781.5126
A29: HEART | B29: Hedione (Firmenich) | C29: 0.09 | F29: open jasmine air and diffusion | G29: =$B$9*C29 -> 1.071 | H29: =G29 -> 1.071 | I29: =IF(D29="D10",H29*0.1,H29) -> 1.071 | J29: =IF(D29="D10",H29*0.9,0) -> 0 | K29: =IFERROR(INDEX(Inventory!$K$4:$K$30,MATCH(B29,Inventory!$A$4:$A$30,0)),"") -> 90 | L29: =IFERROR(INDEX(Inventory!$I$4:$I$30,MATCH(B29,Inventory!$A$4:$A$30,0)),0) -> 0.44266667 | M29: =IF(D29="D10",0.1*L29+0.9*$B$14,L29) -> 0.44266667 | N29: =H29*M29 -> 0.474096 | O29: =C29*$B$5 -> 0.0252 | P29: =IFERROR(K29/I29,"") -> 84.033613
A30: HEART | B30: Jasmin Absolute Accord | C30: 0.055 | F30: sensual white floral body | G30: =$B$9*C30 -> 0.6545 | H30: =G30 -> 0.6545 | I30: =IF(D30="D10",H30*0.1,H30) -> 0.6545 | J30: =IF(D30="D10",H30*0.9,0) -> 0 | K30: =IFERROR(INDEX(Inventory!$K$4:$K$30,MATCH(B30,Inventory!$A$4:$A$30,0)),"") -> 18 | L30: =IFERROR(INDEX(Inventory!$I$4:$I$30,MATCH(B30,Inventory!$A$4:$A$30,0)),0) -> 5 | M30: =IF(D30="D10",0.1*L30+0.9*$B$14,L30) -> 5 | N30: =H30*M30 -> 3.2725 | O30: =C30*$B$5 -> 0.0154 | P30: =IFERROR(K30/I30,"") -> 27.50191
A31: HEART | B31: Tuberose Accord | C31: 0.04 | F31: creamy narcotic flower | G31: =$B$9*C31 -> 0.476 | H31: =G31 -> 0.476 | I31: =IF(D31="D10",H31*0.1,H31) -> 0.476 | J31: =IF(D31="D10",H31*0.9,0) -> 0 | K31: =IFERROR(INDEX(Inventory!$K$4:$K$30,MATCH(B31,Inventory!$A$4:$A$30,0)),"") -> 9 | L31: =IFERROR(INDEX(Inventory!$I$4:$I$30,MATCH(B31,Inventory!$A$4:$A$30,0)),0) -> 3.9588889 | M31: =IF(D31="D10",0.1*L31+0.9*$B$14,L31) -> 3.9588889 | N31: =H31*M31 -> 1.8844311 | O31: =C31*$B$5 -> 0.0112 | P31: =IFERROR(K31/I31,"") -> 18.907563
A32: HEART | B32: Methyl Alpha Ionone Iso | C32: 0.045 | F32: violet-iris powder and elegance | G32: =$B$9*C32 -> 0.5355 | H32: =G32 -> 0.5355 | I32: =IF(D32="D10",H32*0.1,H32) -> 0.5355 | J32: =IF(D32="D10",H32*0.9,0) -> 0 | K32: =IFERROR(INDEX(Inventory!$K$4:$K$30,MATCH(B32,Inventory!$A$4:$A$30,0)),"") -> 27 | L32: =IFERROR(INDEX(Inventory!$I$4:$I$30,MATCH(B32,Inventory!$A$4:$A$30,0)),0) -> 1.8618519 | M32: =IF(D32="D10",0.1*L32+0.9*$B$14,L32) -> 1.8618519 | N32: =H32*M32 -> 0.99702167 | O32: =C32*$B$5 -> 0.0126 | P32: =IFERROR(K32/I32,"") -> 50.420168
A33: HEART | B33: Benzyl Salicylate | C33: 0.05 | F33: solar floral warmth and lasting body | G33: =$B$9*C33 -> 0.595 | H33: =G33 -> 0.595 | I33: =IF(D33="D10",H33*0.1,H33) -> 0.595 | J33: =IF(D33="D10",H33*0.9,0) -> 0 | K33: =IFERROR(INDEX(Inventory!$K$4:$K$30,MATCH(B33,Inventory!$A$4:$A$30,0)),"") -> 54 | L33: =IFERROR(INDEX(Inventory!$I$4:$I$30,MATCH(B33,Inventory!$A$4:$A$30,0)),0) -> 1.1903704 | M33: =IF(D33="D10",0.1*L33+0.9*$B$14,L33) -> 1.1903704 | N33: =H33*M33 -> 0.70827037 | O33: =C33*$B$5 -> 0.014 | P33: =IFERROR(K33/I33,"") -> 90.756303
A34: HEART | B34: Linalool | C34: 0.02 | F34: smooth floral freshness | G34: =$B$9*C34 -> 0.238 | H34: =G34 -> 0.238 | I34: =IF(D34="D10",H34*0.1,H34) -> 0.238 | J34: =IF(D34="D10",H34*0.9,0) -> 0 | K34: =IFERROR(INDEX(Inventory!$K$4:$K$30,MATCH(B34,Inventory!$A$4:$A$30,0)),"") -> 18 | L34: =IFERROR(INDEX(Inventory!$I$4:$I$30,MATCH(B34,Inventory!$A$4:$A$30,0)),0) -> 1.86 | M34: =IF(D34="D10",0.1*L34+0.9*$B$14,L34) -> 1.86 | N34: =H34*M34 -> 0.44268 | O34: =C34*$B$5 -> 0.0056 | P34: =IFERROR(K34/I34,"") -> 75.630252
A35: BASE | B35: Vanillin Crystals | C35: 0.06 | F35: addictive warm vanilla | G35: =$B$9*C35 -> 0.714 | H35: =G35 -> 0.714 | I35: =IF(D35="D10",H35*0.1,H35) -> 0.714 | J35: =IF(D35="D10",H35*0.9,0) -> 0 | K35: =IFERROR(INDEX(Inventory!$K$4:$K$30,MATCH(B35,Inventory!$A$4:$A$30,0)),"") -> 30 | L35: =IFERROR(INDEX(Inventory!$I$4:$I$30,MATCH(B35,Inventory!$A$4:$A$30,0)),0) -> 1.406 | M35: =IF(D35="D10",0.1*L35+0.9*$B$14,L35) -> 1.406 | N35: =H35*M35 -> 1.003884 | O35: =C35*$B$5 -> 0.0168 | P35: =IFERROR(K35/I35,"") -> 42.016807
A36: BASE | B36: Ethyl Vanillin | C36: 0.025 | F36: deeper vanilla sweetness | G36: =$B$9*C36 -> 0.2975 | H36: =G36 -> 0.2975 | I36: =IF(D36="D10",H36*0.1,H36) -> 0.2975 | J36: =IF(D36="D10",H36*0.9,0) -> 0 | K36: =IFERROR(INDEX(Inventory!$K$4:$K$30,MATCH(B36,Inventory!$A$4:$A$30,0)),"") -> 20 | L36: =IFERROR(INDEX(Inventory!$I$4:$I$30,MATCH(B36,Inventory!$A$4:$A$30,0)),0) -> 1.569 | M36: =IF(D36="D10",0.1*L36+0.9*$B$14,L36) -> 1.569 | N36: =H36*M36 -> 0.4667775 | O36: =C36*$B$5 -> 0.007 | P36: =IFERROR(K36/I36,"") -> 67.226891
A37: BASE | B37: Maltol (Crystals) | C37: 0.02 | D37: D10 | F37: caramel sugar glow | G37: =$B$9*C37 -> 0.238 | H37: =G37 -> 0.238 | I37: =IF(D37="D10",H37*0.1,H37) -> 0.0238 | J37: =IF(D37="D10",H37*0.9,0) -> 0.2142 | K37: =IFERROR(INDEX(Inventory!$K$4:$K$30,MATCH(B37,Inventory!$A$4:$A$30,0)),"") -> 10 | L37: =IFERROR(INDEX(Inventory!$I$4:$I$30,MATCH(B37,Inventory!$A$4:$A$30,0)),0) -> 2.651 | M37: =IF(D37="D10",0.1*L37+0.9*$B$14,L37) -> 0.35333529 | N37: =H37*M37 -> 0.0840938 | O37: =C37*$B$5 -> 0.0056 | P37: =IFERROR(K37/I37,"") -> 420.16807
A38: BASE | B38: Coumarin | C38: 0.04 | F38: tonka almond warmth | G38: =$B$9*C38 -> 0.476 | H38: =G38 -> 0.476 | I38: =IF(D38="D10",H38*0.1,H38) -> 0.476 | J38: =IF(D38="D10",H38*0.9,0) -> 0 | K38: =IFERROR(INDEX(Inventory!$K$4:$K$30,MATCH(B38,Inventory!$A$4:$A$30,0)),"") -> 500 | L38: =IFERROR(INDEX(Inventory!$I$4:$I$30,MATCH(B38,Inventory!$A$4:$A$30,0)),0) -> 0.3 | M38: =IF(D38="D10",0.1*L38+0.9*$B$14,L38) -> 0.3 | N38: =H38*M38 -> 0.1428 | O38: =C38*$B$5 -> 0.0112 | P38: =IFERROR(K38/I38,"") -> 1050.4202
A39: BASE | B39: Heliotrope Accord | C39: 0.06 | F39: powdered almond tenderness | G39: =$B$9*C39 -> 0.714 | H39: =G39 -> 0.714 | I39: =IF(D39="D10",H39*0.1,H39) -> 0.714 | J39: =IF(D39="D10",H39*0.9,0) -> 0 | K39: =IFERROR(INDEX(Inventory!$K$4:$K$30,MATCH(B39,Inventory!$A$4:$A$30,0)),"") -> 9 | L39: =IFERROR(INDEX(Inventory!$I$4:$I$30,MATCH(B39,Inventory!$A$4:$A$30,0)),0) -> 3.75 | M39: =IF(D39="D10",0.1*L39+0.9*$B$14,L39) -> 3.75 | N39: =H39*M39 -> 2.6775 | O39: =C39*$B$5 -> 0.0168 | P39: =IFERROR(K39/I39,"") -> 12.605042
A40: BASE | B40: Ambroxan | C40: 0.08 | F40: ambergris radiance and attraction trail | G40: =$B$9*C40 -> 0.952 | H40: =G40 -> 0.952 | I40: =IF(D40="D10",H40*0.1,H40) -> 0.952 | J40: =IF(D40="D10",H40*0.9,0) -> 0 | K40: =IFERROR(INDEX(Inventory!$K$4:$K$30,MATCH(B40,Inventory!$A$4:$A$30,0)),"") -> 20 | L40: =IFERROR(INDEX(Inventory!$I$4:$I$30,MATCH(B40,Inventory!$A$4:$A$30,0)),0) -> 13.375 | M40: =IF(D40="D10",0.1*L40+0.9*$B$14,L40) -> 13.375 | N40: =H40*M40 -> 12.733 | O40: =C40*$B$5 -> 0.0224 | P40: =IFERROR(K40/I40,"") -> 21.008403
A41: BASE | B41: Iso E Super | C41: 0.09 | F41: velvet wood aura | G41: =$B$9*C41 -> 1.071 | H41: =G41 -> 1.071 | I41: =IF(D41="D10",H41*0.1,H41) -> 1.071 | J41: =IF(D41="D10",H41*0.9,0) -> 0 | K41: =IFERROR(INDEX(Inventory!$K$4:$K$30,MATCH(B41,Inventory!$A$4:$A$30,0)),"") -> 27 | L41: =IFERROR(INDEX(Inventory!$I$4:$I$30,MATCH(B41,Inventory!$A$4:$A$30,0)),0) -> 1.4507407 | M41: =IF(D41="D10",0.1*L41+0.9*$B$14,L41) -> 1.4507407 | N41: =H41*M41 -> 1.5537433 | O41: =C41*$B$5 -> 0.0252 | P41: =IFERROR(K41/I41,"") -> 25.210084
A42: BASE | B42: Cashmeran IFF | C42: 0.04 | F42: warm cashmere texture | G42: =$B$9*C42 -> 0.476 | H42: =G42 -> 0.476 | I42: =IF(D42="D10",H42*0.1,H42) -> 0.476 | J42: =IF(D42="D10",H42*0.9,0) -> 0 | K42: =IFERROR(INDEX(Inventory!$K$4:$K$30,MATCH(B42,Inventory!$A$4:$A$30,0)),"") -> 9 | L42: =IFERROR(INDEX(Inventory!$I$4:$I$30,MATCH(B42,Inventory!$A$4:$A$30,0)),0) -> 6.2066667 | M42: =IF(D42="D10",0.1*L42+0.9*$B$14,L42) -> 6.2066667 | N42: =H42*M42 -> 2.9543733 | O42: =C42*$B$5 -> 0.0112 | P42: =IFERROR(K42/I42,"") -> 18.907563
A43: BASE | B43: Sandalore (Givaudan) | C43: 0.04 | F43: creamy sandalwood glow | G43: =$B$9*C43 -> 0.476 | H43: =G43 -> 0.476 | I43: =IF(D43="D10",H43*0.1,H43) -> 0.476 | J43: =IF(D43="D10",H43*0.9,0) -> 0 | K43: =IFERROR(INDEX(Inventory!$K$4:$K$30,MATCH(B43,Inventory!$A$4:$A$30,0)),"") -> 18 | L43: =IFERROR(INDEX(Inventory!$I$4:$I$30,MATCH(B43,Inventory!$A$4:$A$30,0)),0) -> 2.6155556 | M43: =IF(D43="D10",0.1*L43+0.9*$B$14,L43) -> 2.6155556 | N43: =H43*M43 -> 1.2450044 | O43: =C43*$B$5 -> 0.0112 | P43: =IFERROR(K43/I43,"") -> 37.815126
A44: BASE | B44: Ethylene Brassylate | C44: 0.05 | F44: soft intimate musk | G44: =$B$9*C44 -> 0.595 | H44: =G44 -> 0.595 | I44: =IF(D44="D10",H44*0.1,H44) -> 0.595 | J44: =IF(D44="D10",H44*0.9,0) -> 0 | K44: =IFERROR(INDEX(Inventory!$K$4:$K$30,MATCH(B44,Inventory!$A$4:$A$30,0)),"") -> 45 | L44: =IFERROR(INDEX(Inventory!$I$4:$I$30,MATCH(B44,Inventory!$A$4:$A$30,0)),0) -> 0.76422222 | M44: =IF(D44="D10",0.1*L44+0.9*$B$14,L44) -> 0.76422222 | N44: =H44*M44 -> 0.45471222 | O44: =C44*$B$5 -> 0.014 | P44: =IFERROR(K44/I44,"") -> 75.630252
...

Sheet Batch Calculator
A1: SAMR — BATCH CALCULATOR
A2: All quantities in grams. Weighing order: BASE → HEART → TOP. Champagne cells are inputs.
A3: 1 · BATCH INPUTS
A4: Product format | C4: Eau de Parfum | D4: choose one of the six product formats
A5: Batch size | C5: 50 | D5: in the unit chosen below
A6: Size unit (ml / g) | C6: ml | D6: ml is converted to grams with the density cell below
A7: Concentrate % | C7: 0.2 | D7: ="Suggested for this format: "&TEXT(VLOOKUP(BatchFormat,FormatDefaults,2,FALSE),"0.0%")&" (range "&TEXT(VLOOKUP(BatchFormat,FormatDefaults,3,FALSE),"0.0%")&" – "&TEXT(VLOOKUP(BatchFormat,FormatDefaults,4,FALSE),"0.0%")&")" -> Suggested for this format: 20.0% (range 12.0% – 30.0%)
A8: Finished density (g/ml) | C8: 0.85 | D8: ="Typical for this format: "&TEXT(VLOOKUP(BatchFormat,FormatDefaults,5,FALSE),"0.00")&" g/ml" -> Typical for this format: 0.85 g/ml
A9: Optionals included? | C9: =IncludeOptionals -> YES | D9: optionals: Damascone Beta, Saffron Accord — set on Formula Master
A11: 2 · FORMAT PARAMETERS (each is used only by the format named)
A12: Distilled water % (EDP) | C12: 0 | D12: EDP / Extrait — optional, max 3% | E12: CREAM ROUTE 2 — PHASE %
A13: Glycerin % (alc. mist) | C13: 0.02 | D13: Alcohol Body Mist — optional 2–3% | E13: Glycerin (water phase) | G13: 0.03
A14: Water % (alc. mist) | C14: 0.05 | D14: Alcohol Body Mist — optional 5–10% | E14: Emulsifying Wax NF | G14: 0.05
A15: Solubilizer × fragrance | C15: 4 | D15: Water Mist — Polysorbate 20 = 4–6 × fragrance wt | E15: Cetearyl alcohol | G15: 0.02
A16: Glycerin % (W-mist) | C16: 0.025 | D16: Water-Based Mist | E16: Carrier oil (light) | G16: 0.15
A17: Preservative % (W-mist) | C17: 0.008 | D17: Water-Based Mist — broad-spectrum, REQUIRED | E17: Shea / mango butter | G17: 0.05
A18: Vitamin E % (cream 2) | C18: 0.005 | D18: Cream Route 2 — cool-down antioxidant | E18: Preservative | G18: 0.01
A20: 3 · BATCH TOTALS
A21: Total batch mass (g) | C21: =IF(BatchUnit="g",BatchSize,BatchSize*FinishedDensity) -> 42.5 | D21: batch size converted to grams
A22: Batch volume (ml, approx.) | C22: =IF(BatchUnit="ml",BatchSize,BatchSize/FinishedDensity) -> 50 | D22: for cost-per-ml
A23: Fragrance concentrate (g) | C23: =TotalMassG*ConcPct -> 8.5 | D23: total to weigh from the table below
A24: Estimated batch cost (SAR) | C24: =ConcG*ConcCostPerGLoaded+SUMPRODUCT(AuxGrams,AuxCostPerG) -> 27.322281 | D24: materials incl. shipping allocation — see Cost Analysis
A25: Cost per ml (SAR) | C25: =IF(BatchVolMl=0,"",BatchCostSAR/BatchVolMl) -> 0.54644562
A27: 4 · CONCENTRATE WEIGHING (weigh in this order: BASE → HEART → TOP)
A28: Phase | B28: Material | D28: % of conc. | E28: Weigh (g) | F28: Form | G28: Neat (g) | H28: ✓
A29: BASE | B29: Vanillin Crystals | D29: =INDEX(FM_Active,MATCH($B29,FM_Mat,0)) -> 0.07 | E29: =ConcG*D29 -> 0.595 | F29: =IF(INDEX(FM_D10,MATCH($B29,FM_Mat,0))="D10","10% in DPG","neat") -> neat | G29: =E29*IF(INDEX(FM_D10,MATCH($B29,FM_Mat,0))="D10",0.1,1) -> 0.595
A30: BASE | B30: Ethyl Vanillin | D30: =INDEX(FM_Active,MATCH($B30,FM_Mat,0)) -> 0.025 | E30: =ConcG*D30 -> 0.2125 | F30: =IF(INDEX(FM_D10,MATCH($B30,FM_Mat,0))="D10","10% in DPG","neat") -> neat | G30: =E30*IF(INDEX(FM_D10,MATCH($B30,FM_Mat,0))="D10",0.1,1) -> 0.2125
A31: BASE | B31: Maltol (Crystals) | D31: =INDEX(FM_Active,MATCH($B31,FM_Mat,0)) -> 0.02 | E31: =ConcG*D31 -> 0.17 | F31: =IF(INDEX(FM_D10,MATCH($B31,FM_Mat,0))="D10","10% in DPG","neat") -> 10% in DPG | G31: =E31*IF(INDEX(FM_D10,MATCH($B31,FM_Mat,0))="D10",0.1,1) -> 0.017
A32: BASE | B32: Coumarin | D32: =INDEX(FM_Active,MATCH($B32,FM_Mat,0)) -> 0.045 | E32: =ConcG*D32 -> 0.3825 | F32: =IF(INDEX(FM_D10,MATCH($B32,FM_Mat,0))="D10","10% in DPG","neat") -> neat | G32: =E32*IF(INDEX(FM_D10,MATCH($B32,FM_Mat,0))="D10",0.1,1) -> 0.3825
A33: BASE | B33: Heliotrope Accord | D33: =INDEX(FM_Active,MATCH($B33,FM_Mat,0)) -> 0.025 | E33: =ConcG*D33 -> 0.2125 | F33: =IF(INDEX(FM_D10,MATCH($B33,FM_Mat,0))="D10","10% in DPG","neat") -> neat | G33: =E33*IF(INDEX(FM_D10,MATCH($B33,FM_Mat,0))="D10",0.1,1) -> 0.2125
A34: BASE | B34: Aldehyde C-18 Coconut | D34: =INDEX(FM_Active,MATCH($B34,FM_Mat,0)) -> 0.015 | E34: =ConcG*D34 -> 0.1275 | F34: =IF(INDEX(FM_D10,MATCH($B34,FM_Mat,0))="D10","10% in DPG","neat") -> 10% in DPG | G34: =E34*IF(INDEX(FM_D10,MATCH($B34,FM_Mat,0))="D10",0.1,1) -> 0.01275
A35: BASE | B35: Ambroxan | D35: =INDEX(FM_Active,MATCH($B35,FM_Mat,0)) -> 0.075 | E35: =ConcG*D35 -> 0.6375 | F35: =IF(INDEX(FM_D10,MATCH($B35,FM_Mat,0))="D10","10% in DPG","neat") -> neat | G35: =E35*IF(INDEX(FM_D10,MATCH($B35,FM_Mat,0))="D10",0.1,1) -> 0.6375
A36: BASE | B36: Iso E Super | D36: =INDEX(FM_Active,MATCH($B36,FM_Mat,0)) -> 0.095 | E36: =ConcG*D36 -> 0.8075 | F36: =IF(INDEX(FM_D10,MATCH($B36,FM_Mat,0))="D10","10% in DPG","neat") -> neat | G36: =E36*IF(INDEX(FM_D10,MATCH($B36,FM_Mat,0))="D10",0.1,1) -> 0.8075
A37: BASE | B37: Cashmeran IFF | D37: =INDEX(FM_Active,MATCH($B37,FM_Mat,0)) -> 0.03 | E37: =ConcG*D37 -> 0.255 | F37: =IF(INDEX(FM_D10,MATCH($B37,FM_Mat,0))="D10","10% in DPG","neat") -> neat | G37: =E37*IF(INDEX(FM_D10,MATCH($B37,FM_Mat,0))="D10",0.1,1) -> 0.255
A38: BASE | B38: Sandalore (Givaudan) | D38: =INDEX(FM_Active,MATCH($B38,FM_Mat,0)) -> 0.035 | E38: =ConcG*D38 -> 0.2975 | F38: =IF(INDEX(FM_D10,MATCH($B38,FM_Mat,0))="D10","10% in DPG","neat") -> neat | G38: =E38*IF(INDEX(FM_D10,MATCH($B38,FM_Mat,0))="D10",0.1,1) -> 0.2975
A39: BASE | B39: Ethylene Brassylate | D39: =INDEX(FM_Active,MATCH($B39,FM_Mat,0)) -> 0.075 | E39: =ConcG*D39 -> 0.6375 | F39: =IF(INDEX(FM_D10,MATCH($B39,FM_Mat,0))="D10","10% in DPG","neat") -> neat | G39: =E39*IF(INDEX(FM_D10,MATCH($B39,FM_Mat,0))="D10",0.1,1) -> 0.6375
A40: BASE | B40: Galaxolide | D40: =INDEX(FM_Active,MATCH($B40,FM_Mat,0)) -> 0.055 | E40: =ConcG*D40 -> 0.4675 | F40: =IF(INDEX(FM_D10,MATCH($B40,FM_Mat,0))="D10","10% in DPG","neat") -> neat | G40: =E40*IF(INDEX(FM_D10,MATCH($B40,FM_Mat,0))="D10",0.1,1) -> 0.4675
... A53: TOP | B53: Raspberry Accord | D53: =INDEX(FM_Active,MATCH($B53,FM_Mat,0)) -> 0.01 | E53: =ConcG*D53 -> 0.085 | F53: =IF(INDEX(FM_D10,MATCH($B53,FM_Mat,0))="D10","10% in DPG","neat") -> neat | G53: =E53*IF(INDEX(FM_D10,MATCH($B53,FM_Mat,0))="D10",0.1,1) -> 0.085
A54: CONCENTRATE TOTAL (must equal the concentrate above) | E54: =SUM(E29:E53) -> 8.5 | F54: =IF(ABS(E54-ConcG)<0.005,"✓","⚠") -> ✓ | G54: =SUM(G29:G53) -> 8.1328
A56: 5 · SOLVENT & AUXILIARY COMPONENTS
...

Sheet Dilution Prep (D10)
A1: D10 DILUTIONS — 10% IN DPG
A2: Default batch: 10 g of solution = 1.0 g neat material + 9.0 g DPG. Prepare at least 24 h before blending.
A4: Material | B4: Strength | C4: Batch (g) | D4: Neat (g) | E4: DPG (g) | F4: Date made | G4: Remaining (g) | H4: Label / notes
A5: Pink Peppercorn | B5: 0.1 | C5: 10 | D5: =C5*B5 -> 1 | E5: =C5-D5 -> 9 | H5: ="SAMR · "&A5&" · 10% in DPG · "&IF(F5="","(date)",TEXT(F5,"yyyy-mm-dd")) -> SAMR · Pink Peppercorn · 10% in DPG · (date)
A6: Damascone Beta | B6: 0.1 | C6: 10 | D6: =C6*B6 -> 1 | E6: =C6-D6 -> 9 | H6: ="SAMR · "&A6&" · 10% in DPG · "&IF(F6="","(date)",TEXT(F6,"yyyy-mm-dd")) -> SAMR · Damascone Beta · 10% in DPG · (date)
A7: Maltol (Crystals) | B7: 0.1 | C7: 10 | D7: =C7*B7 -> 1 | E7: =C7-D7 -> 9 | H7: ="SAMR · "&A7&" · 10% in DPG · "&IF(F7="","(date)",TEXT(F7,"yyyy-mm-dd")) -> SAMR · Maltol (Crystals) · 10% in DPG · (date)
A8: Aldehyde C-18 Coconut | B8: 0.1 | C8: 10 | D8: =C8*B8 -> 1 | E8: =C8-D8 -> 9 | H8: ="SAMR · "&A8&" · 10% in DPG · "&IF(F8="","(date)",TEXT(F8,"yyyy-mm-dd")) -> SAMR · Aldehyde C-18 Coconut · 10% in DPG · (date)
A11: 1 · Tare a clean 12–15 ml glass bottle on the scale (0.01 g resolution or better).
A12: 2 · Weigh the NEAT material first, then add DPG up to the total. Cap tightly and shake 1 minute.
A13: 3 · Label with the text in the last column. Store dark and cool. Dilutions keep 12+ months.
A14: 4 · When a dilution runs low, make a fresh 10 g batch and update 'Date made' and 'Remaining'.

Sheet Inventory
A1: INVENTORY
A2: On hand = purchases − usage from the Production Log. SAMR shares several jars with ASMR — each workbook tracks its own usage, so split the stock or deduct shared use manually. | F2: Conc / batch (g): | H2: =50*0.85*0.2 -> 8.5 | I2: Alcohol / batch (g): | K2: =50*0.85*0.8 -> 34
A3: Material | B3: Pack | C3: Unit | D3: Packs | E3: Density g/ml | F3: Grams bought | G3: Price/pack SAR (Iterji 2026-07-14) | H3: Paid SAR | I3: SAR/g | J3: Used (g) | K3: On hand (g) | L3: Alert < (g) | M3: Status | N3: Product Link | O3: 50 ml bottles
A4: Bergamot Accord | B4: 30 | C4: ml | D4: 1 | E4: 0.9 | F4: =IF(C4="ml",B4*D4*E4,B4*D4) -> 27 | G4: 54 | H4: =G4*D4 -> 54 | I4: =IF(F4=0,0,H4/F4) -> 2 | J4: =TotalConcUsedG*INDEX(FM_Active,MATCH($A4,FM_Mat,0))*IF(INDEX(FM_D10,MATCH($A4,FM_Mat,0))="D10",0.1,1) -> 0 | K4: =F4-J4 -> 27 | L4: =2*DefaultBatchConcG*INDEX(FM_Active,MATCH($A4,FM_Mat,0))*IF(INDEX(FM_D10,MATCH($A4,FM_Mat,0))="D10",0.1,1) -> 0.765 | M4: =IF(K4<L4,"LOW","OK") -> OK | N4: iterji.com ↗ | O4: =IFERROR(FLOOR((MAX(K4,0)/(INDEX(FM_Active,MATCH($A4,FM_Mat,0))*IF(INDEX(FM_D10,MATCH($A4,FM_Mat,0))="D10",0.1,1)))/(50*YC_Density*YC_ConcPct),1),"") -> 70 | P4: =IF(K4<L4,A4,"") | Q4: =P4 | R4: 1
A5: Pink Peppercorn | B5: 10 | C5: ml | D5: 1 | E5: 0.9 | F5: =IF(C5="ml",B5*D5*E5,B5*D5) -> 9 | G5: 141.25 | H5: =G5*D5 -> 141.25 | I5: =IF(F5=0,0,H5/F5) -> 15.694444 | J5: =TotalConcUsedG*INDEX(FM_Active,MATCH($A5,FM_Mat,0))*IF(INDEX(FM_D10,MATCH($A5,FM_Mat,0))="D10",0.1,1) -> 0 | K5: =F5-J5 -> 9 | L5: =2*DefaultBatchConcG*INDEX(FM_Active,MATCH($A5,FM_Mat,0))*IF(INDEX(FM_D10,MATCH($A5,FM_Mat,0))="D10",0.1,1) -> 0.017 | M5: =IF(K5<L5,"LOW","OK") -> OK | N5: iterji.com ↗ | O5: =IFERROR(FLOOR((MAX(K5,0)/(INDEX(FM_Active,MATCH($A5,FM_Mat,0))*IF(INDEX(FM_D10,MATCH($A5,FM_Mat,0))="D10",0.1,1)))/(50*YC_Density*YC_ConcPct),1),"") -> 1058 | P5: =IF(K5<L5,A5,"") | Q5: =IF(P5="",Q4,IF(Q4="",P5,Q4&", "&P5)) | R5: 2
A6: Aldehyde C-14 Peach | B6: 10 | C6: ml | D6: 2 | E6: 0.9 | F6: =IF(C6="ml",B6*D6*E6,B6*D6) -> 18 | G6: 16.74 | H6: =G6*D6 -> 33.48 | I6: =IF(F6=0,0,H6/F6) -> 1.86 | J6: =TotalConcUsedG*INDEX(FM_Active,MATCH($A6,FM_Mat,0))*IF(INDEX(FM_D10,MATCH($A6,FM_Mat,0))="D10",0.1,1) -> 0 | K6: =F6-J6 -> 18 | L6: =2*DefaultBatchConcG*INDEX(FM_Active,MATCH($A6,FM_Mat,0))*IF(INDEX(FM_D10,MATCH($A6,FM_Mat,0))="D10",0.1,1) -> 0.34 | M6: =IF(K6<L6,"LOW","OK") -> OK | N6: iterji.com ↗ | O6: =IFERROR(FLOOR((MAX(K6,0)/(INDEX(FM_Active,MATCH($A6,FM_Mat,0))*IF(INDEX(FM_D10,MATCH($A6,FM_Mat,0))="D10",0.1,1)))/(50*YC_Density*YC_ConcPct),1),"") -> 105 | P6: =IF(K6<L6,A6,"") | Q6: =IF(P6="",Q5,IF(Q5="",P6,Q5&", "&P6)) | R6: 3
A7: Raspberry Accord | B7: 10 | C7: ml | D7: 1 | E7: 0.9 | F7: =IF(C7="ml",B7*D7*E7,B7*D7) -> 9 | G7: 22.5 | H7: =G7*D7 -> 22.5 | I7: =IF(F7=0,0,H7/F7) -> 2.5 | J7: =TotalConcUsedG*INDEX(FM_Active,MATCH($A7,FM_Mat,0))*IF(INDEX(FM_D10,MATCH($A7,FM_Mat,0))="D10",0.1,1) -> 0 | K7: =F7-J7 -> 9 | L7: =2*DefaultBatchConcG*INDEX(FM_Active,MATCH($A7,FM_Mat,0))*IF(INDEX(FM_D10,MATCH($A7,FM_Mat,0))="D10",0.1,1) -> 0.17 | M7: =IF(K7<L7,"LOW","OK") -> OK | N7: iterji.com ↗ | O7: =IFERROR(FLOOR((MAX(K7,0)/(INDEX(FM_Active,MATCH($A7,FM_Mat,0))*IF(INDEX(FM_D10,MATCH($A7,FM_Mat,0))="D10",0.1,1)))/(50*YC_Density*YC_ConcPct),1),"") -> 105 | P7: =IF(K7<L7,A7,"") | Q7: =IF(P7="",Q6,IF(Q6="",P7,Q6&", "&P7)) | R7: 4
A8: Hedione (Firmenich) | B8: 100 | C8: ml | D8: 1 | E8: 0.9 | F8: =IF(C8="ml",B8*D8*E8,B8*D8) -> 90 | G8: 39.84 | H8: =G8*D8 -> 39.84 | I8: =IF(F8=0,0,H8/F8) -> 0.44266667 | J8: =TotalConcUsedG*INDEX(FM_Active,MATCH($A8,FM_Mat,0))*IF(INDEX(FM_D10,MATCH($A8,FM_Mat,0))="D10",0.1,1) -> 0 | K8: =F8-J8 -> 90 | L8: =2*DefaultBatchConcG*INDEX(FM_Active,MATCH($A8,FM_Mat,0))*IF(INDEX(FM_D10,MATCH($A8,FM_Mat,0))="D10",0.1,1) -> 2.499 | M8: =IF(K8<L8,"LOW","OK") -> OK | N8: iterji.com ↗ | O8: =IFERROR(FLOOR((MAX(K8,0)/(INDEX(FM_Active,MATCH($A8,FM_Mat,0))*IF(INDEX(FM_D10,MATCH($A8,FM_Mat,0))="D10",0.1,1)))/(50*YC_Density*YC_ConcPct),1),"") -> 72 | P8: =IF(K8<L8,A8,"") | Q8: =IF(P8="",Q7,IF(Q7="",P8,Q7&", "&P8)) | R8: 5
A9: Jasmin Absolute Accord | B9: 10 | C9: ml | D9: 2 | E9: 0.9 | F9: =IF(C9="ml",B9*D9*E9,B9*D9) -> 18 | G9: 45 | H9: =G9*D9 -> 90 | I9: =IF(F9=0,0,H9/F9) -> 5 | J9: =TotalConcUsedG*INDEX(FM_Active,MATCH($A9,FM_Mat,0))*IF(INDEX(FM_D10,MATCH($A9,FM_Mat,0))="D10",0.1,1) -> 0 | K9: =F9-J9 -> 18 | L9: =2*DefaultBatchConcG*INDEX(FM_Active,MATCH($A9,FM_Mat,0))*IF(INDEX(FM_D10,MATCH($A9,FM_Mat,0))="D10",0.1,1) -> 0.51 | M9: =IF(K9<L9,"LOW","OK") -> OK | N9: iterji.com ↗ | O9: =IFERROR(FLOOR((MAX(K9,0)/(INDEX(FM_Active,MATCH($A9,FM_Mat,0))*IF(INDEX(FM_D10,MATCH($A9,FM_Mat,0))="D10",0.1,1)))/(50*YC_Density*YC_ConcPct),1),"") -> 70 | P9: =IF(K9<L9,A9,"") | Q9: =IF(P9="",Q8,IF(Q8="",P9,Q8&", "&P9)) | R9: 6
A10: Tuberose Accord | B10: 10 | C10: ml | D10: 1 | E10: 0.9 | F10: =IF(C10="ml",B10*D10*E10,B10*D10) -> 9 | G10: 35.63 | H10: =G10*D10 -> 35.63 | I10: =IF(F10=0,0,H10/F10) -> 3.9588889 | J10: =TotalConcUsedG*INDEX(FM_Active,MATCH($A10,FM_Mat,0))*IF(INDEX(FM_D10,MATCH($A10,FM_Mat,0))="D10",0.1,1) -> 0 | K10: =F10-J10 -> 9 | L10: =2*DefaultBatchConcG*INDEX(FM_Active,MATCH($A10,FM_Mat,0))*IF(INDEX(FM_D10,MATCH($A10,FM_Mat,0))="D10",0.1,1) -> 0.255 | M10: =IF(K10<L10,"LOW","OK") -> OK | N10: iterji.com ↗ | O10: =IFERROR(FLOOR((MAX(K10,0)/(INDEX(FM_Active,MATCH($A10,FM_Mat,0))*IF(INDEX(FM_D10,MATCH($A10,FM_Mat,0))="D10",0.1,1)))/(50*YC_Density*YC_ConcPct),1),"") -> 70 | P10: =IF(K10<L10,A10,"") | Q10: =IF(P10="",Q9,IF(Q9="",P10,Q9&", "&P10)) | R10: 7
A11: Methyl Alpha Ionone Iso | B11: 30 | C11: ml | D11: 1 | E11: 0.9 | F11: =IF(C11="ml",B11*D11*E11,B11*D11) -> 27 | G11: 50.27 | H11: =G11*D11 -> 50.27 | I11: =IF(F11=0,0,H11/F11) -> 1.8618519 | J11: =TotalConcUsedG*INDEX(FM_Active,MATCH($A11,FM_Mat,0))*IF(INDEX(FM_D10,MATCH($A11,FM_Mat,0))="D10",0.1,1) -> 0 | K11: =F11-J11 -> 27 | L11: =2*DefaultBatchConcG*INDEX(FM_Active,MATCH($A11,FM_Mat,0))*IF(INDEX(FM_D10,MATCH($A11,FM_Mat,0))="D10",0.1,1) -> 0.68 | M11: =IF(K11<L11,"LOW","OK") -> OK | N11: iterji.com ↗ | O11: =IFERROR(FLOOR((MAX(K11,0)/(INDEX(FM_Active,MATCH($A11,FM_Mat,0))*IF(INDEX(FM_D10,MATCH($A11,FM_Mat,0))="D10",0.1,1)))/(50*YC_Density*YC_ConcPct),1),"") -> 79 | P11: =IF(K11<L11,A11,"") | Q11: =IF(P11="",Q10,IF(Q10="",P11,Q10&", "&P11)) | R11: 8
A12: Benzyl Salicylate | B12: 30 | C12: ml | D12: 2 | E12: 0.9 | F12: =IF(C12="ml",B12*D12*E12,B12*D12) -> 54 | G12: 32.14 | H12: =G12*D12 -> 64.28 | I12: =IF(F12=0,0,H12/F12) -> 1.1903704 | J12: =TotalConcUsedG*INDEX(FM_Active,MATCH($A12,FM_Mat,0))*IF(INDEX(FM_D10,MATCH($A12,FM_Mat,0))="D10",0.1,1) -> 0 | K12: =F12-J12 -> 54 | L12: =2*DefaultBatchConcG*INDEX(FM_Active,MATCH($A12,FM_Mat,0))*IF(INDEX(FM_D10,MATCH($A12,FM_Mat,0))="D10",0.1,1) -> 1.19 | M12: =IF(K12<L12,"LOW","OK") -> OK | N12: iterji.com ↗ | O12: =IFERROR(FLOOR((MAX(K12,0)/(INDEX(FM_Active,MATCH($A12,FM_Mat,0))*IF(INDEX(FM_D10,MATCH($A12,FM_Mat,0))="D10",0.1,1)))/(50*YC_Density*YC_ConcPct),1),"") -> 90 | P12: =IF(K12<L12,A12,"") | Q12: =IF(P12="",Q11,IF(Q11="",P12,Q11&", "&P12)) | R12: 9
A13: Linalool | B13: 10 | C13: ml | D13: 2 | E13: 0.9 | F13: =IF(C13="ml",B13*D13*E13,B13*D13) -> 18 | G13: 16.74 | H13: =G13*D13 -> 33.48 | I13: =IF(F13=0,0,H13/F13) -> 1.86 | J13: =TotalConcUsedG*INDEX(FM_Active,MATCH($A13,FM_Mat,0))*IF(INDEX(FM_D10,MATCH($A13,FM_Mat,0))="D10",0.1,1) -> 0 | K13: =F13-J13 -> 18 | L13: =2*DefaultBatchConcG*INDEX(FM_Active,MATCH($A13,FM_Mat,0))*IF(INDEX(FM_D10,MATCH($A13,FM_Mat,0))="D10",0.1,1) -> 0.255 | M13: =IF(K13<L13,"LOW","OK") -> OK | N13: iterji.com ↗ | O13: =IFERROR(FLOOR((MAX(K13,0)/(INDEX(FM_Active,MATCH($A13,FM_Mat,0))*IF(INDEX(FM_D10,MATCH($A13,FM_Mat,0))="D10",0.1,1)))/(50*YC_Density*YC_ConcPct),1),"") -> 141 | P13: =IF(K13<L13,A13,"") | Q13: =IF(P13="",Q12,IF(Q12="",P13,Q12&", "&P13)) | R13: 10
A14: Damascone Beta | B14: 10 | C14: ml | D14: 1 | E14: 0.9 | F14: =IF(C14="ml",B14*D14*E14,B14*D14) -> 9 | G14: 98.75 | H14: =G14*D14 -> 98.75 | I14: =IF(F14=0,0,H14/F14) -> 10.972222 | J14: =TotalConcUsedG*INDEX(FM_Active,MATCH($A14,FM_Mat,0))*IF(INDEX(FM_D10,MATCH($A14,FM_Mat,0))="D10",0.1,1) -> 0 | K14: =F14-J14 -> 9 | L14: =2*DefaultBatchConcG*INDEX(FM_Active,MATCH($A14,FM_Mat,0))*IF(INDEX(FM_D10,MATCH($A14,FM_Mat,0))="D10",0.1,1) -> 0.0051 | M14: =IF(K14<L14,"LOW","OK") -> OK | N14: iterji.com ↗ | O14: =IFERROR(FLOOR((MAX(K14,0)/(INDEX(FM_Active,MATCH($A14,FM_Mat,0))*IF(INDEX(FM_D10,MATCH($A14,FM_Mat,0))="D10",0.1,1)))/(50*YC_Density*YC_ConcPct),1),"") -> 3529 | P14: =IF(K14<L14,A14,"") | Q14: =IF(P14="",Q13,IF(Q13="",P14,Q13&", "&P14)) | R14: 11
A15: Vanillin Crystals | B15: 30 | C15: g | D15: 1 | F15: =IF(C15="ml",B15*D15*E15,B15*D15) -> 30 | G15: 42.18 | H15: =G15*D15 -> 42.18 | I15: =IF(F15=0,0,H15/F15) -> 1.406 | J15: =TotalConcUsedG*INDEX(FM_Active,MATCH($A15,FM_Mat,0))*IF(INDEX(FM_D10,MATCH($A15,FM_Mat,0))="D10",0.1,1) -> 0 | K15: =F15-J15 -> 30 | L15: =2*DefaultBatchConcG*INDEX(FM_Active,MATCH($A15,FM_Mat,0))*IF(INDEX(FM_D10,MATCH($A15,FM_Mat,0))="D10",0.1,1) -> 1.19 | M15: =IF(K15<L15,"LOW","OK") -> OK | N15: iterji.com ↗ | O15: =IFERROR(FLOOR((MAX(K15,0)/(INDEX(FM_Active,MATCH($A15,FM_Mat,0))*IF(INDEX(FM_D10,MATCH($A15,FM_Mat,0))="D10",0.1,1)))/(50*YC_Density*YC_ConcPct),1),"") -> 50 | P15: =IF(K15<L15,A15,"") | Q15: =IF(P15="",Q14,IF(Q14="",P15,Q14&", "&P15)) | R15: 12
A16: Ethyl Vanillin | B16: 10 | C16: g | D16: 2 | F16: =IF(C16="ml",B16*D16*E16,B16*D16) -> 20 | G16: 15.69 | H16: =G16*D16 -> 31.38 | I16: =IF(F16=0,0,H16/F16) -> 1.569 | J16: =TotalConcUsedG*INDEX(FM_Active,MATCH($A16,FM_Mat,0))*IF(INDEX(FM_D10,MATCH($A16,FM_Mat,0))="D10",0.1,1) -> 0 | K16: =F16-J16 -> 20 | L16: =2*DefaultBatchConcG*INDEX(FM_Active,MATCH($A16,FM_Mat,0))*IF(INDEX(FM_D10,MATCH($A16,FM_Mat,0))="D10",0.1,1) -> 0.425 | M16: =IF(K16<L16,"LOW","OK") -> OK | N16: iterji.com ↗ | O16: =IFERROR(FLOOR((MAX(K16,0)/(INDEX(FM_Active,MATCH($A16,FM_Mat,0))*IF(INDEX(FM_D10,MATCH($A16,FM_Mat,0))="D10",0.1,1)))/(50*YC_Density*YC_ConcPct),1),"") -> 94 | P16: =IF(K16<L16,A16,"") | Q16: =IF(P16="",Q15,IF(Q15="",P16,Q15&", "&P16)) | R16: 13
A17: Maltol (Crystals) | B17: 10 | C17: g | D17: 1 | F17: =IF(C17="ml",B17*D17*E17,B17*D17) -> 10 | G17: 26.51 | H17: =G17*D17 -> 26.51 | I17: =IF(F17=0,0,H17/F17) -> 2.651 | J17: =TotalConcUsedG*INDEX(FM_Active,MATCH($A17,FM_Mat,0))*IF(INDEX(FM_D10,MATCH($A17,FM_Mat,0))="D10",0.1,1) -> 0 | K17: =F17-J17 -> 10 | L17: =2*DefaultBatchConcG*INDEX(FM_Active,MATCH($A17,FM_Mat,0))*IF(INDEX(FM_D10,MATCH($A17,FM_Mat,0))="D10",0.1,1) -> 0.034 | M17: =IF(K17<L17,"LOW","OK") -> OK | N17: iterji.com ↗ | O17: =IFERROR(FLOOR((MAX(K17,0)/(INDEX(FM_Active,MATCH($A17,FM_Mat,0))*IF(INDEX(FM_D10,MATCH($A17,FM_Mat,0))="D10",0.1,1)))/(50*YC_Density*YC_ConcPct),1),"") -> 588 | P17: =IF(K17<L17,A17,"") | Q17: =IF(P17="",Q16,IF(Q16="",P17,Q16&", "&P17)) | R17: 14
A18: Coumarin | B18: 500 | C18: g | D18: 1 | F18: =IF(C18="ml",B18*D18*E18,B18*D18) -> 500 | G18: 150 | H18: =G18*D18 -> 150 | I18: =IF(F18=0,0,H18/F18) -> 0.3 | J18: =TotalConcUsedG*INDEX(FM_Active,MATCH($A18,FM_Mat,0))*IF(INDEX(FM_D10,MATCH($A18,FM_Mat,0))="D10",0.1,1) -> 0 | K18: =F18-J18 -> 500 | L18: =2*DefaultBatchConcG*INDEX(FM_Active,MATCH($A18,FM_Mat,0))*IF(INDEX(FM_D10,MATCH($A18,FM_Mat,0))="D10",0.1,1) -> 0.765 | M18: =IF(K18<L18,"LOW","OK") -> OK | N18: iterji.com ↗ | O18: =IFERROR(FLOOR((MAX(K18,0)/(INDEX(FM_Active,MATCH($A18,FM_Mat,0))*IF(INDEX(FM_D10,MATCH($A18,FM_Mat,0))="D10",0.1,1)))/(50*YC_Density*YC_ConcPct),1),"") -> 1307 | P18: =IF(K18<L18,A18,"") | Q18: =IF(P18="",Q17,IF(Q17="",P18,Q17&", "&P18)) | R18: 15
A19: Heliotrope Accord | B19: 10 | C19: ml | D19: 1 | E19: 0.9 | F19: =IF(C19="ml",B19*D19*E19,B19*D19) -> 9 | G19: 33.75 | H19: =G19*D19 -> 33.75 | I19: =IF(F19=0,0,H19/F19) -> 3.75 | J19: =TotalConcUsedG*INDEX(FM_Active,MATCH($A19,FM_Mat,0))*IF(INDEX(FM_D10,MATCH($A19,FM_Mat,0))="D10",0.1,1) -> 0 | K19: =F19-J19 -> 9 | L19: =2*DefaultBatchConcG*INDEX(FM_Active,MATCH($A19,FM_Mat,0))*IF(INDEX(FM_D10,MATCH($A19,FM_Mat,0))="D10",0.1,1) -> 0.425 | M19: =IF(K19<L19,"LOW","OK") -> OK | N19: iterji.com ↗ | O19: =IFERROR(FLOOR((MAX(K19,0)/(INDEX(FM_Active,MATCH($A19,FM_Mat,0))*IF(INDEX(FM_D10,MATCH($A19,FM_Mat,0))="D10",0.1,1)))/(50*YC_Density*YC_ConcPct),1),"") -> 42 | P19: =IF(K19<L19,A19,"") | Q19: =IF(P19="",Q18,IF(Q18="",P19,Q18&", "&P19)) | R19: 16
A20: Aldehyde C-18 Coconut | B20: 10 | C20: ml | D20: 1 | E20: 0.9 | F20: =IF(C20="ml",B20*D20*E20,B20*D20) -> 9 | G20: 13.25 | H20: =G20*D20 -> 13.25 | I20: =IF(F20=0,0,H20/F20) -> 1.4722222 | J20: =TotalConcUsedG*INDEX(FM_Active,MATCH($A20,FM_Mat,0))*IF(INDEX(FM_D10,MATCH($A20,FM_Mat,0))="D10",0.1,1) -> 0 | K20: =F20-J20 -> 9 | L20: =2*DefaultBatchConcG*INDEX(FM_Active,MATCH($A20,FM_Mat,0))*IF(INDEX(FM_D10,MATCH($A20,FM_Mat,0))="D10",0.1,1) -> 0.0255 | M20: =IF(K20<L20,"LOW","OK") -> OK | N20: iterji.com ↗ | O20: =IFERROR(FLOOR((MAX(K20,0)/(INDEX(FM_Active,MATCH($A20,FM_Mat,0))*IF(INDEX(FM_D10,MATCH($A20,FM_Mat,0))="D10",0.1,1)))/(50*YC_Density*YC_ConcPct),1),"") -> 705 | P20: =IF(K20<L20,A20,"") | Q20: =IF(P20="",Q19,IF(Q19="",P20,Q19&", "&P20)) | R20: 17
A21: Ambroxan | B21: 10 | C21: g | D21: 2 | F21: =IF(C21="ml",B21*D21*E21,B21*D21) -> 20 | G21: 133.75 | H21: =G21*D21 -> 267.5 | I21: =IF(F21=0,0,H21/F21) -> 13.375 | J21: =TotalConcUsedG*INDEX(FM_Active,MATCH($A21,FM_Mat,0))*IF(INDEX(FM_D10,MATCH($A21,FM_Mat,0))="D10",0.1,1) -> 0 | K21: =F21-J21 -> 20 | L21: =2*DefaultBatchConcG*INDEX(FM_Active,MATCH($A21,FM_Mat,0))*IF(INDEX(FM_D10,MATCH($A21,FM_Mat,0))="D10",0.1,1) -> 1.275 | M21: =IF(K21<L21,"LOW","OK") -> OK | N21: iterji.com ↗ | O21: =IFERROR(FLOOR((MAX(K21,0)/(INDEX(FM_Active,MATCH($A21,FM_Mat,0))*IF(INDEX(FM_D10,MATCH($A21,FM_Mat,0))="D10",0.1,1)))/(50*YC_Density*YC_ConcPct),1),"") -> 31 | P21: =IF(K21<L21,A21,"") | Q21: =IF(P21="",Q20,IF(Q20="",P21,Q20&", "&P21)) | R21: 18
A22: Iso E Super | B22: 30 | C22: ml | D22: 1 | E22: 0.9 | F22: =IF(C22="ml",B22*D22*E22,B22*D22) -> 27 | G22: 39.17 | H22: =G22*D22 -> 39.17 | I22: =IF(F22=0,0,H22/F22) -> 1.4507407 | J22: =TotalConcUsedG*INDEX(FM_Active,MATCH($A22,FM_Mat,0))*IF(INDEX(FM_D10,MATCH($A22,FM_Mat,0))="D10",0.1,1) -> 0 | K22: =F22-J22 -> 27 | L22: =2*DefaultBatchConcG*INDEX(FM_Active,MATCH($A22,FM_Mat,0))*IF(INDEX(FM_D10,MATCH($A22,FM_Mat,0))="D10",0.1,1) -> 1.615 | M22: =IF(K22<L22,"LOW","OK") -> OK | N22: iterji.com ↗ | O22: =IFERROR(FLOOR((MAX(K22,0)/(INDEX(FM_Active,MATCH($A22,FM_Mat,0))*IF(INDEX(FM_D10,MATCH($A22,FM_Mat,0))="D10",0.1,1)))/(50*YC_Density*YC_ConcPct),1),"") -> 33 | P22: =IF(K22<L22,A22,"") | Q22: =IF(P22="",Q21,IF(Q21="",P22,Q21&", "&P22)) | R22: 19
A23: Cashmeran IFF | B23: 10 | C23: ml | D23: 1 | E23: 0.9 | F23: =IF(C23="ml",B23*D23*E23,B23*D23) -> 9 | G23: 55.86 | H23: =G23*D23 -> 55.86 | I23: =IF(F23=0,0,H23/F23) -> 6.2066667 | J23: =TotalConcUsedG*INDEX(FM_Active,MATCH($A23,FM_Mat,0))*IF(INDEX(FM_D10,MATCH($A23,FM_Mat,0))="D10",0.1,1) -> 0 | K23: =F23-J23 -> 9 | L23: =2*DefaultBatchConcG*INDEX(FM_Active,MATCH($A23,FM_Mat,0))*IF(INDEX(FM_D10,MATCH($A23,FM_Mat,0))="D10",0.1,1) -> 0.51 | M23: =IF(K23<L23,"LOW","OK") -> OK | N23: iterji.com ↗ | O23: =IFERROR(FLOOR((MAX(K23,0)/(INDEX(FM_Active,MATCH($A23,FM_Mat,0))*IF(INDEX(FM_D10,MATCH($A23,FM_Mat,0))="D10",0.1,1)))/(50*YC_Density*YC_ConcPct),1),"") -> 35 | P23: =IF(K23<L23,A23,"") | Q23: =IF(P23="",Q22,IF(Q22="",P23,Q22&", "&P23)) | R23: 20
A24: Sandalore (Givaudan) | B24: 10 | C24: ml | D24: 2 | E24: 0.9 | F24: =IF(C24="ml",B24*D24*E24,B24*D24) -> 18 | G24: 23.54 | H24: =G24*D24 -> 47.08 | I24: =IF(F24=0,0,H24/F24) -> 2.6155556 | J24: =TotalConcUsedG*INDEX(FM_Active,MATCH($A24,FM_Mat,0))*IF(INDEX(FM_D10,MATCH($A24,FM_Mat,0))="D10",0.1,1) -> 0 | K24: =F24-J24 -> 18 | L24: =2*DefaultBatchConcG*INDEX(FM_Active,MATCH($A24,FM_Mat,0))*IF(INDEX(FM_D10,MATCH($A24,FM_Mat,0))="D10",0.1,1) -> 0.595 | M24: =IF(K24<L24,"LOW","OK") -> OK | N24: iterji.com ↗ | O24: =IFERROR(FLOOR((MAX(K24,0)/(INDEX(FM_Active,MATCH($A24,FM_Mat,0))*IF(INDEX(FM_D10,MATCH($A24,FM_Mat,0))="D10",0.1,1)))/(50*YC_Density*YC_ConcPct),1),"") -> 60 | P24: =IF(K24<L24,A24,"") | Q24: =IF(P24="",Q23,IF(Q23="",P24,Q23&", "&P24)) | R24: 21
A25: Ethylene Brassylate | B25: 50 | C25: ml | D25: 1 | E25: 0.9 | F25: =IF(C25="ml",B25*D25*E25,B25*D25) -> 45 | G25: 34.39 | H25: =G25*D25 -> 34.39 | I25: =IF(F25=0,0,H25/F25) -> 0.76422222 | J25: =TotalConcUsedG*INDEX(FM_Active,MATCH($A25,FM_Mat,0))*IF(INDEX(FM_D10,MATCH($A25,FM_Mat,0))="D10",0.1,1) -> 0 | K25: =F25-J25 -> 45 | L25: =2*DefaultBatchConcG*INDEX(FM_Active,MATCH($A25,FM_Mat,0))*IF(INDEX(FM_D10,MATCH($A25,FM_Mat,0))="D10",0.1,1) -> 1.275 | M25: =IF(K25<L25,"LOW","OK") -> OK | N25: iterji.com ↗ | O25: =IFERROR(FLOOR((MAX(K25,0)/(INDEX(FM_Active,MATCH($A25,FM_Mat,0))*IF(INDEX(FM_D10,MATCH($A25,FM_Mat,0))="D10",0.1,1)))/(50*YC_Density*YC_ConcPct),1),"") -> 70 | P25: =IF(K25<L25,A25,"") | Q25: =IF(P25="",Q24,IF(Q24="",P25,Q24&", "&P25)) | R25: 22
A26: Galaxolide | B26: 30 | C26: ml | D26: 1 | E26: 0.9 | F26: =IF(C26="ml",B26*D26*E26,B26*D26) -> 27 | G26: 27 | H26: =G26*D26 -> 27 | I26: =IF(F26=0,0,H26/F26) -> 1 | J26: =TotalConcUsedG*INDEX(FM_Active,MATCH($A26,FM_Mat,0))*IF(INDEX(FM_D10,MATCH($A26,FM_Mat,0))="D10",0.1,1) -> 0 | K26: =F26-J26 -> 27 | L26: =2*DefaultBatchConcG*INDEX(FM_Active,MATCH($A26,FM_Mat,0))*IF(INDEX(FM_D10,MATCH($A26,FM_Mat,0))="D10",0.1,1) -> 0.935 | M26: =IF(K26<L26,"LOW","OK") -> OK | N26: iterji.com ↗ | O26: =IFERROR(FLOOR((MAX(K26,0)/(INDEX(FM_Active,MATCH($A26,FM_Mat,0))*IF(INDEX(FM_D10,MATCH($A26,FM_Mat,0))="D10",0.1,1)))/(50*YC_Density*YC_ConcPct),1),"") -> 57 | P26: =IF(K26<L26,A26,"") | Q26: =IF(P26="",Q25,IF(Q25="",P26,Q25&", "&P26)) | R26: 23
A27: Exaltolide Total (Firmenich) | B27: 10 | C27: ml | D27: 1 | E27: 0.9 | F27: =IF(C27="ml",B27*D27*E27,B27*D27) -> 9 | G27: 27.53 | H27: =G27*D27 -> 27.53 | I27: =IF(F27=0,0,H27/F27) -> 3.0588889 | J27: =TotalConcUsedG*INDEX(FM_Active,MATCH($A27,FM_Mat,0))*IF(INDEX(FM_D10,MATCH($A27,FM_Mat,0))="D10",0.1,1) -> 0 | K27: =F27-J27 -> 9 | L27: =2*DefaultBatchConcG*INDEX(FM_Active,MATCH($A27,FM_Mat,0))*IF(INDEX(FM_D10,MATCH($A27,FM_Mat,0))="D10",0.1,1) -> 0.425 | M27: =IF(K27<L27,"LOW","OK") -> OK | N27: iterji.com ↗ | O27: =IFERROR(FLOOR((MAX(K27,0)/(INDEX(FM_Active,MATCH($A27,FM_Mat,0))*IF(INDEX(FM_D10,MATCH($A27,FM_Mat,0))="D10",0.1,1)))/(50*YC_Density*YC_ConcPct),1),"") -> 42 | P27: =IF(K27<L27,A27,"") | Q27: =IF(P27="",Q26,IF(Q26="",P27,Q26&", "&P27)) | R27: 24
A28: Saffron Accord | B28: 10 | C28: ml | D28: 1 | E28: 0.9 | F28: =IF(C28="ml",B28*D28*E28,B28*D28) -> 9 | G28: 33.75 | H28: =G28*D28 -> 33.75 | I28: =IF(F28=0,0,H28/F28) -> 3.75 | J28: =TotalConcUsedG*INDEX(FM_Active,MATCH($A28,FM_Mat,0))*IF(INDEX(FM_D10,MATCH($A28,FM_Mat,0))="D10",0.1,1) -> 0 | K28: =F28-J28 -> 9 | L28: =2*DefaultBatchConcG*INDEX(FM_Active,MATCH($A28,FM_Mat,0))*IF(INDEX(FM_D10,MATCH($A28,FM_Mat,0))="D10",0.1,1) -> 0.085 | M28: =IF(K28<L28,"LOW","OK") -> OK | N28: iterji.com ↗ | O28: =IFERROR(FLOOR((MAX(K28,0)/(INDEX(FM_Active,MATCH($A28,FM_Mat,0))*IF(INDEX(FM_D10,MATCH($A28,FM_Mat,0))="D10",0.1,1)))/(50*YC_Density*YC_ConcPct),1),"") -> 211 | P28: =IF(K28<L28,A28,"") | Q28: =IF(P28="",Q27,IF(Q27="",P28,Q27&", "&P28)) | R28: 25
A29: DPG (Dipropylene Glycol) | B29: 500 | C29: ml | D29: 1 | E29: 1.02 | F29: =IF(C29="ml",B29*D29*E29,B29*D29) -> 510 | G29: 50 | H29: =G29*D29 -> 50 | I29: =IF(F29=0,0,H29/F29) -> 0.098039216 | J29: =TotalConcUsedG*D10ActivePct*0.9 -> 0 | K29: =F29-J29 -> 510 | L29: =2*DefaultBatchConcG*D10ActivePct*0.9 -> 0.7344 | M29: =IF(K29<L29,"LOW","OK") -> OK | N29: iterji.com ↗ | O29: =IFERROR(FLOOR((MAX(K29,0)/(D10ActivePct*0.9))/(50*YC_Density*YC_ConcPct),1),"") -> 1388 | P29: =IF(K29<L29,A29,"") | Q29: =IF(P29="",Q28,IF(Q28="",P29,Q28&", "&P29)) | R29: 26
A30: Alcohol 190 proof SDA 40B | B30: 5000 | C30: ml | D30: 1 | E30: 0.81 | F30: =IF(C30="ml",B30*D30*E30,B30*D30) -> 4050 | G30: 150 | H30: =G30*D30 -> 150 | I30: =IF(F30=0,0,H30/F30) -> 0.037037037 | J30: =AlcoholUsedG -> 0 | K30: =F30-J30 -> 4050 | L30: =2*DefaultBatchAlcG -> 68 | M30: =IF(K30<L30,"LOW","OK") -> OK | N30: iterji.com ↗ | O30: =IFERROR(FLOOR(MAX(K30,0)/(50*YC_Density*(1-YC_ConcPct)),1),"") -> 119 | P30: =IF(K30<L30,A30,"") | Q30: =IF(P30="",Q29,IF(Q29="",P30,Q29&", "&P30)) | R30: 27
A31: TOTAL PAID (SAR) | H31: =SUM(H4:H30) -> 1692.83

Sheet Inventory Bottles
A1: INVENTORY & BOTTLES
A2: One live view of stock, bottle capacity by size, and which material increases output if you buy more.
A3: Bottle size | B3: 10 | C3: 20 | D3: 30 | E3: 50 | F3: 70 | G3: 100 | H3: Current | I3: Type trial purchase quantities in "Add packs". Projected bottles update immediately. Gold rows are materials where +1 pack can raise the 50 ml output; red rows are the current bottleneck.
B4: =MIN(K7:K33) -> 156 | C4: =MIN(L7:L33) -> 78 | D4: =MIN(M7:M33) -> 52 | E4: =MIN(N7:N33) -> 31 | F4: =MIN(O7:O33) -> 22 | G4: =MIN(P7:P33) -> 15 | H4: Projected
B5: =MIN(Q7:Q33) -> 156 | C5: =MIN(R7:R33) -> 78 | D5: =MIN(S7:S33) -> 52 | E5: =MIN(T7:T33) -> 31 | F5: =MIN(U7:U33) -> 22 | G5: =MIN(V7:V33) -> 15
A6: Material | B6: Pack | C6: Unit | D6: Packs | E6: Add packs | F6: Density | G6: On hand g | H6: Projected g | I6: Active % | J6: Use / g conc | K6: Cur 10 | L6: Cur 20 | M6: Cur 30 | N6: Cur 50 | O6: Cur 70 | P6: Cur 100 | Q6: Proj 10 | R6: Proj 20 | S6: Proj 30 | T6: Proj 50 | U6: Proj 70 | V6: Proj 100 | W6: +50 if +1 pack | X6: Priority | Y6: Product
