Workbook
Name FormatList: Lists!$A$2:$A$7
Name FormatDefaults: Lists!$A$2:$E$7
Name StatusList: Lists!$G$2:$G$4
Name YesNoList: Lists!$H$2:$H$3
Name UnitList: Lists!$I$2:$I$3
Name IncludeOptionals: 'Formula Master'!$C$4
Name OptPctSum: 'Formula Master'!$I$3
Name D10ActivePct: 'Formula Master'!$I$4
Name FM_Mat: 'Formula Master'!$B$7:$B$31
Name FM_InputPct: 'Formula Master'!$C$7:$C$31
Name FM_D10: 'Formula Master'!$D$7:$D$31
Name FM_Active: 'Formula Master'!$F$7:$F$31
Name FM_CostG: 'Formula Master'!$H$7:$H$31
Name BatchFormat: 'Batch Calculator'!$C$4
Name BatchSize: 'Batch Calculator'!$C$5
Name BatchUnit: 'Batch Calculator'!$C$6
Name ConcPct: 'Batch Calculator'!$C$7
Name FinishedDensity: 'Batch Calculator'!$C$8
Name WaterPct: 'Batch Calculator'!$C$12
Name MistGlyPct: 'Batch Calculator'!$C$13
Name MistWaterPct: 'Batch Calculator'!$C$14
Name SolubRatio: 'Batch Calculator'!$C$15
Name WMGlyPct: 'Batch Calculator'!$C$16
Name WMPresPct: 'Batch Calculator'!$C$17
Name VitEPct: 'Batch Calculator'!$C$18
Name CR2GlyPct: 'Batch Calculator'!$G$13
Name CR2EwaxPct: 'Batch Calculator'!$G$14
Name CR2CetPct: 'Batch Calculator'!$G$15
Name CR2OilPct: 'Batch Calculator'!$G$16
Name CR2ButterPct: 'Batch Calculator'!$G$17
Name CR2PresPct: 'Batch Calculator'!$G$18
Name TotalMassG: 'Batch Calculator'!$C$21
Name BatchVolMl: 'Batch Calculator'!$C$22
Name ConcG: 'Batch Calculator'!$C$23
Name BatchCostSAR: 'Batch Calculator'!$C$24
Name CostPerMl: 'Batch Calculator'!$C$25
Name AuxGrams: 'Batch Calculator'!$D$58:$D$68
Name AlcoholG: 'Batch Calculator'!$D$58
Name WaterG: 'Batch Calculator'!$D$59
Name GlycerinG: 'Batch Calculator'!$D$60
Name PolysorbateG: 'Batch Calculator'!$D$61
Name PreservativeG: 'Batch Calculator'!$D$62
Name CreamBaseG: 'Batch Calculator'!$D$63
Name Inv_Mat: Inventory!$A$4:$A$31
Name Inv_GramsBought: Inventory!$F$4:$F$31
Name Inv_TotalPaid: Inventory!$H$4:$H$31
Name Inv_PricePerG: Inventory!$I$4:$I$31
Name Inv_OnHand: Inventory!$K$4:$K$31
Name Inv_Threshold: Inventory!$L$4:$L$31
Name Inv_LowNames: Inventory!$N$4:$N$31
Name Inv_LowJoined: Inventory!$O$31
Name DefaultBatchConcG: Inventory!$H$2
Name DefaultBatchAlcG: Inventory!$K$2
Name MacDays: 'Production Log'!$C$3
Name TotalConcUsedG: 'Production Log'!$F$3
Name AlcoholUsedG: 'Production Log'!$I$3
Name LogID: 'Production Log'!$B$5:$B$44
Name LogConcG: 'Production Log'!$G$5:$G$44
Name LogAlcG: 'Production Log'!$H$5:$H$44
Name LogStart: 'Production Log'!$I$5:$I$44

Sheet Dashboard
B2: A U R A · 3 7
B3: a signature luxury skin scent · Extrait — Mist — Cream · presence that stays
B6: INVESTED (SAR) | C6: STOCK VALUE (SAR) | D6: CONCENTRATE (SAR/g) | E6: BATCHES LOGGED | F6: MACERATING NOW | G6: LOW-STOCK ITEMS
B7: =TotalCapital | C7: =StockValueSAR | D7: =ConcCostPerGLoaded | E7: =SUMPRODUCT((LogID<>"")*1) | F7: =COUNTIF(LogStatus,"Macerating") | G7: =SUMPRODUCT((Inv_OnHand<Inv_Threshold)*1)
B9: CURRENT BATCH — quick launch | E9: MACERATION MILESTONES
B10: Format | C10: =BatchFormat | E10: Next ready window opens | G10: =IF(COUNTIFS(LogStatus,"Macerating",LogStart,"<>")=0,"—",TEXT(MIN(LogMacStart)+28,"yyyy-mm-dd"))
B11: Batch | C11: =BatchSize&" "&BatchUnit | E11: Next maceration complete | G11: =IF(COUNTIFS(LogStatus,"Macerating",LogStart,"<>")=0,"—",TEXT(MIN(LogMacStart)+MacDays,"yyyy-mm-dd"))
B12: Concentrate to weigh (g) | C12: =ConcG | E12: Batches in ready window | G12: =SUMPRODUCT((LogStatus="Macerating")*(LogStart<>"")*((TODAY()-LogStart)>=28))
B13: Alcohol (g) | C13: =AlcoholG | E13: Concentrate used to date (g) | G13: =TotalConcUsedG
B14: Estimated cost (SAR) | C14: =BatchCostSAR | E14: Alcohol used to date (g) | G14: =AlcoholUsedG
B15: Cost per ml (SAR) | C15: =CostPerMl | E15: Maceration target (days) | G15: =MacDays
B17: INVENTORY ALERTS
B18: =IF($G$7=0,"✓ All materials stocked for at least two default batches.","⚠ Low stock — reorder: "&Inv_LowJoined)
B20: WORKFLOW
B21: 1 · Set format, size and concentration in the Batch Calculator — print it and take it to the bench.
B22: 2 · Weigh BASE → HEART → TOP, marry the concentrate 24–48 h, then dilute and start maceration.
B23: 3 · Log the batch in the Production Log — Inventory and the Maceration Tracker update themselves.
B25: ASMR personal production suite · verify against current IFRA standards before any commercial use

Sheet Formula Master
A1: ASMR — MASTER FORMULA
A2: Concentrate = 100% by weight. D10 = weighed as a 10% dilution in DPG — the % shown is the weight of the dilution.
H3: Optionals Σ | I3: =SUMIF($E$7:$E$31,"OPT",$C$7:$C$31)
A4: Include optional materials (Irone Alpha, Javanol): | C4: YES | H4: D10 Σ (active) | I4: =SUMIF($D$7:$D$31,"D10",$F$7:$F$31)
A6: Phase | B6: Material | C6: Input % | D6: D10 | E6: Optional | F6: Active % | G6: Role in the accord | H6: SAR/g (as weighed)
A7: TOP | B7: Bergamot Accord | C7: 0.09 | F7: =IF(IncludeOptionals="YES",C7,IF($E7="OPT",0,C7/(1-OptPctSum))) | G7: sparkling citrus opening — photosafe accord | H7: =IF($D7="D10",0.1*INDEX(Inv_PricePerG,MATCH($B7,Inv_Mat,0))+0.9*DPGPricePerG,INDEX(Inv_PricePerG,MATCH($B7,Inv_Mat,0)))
A8: TOP | B8: Petitgrain Paraguay | C8: 0.015 | F8: =IF(IncludeOptionals="YES",C8,IF($E8="OPT",0,C8/(1-OptPctSum))) | G8: green-bitter citrus leaf | H8: =IF($D8="D10",0.1*INDEX(Inv_PricePerG,MATCH($B8,Inv_Mat,0))+0.9*DPGPricePerG,INDEX(Inv_PricePerG,MATCH($B8,Inv_Mat,0)))
A9: TOP | B9: Neroli Accord | C9: 0.01 | F9: =IF(IncludeOptionals="YES",C9,IF($E9="OPT",0,C9/(1-OptPctSum))) | G9: orange-flower lift | H9: =IF($D9="D10",0.1*INDEX(Inv_PricePerG,MATCH($B9,Inv_Mat,0))+0.9*DPGPricePerG,INDEX(Inv_PricePerG,MATCH($B9,Inv_Mat,0)))
A10: TOP | B10: Pink Peppercorn | C10: 0.005 | D10: D10 | F10: =IF(IncludeOptionals="YES",C10,IF($E10="OPT",0,C10/(1-OptPctSum))) | G10: rosy-spicy glint | H10: =IF($D10="D10",0.1*INDEX(Inv_PricePerG,MATCH($B10,Inv_Mat,0))+0.9*DPGPricePerG,INDEX(Inv_PricePerG,MATCH($B10,Inv_Mat,0)))
A11: TOP | B11: Floralozone | C11: 0.005 | D11: D10 | F11: =IF(IncludeOptionals="YES",C11,IF($E11="OPT",0,C11/(1-OptPctSum))) | G11: clean air, sea-light transparency | H11: =IF($D11="D10",0.1*INDEX(Inv_PricePerG,MATCH($B11,Inv_Mat,0))+0.9*DPGPricePerG,INDEX(Inv_PricePerG,MATCH($B11,Inv_Mat,0)))
A12: HEART | B12: Hedione (Firmenich) | C12: 0.2 | F12: =IF(IncludeOptionals="YES",C12,IF($E12="OPT",0,C12/(1-OptPctSum))) | G12: transparent jasmine — the radiance engine | H12: =IF($D12="D10",0.1*INDEX(Inv_PricePerG,MATCH($B12,Inv_Mat,0))+0.9*DPGPricePerG,INDEX(Inv_PricePerG,MATCH($B12,Inv_Mat,0)))
A13: HEART | B13: Orange Blossom Tunisia Absolute | C13: 0.025 | F13: =IF(IncludeOptionals="YES",C13,IF($E13="OPT",0,C13/(1-OptPctSum))) | G13: true white-flower warmth | H13: =IF($D13="D10",0.1*INDEX(Inv_PricePerG,MATCH($B13,Inv_Mat,0))+0.9*DPGPricePerG,INDEX(Inv_PricePerG,MATCH($B13,Inv_Mat,0)))
A14: HEART | B14: Methyl Alpha Ionone Iso | C14: 0.04 | F14: =IF(IncludeOptionals="YES",C14,IF($E14="OPT",0,C14/(1-OptPctSum))) | G14: powdery orris-violet velvet | H14: =IF($D14="D10",0.1*INDEX(Inv_PricePerG,MATCH($B14,Inv_Mat,0))+0.9*DPGPricePerG,INDEX(Inv_PricePerG,MATCH($B14,Inv_Mat,0)))
A15: HEART | B15: Irone Alpha | C15: 0.01 | D15: D10 | E15: OPT | F15: =IF(IncludeOptionals="YES",C15,IF($E15="OPT",0,C15/(1-OptPctSum))) | G15: precious orris butter — optional luxury | H15: =IF($D15="D10",0.1*INDEX(Inv_PricePerG,MATCH($B15,Inv_Mat,0))+0.9*DPGPricePerG,INDEX(Inv_PricePerG,MATCH($B15,Inv_Mat,0)))
A16: HEART | B16: Benzyl Salicylate | C16: 0.03 | F16: =IF(IncludeOptionals="YES",C16,IF($E16="OPT",0,C16/(1-OptPctSum))) | G16: soft balsamic blender | H16: =IF($D16="D10",0.1*INDEX(Inv_PricePerG,MATCH($B16,Inv_Mat,0))+0.9*DPGPricePerG,INDEX(Inv_PricePerG,MATCH($B16,Inv_Mat,0)))
A17: HEART | B17: Linalool | C17: 0.01 | F17: =IF(IncludeOptionals="YES",C17,IF($E17="OPT",0,C17/(1-OptPctSum))) | G17: fresh floral smoothing | H17: =IF($D17="D10",0.1*INDEX(Inv_PricePerG,MATCH($B17,Inv_Mat,0))+0.9*DPGPricePerG,INDEX(Inv_PricePerG,MATCH($B17,Inv_Mat,0)))
A18: BASE | B18: Iso E Super | C18: 0.15 | F18: =IF(IncludeOptionals="YES",C18,IF($E18="OPT",0,C18/(1-OptPctSum))) | G18: velvet-wood aura, skin-like halo | H18: =IF($D18="D10",0.1*INDEX(Inv_PricePerG,MATCH($B18,Inv_Mat,0))+0.9*DPGPricePerG,INDEX(Inv_PricePerG,MATCH($B18,Inv_Mat,0)))
A19: BASE | B19: Amberxan (Ambroxan) | C19: 0.08 | F19: =IF(IncludeOptionals="YES",C19,IF($E19="OPT",0,C19/(1-OptPctSum))) | G19: mineral amber radiance — the 'still here' trail | H19: =IF($D19="D10",0.1*INDEX(Inv_PricePerG,MATCH($B19,Inv_Mat,0))+0.9*DPGPricePerG,INDEX(Inv_PricePerG,MATCH($B19,Inv_Mat,0)))
A20: BASE | B20: Cashmeran IFF | C20: 0.025 | F20: =IF(IncludeOptionals="YES",C20,IF($E20="OPT",0,C20/(1-OptPctSum))) | G20: cashmere musk-wood | H20: =IF($D20="D10",0.1*INDEX(Inv_PricePerG,MATCH($B20,Inv_Mat,0))+0.9*DPGPricePerG,INDEX(Inv_PricePerG,MATCH($B20,Inv_Mat,0)))
A21: BASE | B21: Sandal Spicatum Australia | C21: 0.04 | F21: =IF(IncludeOptionals="YES",C21,IF($E21="OPT",0,C21/(1-OptPctSum))) | G21: creamy natural sandalwood EO | H21: =IF($D21="D10",0.1*INDEX(Inv_PricePerG,MATCH($B21,Inv_Mat,0))+0.9*DPGPricePerG,INDEX(Inv_PricePerG,MATCH($B21,Inv_Mat,0)))
A22: BASE | B22: Sandalore (Givaudan) | C22: 0.03 | F22: =IF(IncludeOptionals="YES",C22,IF($E22="OPT",0,C22/(1-OptPctSum))) | G22: smooth sandalwood glow | H22: =IF($D22="D10",0.1*INDEX(Inv_PricePerG,MATCH($B22,Inv_Mat,0))+0.9*DPGPricePerG,INDEX(Inv_PricePerG,MATCH($B22,Inv_Mat,0)))
A23: BASE | B23: Javanol | C23: 0.005 | D23: D10 | E23: OPT | F23: =IF(IncludeOptionals="YES",C23,IF($E23="OPT",0,C23/(1-OptPctSum))) | G23: ultra-modern sandalwood — optional | H23: =IF($D23="D10",0.1*INDEX(Inv_PricePerG,MATCH($B23,Inv_Mat,0))+0.9*DPGPricePerG,INDEX(Inv_PricePerG,MATCH($B23,Inv_Mat,0)))
A24: BASE | B24: Globalide (Habanolide) | C24: 0.065 | F24: =IF(IncludeOptionals="YES",C24,IF($E24="OPT",0,C24/(1-OptPctSum))) | G24: clean airy musk | H24: =IF($D24="D10",0.1*INDEX(Inv_PricePerG,MATCH($B24,Inv_Mat,0))+0.9*DPGPricePerG,INDEX(Inv_PricePerG,MATCH($B24,Inv_Mat,0)))
A25: BASE | B25: Helvetolide | C25: 0.05 | F25: =IF(IncludeOptionals="YES",C25,IF($E25="OPT",0,C25/(1-OptPctSum))) | G25: fruity-ambrette musk | H25: =IF($D25="D10",0.1*INDEX(Inv_PricePerG,MATCH($B25,Inv_Mat,0))+0.9*DPGPricePerG,INDEX(Inv_PricePerG,MATCH($B25,Inv_Mat,0)))
A26: BASE | B26: Ambrettolide (Givaudan) | C26: 0.025 | F26: =IF(IncludeOptionals="YES",C26,IF($E26="OPT",0,C26/(1-OptPctSum))) | G26: seamless skin musk | H26: =IF($D26="D10",0.1*INDEX(Inv_PricePerG,MATCH($B26,Inv_Mat,0))+0.9*DPGPricePerG,INDEX(Inv_PricePerG,MATCH($B26,Inv_Mat,0)))
A27: BASE | B27: Ethylene Brassylate | C27: 0.035 | F27: =IF(IncludeOptionals="YES",C27,IF($E27="OPT",0,C27/(1-OptPctSum))) | G27: soft powder musk | H27: =IF($D27="D10",0.1*INDEX(Inv_PricePerG,MATCH($B27,Inv_Mat,0))+0.9*DPGPricePerG,INDEX(Inv_PricePerG,MATCH($B27,Inv_Mat,0)))
A28: BASE | B28: Exaltolide Total (Firmenich) | C28: 0.02 | F28: =IF(IncludeOptionals="YES",C28,IF($E28="OPT",0,C28/(1-OptPctSum))) | G28: warm intimate musk | H28: =IF($D28="D10",0.1*INDEX(Inv_PricePerG,MATCH($B28,Inv_Mat,0))+0.9*DPGPricePerG,INDEX(Inv_PricePerG,MATCH($B28,Inv_Mat,0)))
A29: BASE | B29: Cedarwood Virginia | C29: 0.02 | F29: =IF(IncludeOptionals="YES",C29,IF($E29="OPT",0,C29/(1-OptPctSum))) | G29: dry pencil-cedar backbone | H29: =IF($D29="D10",0.1*INDEX(Inv_PricePerG,MATCH($B29,Inv_Mat,0))+0.9*DPGPricePerG,INDEX(Inv_PricePerG,MATCH($B29,Inv_Mat,0)))
A30: BASE | B30: Vetyveryle Acetate | C30: 0.005 | F30: =IF(IncludeOptionals="YES",C30,IF($E30="OPT",0,C30/(1-OptPctSum))) | G30: polished vetiver whisper | H30: =IF($D30="D10",0.1*INDEX(Inv_PricePerG,MATCH($B30,Inv_Mat,0))+0.9*DPGPricePerG,INDEX(Inv_PricePerG,MATCH($B30,Inv_Mat,0)))
A31: BASE | B31: Safraleine | C31: 0.01 | D31: D10 | F31: =IF(IncludeOptionals="YES",C31,IF($E31="OPT",0,C31/(1-OptPctSum))) | G31: saffron-leather warmth | H31: =IF($D31="D10",0.1*INDEX(Inv_PricePerG,MATCH($B31,Inv_Mat,0))+0.9*DPGPricePerG,INDEX(Inv_PricePerG,MATCH($B31,Inv_Mat,0)))
B33: TOTALS | C33: =SUM(C7:C31) | F33: =SUM(F7:F31)
A34: =IF(AND(ROUND(C33,6)=1,ROUND(F33,6)=1),"✓ BALANCED — input Σ = "&TEXT(C33,"0.00%")&" · active Σ = "&TEXT(F33,"0.00%"),"⚠ FORMULA DOES NOT SUM TO 100% — check the Input % column")
A36: Legend: | B36: OPTIONAL / extra | C36: hover the cell comment for its expected effect
B37: OVERLAPS another | C37: shares a smell with a partner material — intentional layering, first to simplify
A38: Every other ingredient is essential to the accord. There are NO wasted materials here — each phase (top / heart / base) needs its members to smell complete.

Sheet Batch Calculator
A1: ASMR — BATCH CALCULATOR
A2: All quantities in grams. Weighing order: BASE → HEART → TOP. Champagne cells are inputs.
A3: 1 · BATCH INPUTS
A4: Product format | C4: Extrait de Parfum | D4: choose one of the six product formats
A5: Batch size | C5: 50 | D5: in the unit chosen below
A6: Size unit (ml / g) | C6: ml | D6: ml is converted to grams with the density cell below
A7: Concentrate % | C7: 0.28 | D7: ="Suggested for this format: "&TEXT(VLOOKUP(BatchFormat,FormatDefaults,2,FALSE),"0.0%")&" (range "&TEXT(VLOOKUP(BatchFormat,FormatDefaults,3,FALSE),"0.0%")&" – "&TEXT(VLOOKUP(BatchFormat,FormatDefaults,4,FALSE),"0.0%")&")"
A8: Finished density (g/ml) | C8: 0.85 | D8: ="Typical for this format: "&TEXT(VLOOKUP(BatchFormat,FormatDefaults,5,FALSE),"0.00")&" g/ml"
A9: Optionals included? | C9: =IncludeOptionals | D9: optionals: Irone Alpha, Javanol — set on Formula Master
A11: 2 · FORMAT PARAMETERS (each is used only by the format named)
A12: Distilled water % (EDP) | C12: 0 | D12: EDP / Extrait — optional, max 3% | E12: CREAM ROUTE 2 — PHASE %
A13: Glycerin % (alc. mist) | C13: 0.02 | D13: Alcohol Body Mist — optional 2–3% | E13: Glycerin (water phase) | G13: 0.03
A14: Water % (alc. mist) | C14: 0.05 | D14: Alcohol Body Mist — optional 5–10% | E14: Emulsifying Wax NF | G14: 0.05
A15: Solubilizer × fragrance | C15: 4 | D15: Water Mist — Polysorbate 20 = 4–6 × fragrance wt | E15: Cetearyl alcohol | G15: 0.02
A16: Glycerin % (W-mist) | C16: 0.025 | D16: Water-Based Mist | E16: Carrier oil (light) | G16: 0.15
A17: Preservative % (W-mist) | C17: 0.008 | D17: Water-Based Mist — broad-spectrum, REQUIRED | E17: Shea / mango butter | G17: 0.05
A18: Vitamin E % (cream 2) | C18: 0.005 | D18: Cream Route 2 — cool-down antioxidant | E18: Preservative | G18: 0.01
A20: 3 · BATCH TOTALS
A21: Total batch mass (g) | C21: =IF(BatchUnit="g",BatchSize,BatchSize*FinishedDensity) | D21: batch size converted to grams
A22: Batch volume (ml, approx.) | C22: =IF(BatchUnit="ml",BatchSize,BatchSize/FinishedDensity) | D22: for cost-per-ml
A23: Fragrance concentrate (g) | C23: =TotalMassG*ConcPct | D23: total to weigh from the table below
A24: Estimated batch cost (SAR) | C24: =ConcG*ConcCostPerGLoaded+SUMPRODUCT(AuxGrams,AuxCostPerG) | D24: materials incl. shipping allocation — see Cost Analysis
A25: Cost per ml (SAR) | C25: =IF(BatchVolMl=0,"",BatchCostSAR/BatchVolMl)
A27: 4 · CONCENTRATE WEIGHING (weigh in this order: BASE → HEART → TOP)
A28: Phase | B28: Material | D28: % of conc. | E28: Weigh (g) | F28: Form | G28: Neat (g) | H28: ✓
A29: BASE | B29: Iso E Super | D29: =INDEX(FM_Active,MATCH($B29,FM_Mat,0)) | E29: =ConcG*D29 | F29: =IF(INDEX(FM_D10,MATCH($B29,FM_Mat,0))="D10","10% in DPG","neat") | G29: =E29*IF(INDEX(FM_D10,MATCH($B29,FM_Mat,0))="D10",0.1,1)
A30: BASE | B30: Amberxan (Ambroxan) | D30: =INDEX(FM_Active,MATCH($B30,FM_Mat,0)) | E30: =ConcG*D30 | F30: =IF(INDEX(FM_D10,MATCH($B30,FM_Mat,0))="D10","10% in DPG","neat") | G30: =E30*IF(INDEX(FM_D10,MATCH($B30,FM_Mat,0))="D10",0.1,1)
A31: BASE | B31: Cashmeran IFF | D31: =INDEX(FM_Active,MATCH($B31,FM_Mat,0)) | E31: =ConcG*D31 | F31: =IF(INDEX(FM_D10,MATCH($B31,FM_Mat,0))="D10","10% in DPG","neat") | G31: =E31*IF(INDEX(FM_D10,MATCH($B31,FM_Mat,0))="D10",0.1,1)
A32: BASE | B32: Sandal Spicatum Australia | D32: =INDEX(FM_Active,MATCH($B32,FM_Mat,0)) | E32: =ConcG*D32 | F32: =IF(INDEX(FM_D10,MATCH($B32,FM_Mat,0))="D10","10% in DPG","neat") | G32: =E32*IF(INDEX(FM_D10,MATCH($B32,FM_Mat,0))="D10",0.1,1)
A33: BASE | B33: Sandalore (Givaudan) | D33: =INDEX(FM_Active,MATCH($B33,FM_Mat,0)) | E33: =ConcG*D33 | F33: =IF(INDEX(FM_D10,MATCH($B33,FM_Mat,0))="D10","10% in DPG","neat") | G33: =E33*IF(INDEX(FM_D10,MATCH($B33,FM_Mat,0))="D10",0.1,1)
A34: BASE | B34: Javanol | D34: =INDEX(FM_Active,MATCH($B34,FM_Mat,0)) | E34: =ConcG*D34 | F34: =IF(INDEX(FM_D10,MATCH($B34,FM_Mat,0))="D10","10% in DPG","neat") | G34: =E34*IF(INDEX(FM_D10,MATCH($B34,FM_Mat,0))="D10",0.1,1)
A35: BASE | B35: Globalide (Habanolide) | D35: =INDEX(FM_Active,MATCH($B35,FM_Mat,0)) | E35: =ConcG*D35 | F35: =IF(INDEX(FM_D10,MATCH($B35,FM_Mat,0))="D10","10% in DPG","neat") | G35: =E35*IF(INDEX(FM_D10,MATCH($B35,FM_Mat,0))="D10",0.1,1)
A36: BASE | B36: Helvetolide | D36: =INDEX(FM_Active,MATCH($B36,FM_Mat,0)) | E36: =ConcG*D36 | F36: =IF(INDEX(FM_D10,MATCH($B36,FM_Mat,0))="D10","10% in DPG","neat") | G36: =E36*IF(INDEX(FM_D10,MATCH($B36,FM_Mat,0))="D10",0.1,1)
A37: BASE | B37: Ambrettolide (Givaudan) | D37: =INDEX(FM_Active,MATCH($B37,FM_Mat,0)) | E37: =ConcG*D37 | F37: =IF(INDEX(FM_D10,MATCH($B37,FM_Mat,0))="D10","10% in DPG","neat") | G37: =E37*IF(INDEX(FM_D10,MATCH($B37,FM_Mat,0))="D10",0.1,1)
A38: BASE | B38: Ethylene Brassylate | D38: =INDEX(FM_Active,MATCH($B38,FM_Mat,0)) | E38: =ConcG*D38 | F38: =IF(INDEX(FM_D10,MATCH($B38,FM_Mat,0))="D10","10% in DPG","neat") | G38: =E38*IF(INDEX(FM_D10,MATCH($B38,FM_Mat,0))="D10",0.1,1)
A39: BASE | B39: Exaltolide Total (Firmenich) | D39: =INDEX(FM_Active,MATCH($B39,FM_Mat,0)) | E39: =ConcG*D39 | F39: =IF(INDEX(FM_D10,MATCH($B39,FM_Mat,0))="D10","10% in DPG","neat") | G39: =E39*IF(INDEX(FM_D10,MATCH($B39,FM_Mat,0))="D10",0.1,1)
A40: BASE | B40: Cedarwood Virginia | D40: =INDEX(FM_Active,MATCH($B40,FM_Mat,0)) | E40: =ConcG*D40 | F40: =IF(INDEX(FM_D10,MATCH($B40,FM_Mat,0))="D10","10% in DPG","neat") | G40: =E40*IF(INDEX(FM_D10,MATCH($B40,FM_Mat,0))="D10",0.1,1)
... A53: TOP | B53: Floralozone | D53: =INDEX(FM_Active,MATCH($B53,FM_Mat,0)) | E53: =ConcG*D53 | F53: =IF(INDEX(FM_D10,MATCH($B53,FM_Mat,0))="D10","10% in DPG","neat") | G53: =E53*IF(INDEX(FM_D10,MATCH($B53,FM_Mat,0))="D10",0.1,1)
A54: CONCENTRATE TOTAL (must equal the concentrate above) | E54: =SUM(E29:E53) | F54: =IF(ABS(E54-ConcG)<0.005,"✓","⚠") | G54: =SUM(G29:G53)
A56: 5 · SOLVENT & AUXILIARY COMPONENTS
...

Sheet Dilution Prep (D10)
A1: D10 DILUTIONS — 10% IN DPG
A2: Default batch: 10 g of solution = 1.0 g neat material + 9.0 g DPG. Prepare at least 24 h before blending.
A4: Material | B4: Strength | C4: Batch (g) | D4: Neat (g) | E4: DPG (g) | F4: Date made | G4: Remaining (g) | H4: Label / notes
A5: Pink Peppercorn | B5: 0.1 | C5: 10 | D5: =C5*B5 | E5: =C5-D5 | H5: ="ASMR · "&A5&" · 10% in DPG · "&IF(F5="","(date)",TEXT(F5,"yyyy-mm-dd"))
A6: Floralozone | B6: 0.1 | C6: 10 | D6: =C6*B6 | E6: =C6-D6 | H6: ="ASMR · "&A6&" · 10% in DPG · "&IF(F6="","(date)",TEXT(F6,"yyyy-mm-dd"))
A7: Irone Alpha | B7: 0.1 | C7: 10 | D7: =C7*B7 | E7: =C7-D7 | H7: ="ASMR · "&A7&" · 10% in DPG · "&IF(F7="","(date)",TEXT(F7,"yyyy-mm-dd"))
A8: Javanol | B8: 0.1 | C8: 10 | D8: =C8*B8 | E8: =C8-D8 | H8: ="ASMR · "&A8&" · 10% in DPG · "&IF(F8="","(date)",TEXT(F8,"yyyy-mm-dd"))
A9: Safraleine | B9: 0.1 | C9: 10 | D9: =C9*B9 | E9: =C9-D9 | H9: ="ASMR · "&A9&" · 10% in DPG · "&IF(F9="","(date)",TEXT(F9,"yyyy-mm-dd"))
A11: 1 · Tare a clean 12–15 ml glass bottle on the scale (0.01 g resolution or better).
A12: 2 · Weigh the NEAT material first, then add DPG up to the total. Cap tightly and shake 1 minute.
A13: 3 · Label with the text in the last column. Store dark and cool. Dilutions keep 12+ months.
A14: 4 · When a dilution runs low, make a fresh 10 g batch and update 'Date made' and 'Remaining'.

Sheet Inventory
A1: INVENTORY
A2: On hand = purchases − usage from the Production Log. | F2: Conc / batch (g): | H2: =50*0.85*0.28 | I2: Alcohol / batch (g): | K2: =50*0.85*0.72
A3: Material | B3: Pack | C3: Unit | D3: Packs | E3: Density g/ml | F3: Grams bought | G3: Price/pack SAR | H3: Paid SAR | I3: SAR/g | J3: Used (g) | K3: On hand (g) | L3: Alert < (g) | M3: Status
A4: Hedione (Firmenich) | B4: 30 | C4: ml | D4: 1 | E4: 0.9 | F4: =IF(C4="ml",B4*D4*E4,B4*D4) | G4: 23.9 | H4: =G4*D4 | I4: =IF(F4=0,0,H4/F4) | J4: =TotalConcUsedG*INDEX(FM_Active,MATCH($A4,FM_Mat,0))*IF(INDEX(FM_D10,MATCH($A4,FM_Mat,0))="D10",0.1,1) | K4: =F4-J4 | L4: =2*DefaultBatchConcG*INDEX(FM_Active,MATCH($A4,FM_Mat,0))*IF(INDEX(FM_D10,MATCH($A4,FM_Mat,0))="D10",0.1,1) | M4: =IF(K4<L4,"LOW","OK") | N4: =IF(K4<L4,A4,"") | O4: =N4
A5: Iso E Super | B5: 10 | C5: ml | D5: 1 | E5: 0.9 | F5: =IF(C5="ml",B5*D5*E5,B5*D5) | G5: 13.6 | H5: =G5*D5 | I5: =IF(F5=0,0,H5/F5) | J5: =TotalConcUsedG*INDEX(FM_Active,MATCH($A5,FM_Mat,0))*IF(INDEX(FM_D10,MATCH($A5,FM_Mat,0))="D10",0.1,1) | K5: =F5-J5 | L5: =2*DefaultBatchConcG*INDEX(FM_Active,MATCH($A5,FM_Mat,0))*IF(INDEX(FM_D10,MATCH($A5,FM_Mat,0))="D10",0.1,1) | M5: =IF(K5<L5,"LOW","OK") | N5: =IF(K5<L5,A5,"") | O5: =IF(N5="",O4,IF(O4="",N5,O4&", "&N5))
A6: Amberxan (Ambroxan) | B6: 10 | C6: g | D6: 1 | F6: =IF(C6="ml",B6*D6*E6,B6*D6) | G6: 81 | H6: =G6*D6 | I6: =IF(F6=0,0,H6/F6) | J6: =TotalConcUsedG*INDEX(FM_Active,MATCH($A6,FM_Mat,0))*IF(INDEX(FM_D10,MATCH($A6,FM_Mat,0))="D10",0.1,1) | K6: =F6-J6 | L6: =2*DefaultBatchConcG*INDEX(FM_Active,MATCH($A6,FM_Mat,0))*IF(INDEX(FM_D10,MATCH($A6,FM_Mat,0))="D10",0.1,1) | M6: =IF(K6<L6,"LOW","OK") | N6: =IF(K6<L6,A6,"") | O6: =IF(N6="",O5,IF(O5="",N6,O5&", "&N6))
A7: Globalide (Habanolide) | B7: 10 | C7: g | D7: 1 | F7: =IF(C7="ml",B7*D7*E7,B7*D7) | G7: 30 | H7: =G7*D7 | I7: =IF(F7=0,0,H7/F7) | J7: =TotalConcUsedG*INDEX(FM_Active,MATCH($A7,FM_Mat,0))*IF(INDEX(FM_D10,MATCH($A7,FM_Mat,0))="D10",0.1,1) | K7: =F7-J7 | L7: =2*DefaultBatchConcG*INDEX(FM_Active,MATCH($A7,FM_Mat,0))*IF(INDEX(FM_D10,MATCH($A7,FM_Mat,0))="D10",0.1,1) | M7: =IF(K7<L7,"LOW","OK") | N7: =IF(K7<L7,A7,"") | O7: =IF(N7="",O6,IF(O6="",N7,O6&", "&N7))
A8: Helvetolide | B8: 10 | C8: g | D8: 1 | F8: =IF(C8="ml",B8*D8*E8,B8*D8) | G8: 55 | H8: =G8*D8 | I8: =IF(F8=0,0,H8/F8) | J8: =TotalConcUsedG*INDEX(FM_Active,MATCH($A8,FM_Mat,0))*IF(INDEX(FM_D10,MATCH($A8,FM_Mat,0))="D10",0.1,1) | K8: =F8-J8 | L8: =2*DefaultBatchConcG*INDEX(FM_Active,MATCH($A8,FM_Mat,0))*IF(INDEX(FM_D10,MATCH($A8,FM_Mat,0))="D10",0.1,1) | M8: =IF(K8<L8,"LOW","OK") | N8: =IF(K8<L8,A8,"") | O8: =IF(N8="",O7,IF(O7="",N8,O7&", "&N8))
A9: Ambrettolide (Givaudan) | B9: 10 | C9: ml | D9: 1 | E9: 0.9 | F9: =IF(C9="ml",B9*D9*E9,B9*D9) | G9: 92.07 | H9: =G9*D9 | I9: =IF(F9=0,0,H9/F9) | J9: =TotalConcUsedG*INDEX(FM_Active,MATCH($A9,FM_Mat,0))*IF(INDEX(FM_D10,MATCH($A9,FM_Mat,0))="D10",0.1,1) | K9: =F9-J9 | L9: =2*DefaultBatchConcG*INDEX(FM_Active,MATCH($A9,FM_Mat,0))*IF(INDEX(FM_D10,MATCH($A9,FM_Mat,0))="D10",0.1,1) | M9: =IF(K9<L9,"LOW","OK") | N9: =IF(K9<L9,A9,"") | O9: =IF(N9="",O8,IF(O8="",N9,O8&", "&N9))
A10: Ethylene Brassylate | B10: 10 | C10: ml | D10: 1 | E10: 0.9 | F10: =IF(C10="ml",B10*D10*E10,B10*D10) | G10: 10.11 | H10: =G10*D10 | I10: =IF(F10=0,0,H10/F10) | J10: =TotalConcUsedG*INDEX(FM_Active,MATCH($A10,FM_Mat,0))*IF(INDEX(FM_D10,MATCH($A10,FM_Mat,0))="D10",0.1,1) | K10: =F10-J10 | L10: =2*DefaultBatchConcG*INDEX(FM_Active,MATCH($A10,FM_Mat,0))*IF(INDEX(FM_D10,MATCH($A10,FM_Mat,0))="D10",0.1,1) | M10: =IF(K10<L10,"LOW","OK") | N10: =IF(K10<L10,A10,"") | O10: =IF(N10="",O9,IF(O9="",N10,O9&", "&N10))
A11: Exaltolide Total (Firmenich) | B11: 10 | C11: ml | D11: 1 | E11: 0.9 | F11: =IF(C11="ml",B11*D11*E11,B11*D11) | G11: 27.53 | H11: =G11*D11 | I11: =IF(F11=0,0,H11/F11) | J11: =TotalConcUsedG*INDEX(FM_Active,MATCH($A11,FM_Mat,0))*IF(INDEX(FM_D10,MATCH($A11,FM_Mat,0))="D10",0.1,1) | K11: =F11-J11 | L11: =2*DefaultBatchConcG*INDEX(FM_Active,MATCH($A11,FM_Mat,0))*IF(INDEX(FM_D10,MATCH($A11,FM_Mat,0))="D10",0.1,1) | M11: =IF(K11<L11,"LOW","OK") | N11: =IF(K11<L11,A11,"") | O11: =IF(N11="",O10,IF(O10="",N11,O10&", "&N11))
A12: Cashmeran IFF | B12: 10 | C12: ml | D12: 1 | E12: 0.9 | F12: =IF(C12="ml",B12*D12*E12,B12*D12) | G12: 55.86 | H12: =G12*D12 | I12: =IF(F12=0,0,H12/F12) | J12: =TotalConcUsedG*INDEX(FM_Active,MATCH($A12,FM_Mat,0))*IF(INDEX(FM_D10,MATCH($A12,FM_Mat,0))="D10",0.1,1) | K12: =F12-J12 | L12: =2*DefaultBatchConcG*INDEX(FM_Active,MATCH($A12,FM_Mat,0))*IF(INDEX(FM_D10,MATCH($A12,FM_Mat,0))="D10",0.1,1) | M12: =IF(K12<L12,"LOW","OK") | N12: =IF(K12<L12,A12,"") | O12: =IF(N12="",O11,IF(O11="",N12,O11&", "&N12))
A13: Sandal Spicatum Australia | B13: 10 | C13: g | D13: 1 | F13: =IF(C13="ml",B13*D13*E13,B13*D13) | G13: 179 | H13: =G13*D13 | I13: =IF(F13=0,0,H13/F13) | J13: =TotalConcUsedG*INDEX(FM_Active,MATCH($A13,FM_Mat,0))*IF(INDEX(FM_D10,MATCH($A13,FM_Mat,0))="D10",0.1,1) | K13: =F13-J13 | L13: =2*DefaultBatchConcG*INDEX(FM_Active,MATCH($A13,FM_Mat,0))*IF(INDEX(FM_D10,MATCH($A13,FM_Mat,0))="D10",0.1,1) | M13: =IF(K13<L13,"LOW","OK") | N13: =IF(K13<L13,A13,"") | O13: =IF(N13="",O12,IF(O12="",N13,O12&", "&N13))
A14: Sandalore (Givaudan) | B14: 10 | C14: ml | D14: 1 | E14: 0.9 | F14: =IF(C14="ml",B14*D14*E14,B14*D14) | G14: 23.54 | H14: =G14*D14 | I14: =IF(F14=0,0,H14/F14) | J14: =TotalConcUsedG*INDEX(FM_Active,MATCH($A14,FM_Mat,0))*IF(INDEX(FM_D10,MATCH($A14,FM_Mat,0))="D10",0.1,1) | K14: =F14-J14 | L14: =2*DefaultBatchConcG*INDEX(FM_Active,MATCH($A14,FM_Mat,0))*IF(INDEX(FM_D10,MATCH($A14,FM_Mat,0))="D10",0.1,1) | M14: =IF(K14<L14,"LOW","OK") | N14: =IF(K14<L14,A14,"") | O14: =IF(N14="",O13,IF(O13="",N14,O13&", "&N14))
A15: Javanol | B15: 10 | C15: g | D15: 1 | F15: =IF(C15="ml",B15*D15*E15,B15*D15) | G15: 81 | H15: =G15*D15 | I15: =IF(F15=0,0,H15/F15) | J15: =TotalConcUsedG*INDEX(FM_Active,MATCH($A15,FM_Mat,0))*IF(INDEX(FM_D10,MATCH($A15,FM_Mat,0))="D10",0.1,1) | K15: =F15-J15 | L15: =2*DefaultBatchConcG*INDEX(FM_Active,MATCH($A15,FM_Mat,0))*IF(INDEX(FM_D10,MATCH($A15,FM_Mat,0))="D10",0.1,1) | M15: =IF(K15<L15,"LOW","OK") | N15: =IF(K15<L15,A15,"") | O15: =IF(N15="",O14,IF(O14="",N15,O14&", "&N15))
A16: Cedarwood Virginia | B16: 10 | C16: g | D16: 1 | F16: =IF(C16="ml",B16*D16*E16,B16*D16) | G16: 31 | H16: =G16*D16 | I16: =IF(F16=0,0,H16/F16) | J16: =TotalConcUsedG*INDEX(FM_Active,MATCH($A16,FM_Mat,0))*IF(INDEX(FM_D10,MATCH($A16,FM_Mat,0))="D10",0.1,1) | K16: =F16-J16 | L16: =2*DefaultBatchConcG*INDEX(FM_Active,MATCH($A16,FM_Mat,0))*IF(INDEX(FM_D10,MATCH($A16,FM_Mat,0))="D10",0.1,1) | M16: =IF(K16<L16,"LOW","OK") | N16: =IF(K16<L16,A16,"") | O16: =IF(N16="",O15,IF(O15="",N16,O15&", "&N16))
A17: Vetyveryle Acetate | B17: 10 | C17: g | D17: 1 | F17: =IF(C17="ml",B17*D17*E17,B17*D17) | G17: 124 | H17: =G17*D17 | I17: =IF(F17=0,0,H17/F17) | J17: =TotalConcUsedG*INDEX(FM_Active,MATCH($A17,FM_Mat,0))*IF(INDEX(FM_D10,MATCH($A17,FM_Mat,0))="D10",0.1,1) | K17: =F17-J17 | L17: =2*DefaultBatchConcG*INDEX(FM_Active,MATCH($A17,FM_Mat,0))*IF(INDEX(FM_D10,MATCH($A17,FM_Mat,0))="D10",0.1,1) | M17: =IF(K17<L17,"LOW","OK") | N17: =IF(K17<L17,A17,"") | O17: =IF(N17="",O16,IF(O16="",N17,O16&", "&N17))
A18: Methyl Alpha Ionone Iso | B18: 10 | C18: ml | D18: 1 | E18: 0.9 | F18: =IF(C18="ml",B18*D18*E18,B18*D18) | G18: 17.46 | H18: =G18*D18 | I18: =IF(F18=0,0,H18/F18) | J18: =TotalConcUsedG*INDEX(FM_Active,MATCH($A18,FM_Mat,0))*IF(INDEX(FM_D10,MATCH($A18,FM_Mat,0))="D10",0.1,1) | K18: =F18-J18 | L18: =2*DefaultBatchConcG*INDEX(FM_Active,MATCH($A18,FM_Mat,0))*IF(INDEX(FM_D10,MATCH($A18,FM_Mat,0))="D10",0.1,1) | M18: =IF(K18<L18,"LOW","OK") | N18: =IF(K18<L18,A18,"") | O18: =IF(N18="",O17,IF(O17="",N18,O17&", "&N18))
A19: Irone Alpha | B19: 10 | C19: g | D19: 1 | F19: =IF(C19="ml",B19*D19*E19,B19*D19) | G19: 216 | H19: =G19*D19 | I19: =IF(F19=0,0,H19/F19) | J19: =TotalConcUsedG*INDEX(FM_Active,MATCH($A19,FM_Mat,0))*IF(INDEX(FM_D10,MATCH($A19,FM_Mat,0))="D10",0.1,1) | K19: =F19-J19 | L19: =2*DefaultBatchConcG*INDEX(FM_Active,MATCH($A19,FM_Mat,0))*IF(INDEX(FM_D10,MATCH($A19,FM_Mat,0))="D10",0.1,1) | M19: =IF(K19<L19,"LOW","OK") | N19: =IF(K19<L19,A19,"") | O19: =IF(N19="",O18,IF(O18="",N19,O18&", "&N19))
A20: Benzyl Salicylate | B20: 10 | C20: ml | D20: 1 | E20: 0.9 | F20: =IF(C20="ml",B20*D20*E20,B20*D20) | G20: 11.16 | H20: =G20*D20 | I20: =IF(F20=0,0,H20/F20) | J20: =TotalConcUsedG*INDEX(FM_Active,MATCH($A20,FM_Mat,0))*IF(INDEX(FM_D10,MATCH($A20,FM_Mat,0))="D10",0.1,1) | K20: =F20-J20 | L20: =2*DefaultBatchConcG*INDEX(FM_Active,MATCH($A20,FM_Mat,0))*IF(INDEX(FM_D10,MATCH($A20,FM_Mat,0))="D10",0.1,1) | M20: =IF(K20<L20,"LOW","OK") | N20: =IF(K20<L20,A20,"") | O20: =IF(N20="",O19,IF(O19="",N20,O19&", "&N20))
A21: Linalool | B21: 10 | C21: ml | D21: 1 | E21: 0.9 | F21: =IF(C21="ml",B21*D21*E21,B21*D21) | G21: 16.74 | H21: =G21*D21 | I21: =IF(F21=0,0,H21/F21) | J21: =TotalConcUsedG*INDEX(FM_Active,MATCH($A21,FM_Mat,0))*IF(INDEX(FM_D10,MATCH($A21,FM_Mat,0))="D10",0.1,1) | K21: =F21-J21 | L21: =2*DefaultBatchConcG*INDEX(FM_Active,MATCH($A21,FM_Mat,0))*IF(INDEX(FM_D10,MATCH($A21,FM_Mat,0))="D10",0.1,1) | M21: =IF(K21<L21,"LOW","OK") | N21: =IF(K21<L21,A21,"") | O21: =IF(N21="",O20,IF(O20="",N21,O20&", "&N21))
A22: Neroli Accord | B22: 10 | C22: ml | D22: 1 | E22: 0.9 | F22: =IF(C22="ml",B22*D22*E22,B22*D22) | G22: 54.38 | H22: =G22*D22 | I22: =IF(F22=0,0,H22/F22) | J22: =TotalConcUsedG*INDEX(FM_Active,MATCH($A22,FM_Mat,0))*IF(INDEX(FM_D10,MATCH($A22,FM_Mat,0))="D10",0.1,1) | K22: =F22-J22 | L22: =2*DefaultBatchConcG*INDEX(FM_Active,MATCH($A22,FM_Mat,0))*IF(INDEX(FM_D10,MATCH($A22,FM_Mat,0))="D10",0.1,1) | M22: =IF(K22<L22,"LOW","OK") | N22: =IF(K22<L22,A22,"") | O22: =IF(N22="",O21,IF(O21="",N22,O21&", "&N22))
A23: Orange Blossom Tunisia Absolute | B23: 10 | C23: g | D23: 1 | F23: =IF(C23="ml",B23*D23*E23,B23*D23) | G23: 435 | H23: =G23*D23 | I23: =IF(F23=0,0,H23/F23) | J23: =TotalConcUsedG*INDEX(FM_Active,MATCH($A23,FM_Mat,0))*IF(INDEX(FM_D10,MATCH($A23,FM_Mat,0))="D10",0.1,1) | K23: =F23-J23 | L23: =2*DefaultBatchConcG*INDEX(FM_Active,MATCH($A23,FM_Mat,0))*IF(INDEX(FM_D10,MATCH($A23,FM_Mat,0))="D10",0.1,1) | M23: =IF(K23<L23,"LOW","OK") | N23: =IF(K23<L23,A23,"") | O23: =IF(N23="",O22,IF(O22="",N23,O22&", "&N23))
A24: Petitgrain Paraguay | B24: 10 | C24: ml | D24: 1 | E24: 0.9 | F24: =IF(C24="ml",B24*D24*E24,B24*D24) | G24: 43.75 | H24: =G24*D24 | I24: =IF(F24=0,0,H24/F24) | J24: =TotalConcUsedG*INDEX(FM_Active,MATCH($A24,FM_Mat,0))*IF(INDEX(FM_D10,MATCH($A24,FM_Mat,0))="D10",0.1,1) | K24: =F24-J24 | L24: =2*DefaultBatchConcG*INDEX(FM_Active,MATCH($A24,FM_Mat,0))*IF(INDEX(FM_D10,MATCH($A24,FM_Mat,0))="D10",0.1,1) | M24: =IF(K24<L24,"LOW","OK") | N24: =IF(K24<L24,A24,"") | O24: =IF(N24="",O23,IF(O23="",N24,O23&", "&N24))
A25: Pink Peppercorn | B25: 10 | C25: ml | D25: 1 | E25: 0.9 | F25: =IF(C25="ml",B25*D25*E25,B25*D25) | G25: 141.25 | H25: =G25*D25 | I25: =IF(F25=0,0,H25/F25) | J25: =TotalConcUsedG*INDEX(FM_Active,MATCH($A25,FM_Mat,0))*IF(INDEX(FM_D10,MATCH($A25,FM_Mat,0))="D10",0.1,1) | K25: =F25-J25 | L25: =2*DefaultBatchConcG*INDEX(FM_Active,MATCH($A25,FM_Mat,0))*IF(INDEX(FM_D10,MATCH($A25,FM_Mat,0))="D10",0.1,1) | M25: =IF(K25<L25,"LOW","OK") | N25: =IF(K25<L25,A25,"") | O25: =IF(N25="",O24,IF(O24="",N25,O24&", "&N25))
A26: Bergamot Accord | B26: 10 | C26: ml | D26: 1 | E26: 0.9 | F26: =IF(C26="ml",B26*D26*E26,B26*D26) | G26: 18.75 | H26: =G26*D26 | I26: =IF(F26=0,0,H26/F26) | J26: =TotalConcUsedG*INDEX(FM_Active,MATCH($A26,FM_Mat,0))*IF(INDEX(FM_D10,MATCH($A26,FM_Mat,0))="D10",0.1,1) | K26: =F26-J26 | L26: =2*DefaultBatchConcG*INDEX(FM_Active,MATCH($A26,FM_Mat,0))*IF(INDEX(FM_D10,MATCH($A26,FM_Mat,0))="D10",0.1,1) | M26: =IF(K26<L26,"LOW","OK") | N26: =IF(K26<L26,A26,"") | O26: =IF(N26="",O25,IF(O25="",N26,O25&", "&N26))
A27: Bergamot Essential Oil | B27: 10 | C27: ml | D27: 1 | E27: 0.9 | F27: =IF(C27="ml",B27*D27*E27,B27*D27) | G27: 25 | H27: =G27*D27 | I27: =IF(F27=0,0,H27/F27) | J27: 0 | K27: =F27-J27 | L27: 0 | M27: =IF(K27<L27,"LOW","OK") | N27: =IF(K27<L27,A27,"") | O27: =IF(N27="",O26,IF(O26="",N27,O26&", "&N27))
A28: Floralozone | B28: 10 | C28: g | D28: 1 | F28: =IF(C28="ml",B28*D28*E28,B28*D28) | G28: 28 | H28: =G28*D28 | I28: =IF(F28=0,0,H28/F28) | J28: =TotalConcUsedG*INDEX(FM_Active,MATCH($A28,FM_Mat,0))*IF(INDEX(FM_D10,MATCH($A28,FM_Mat,0))="D10",0.1,1) | K28: =F28-J28 | L28: =2*DefaultBatchConcG*INDEX(FM_Active,MATCH($A28,FM_Mat,0))*IF(INDEX(FM_D10,MATCH($A28,FM_Mat,0))="D10",0.1,1) | M28: =IF(K28<L28,"LOW","OK") | N28: =IF(K28<L28,A28,"") | O28: =IF(N28="",O27,IF(O27="",N28,O27&", "&N28))
A29: Safraleine | B29: 10 | C29: g | D29: 1 | F29: =IF(C29="ml",B29*D29*E29,B29*D29) | G29: 81 | H29: =G29*D29 | I29: =IF(F29=0,0,H29/F29) | J29: =TotalConcUsedG*INDEX(FM_Active,MATCH($A29,FM_Mat,0))*IF(INDEX(FM_D10,MATCH($A29,FM_Mat,0))="D10",0.1,1) | K29: =F29-J29 | L29: =2*DefaultBatchConcG*INDEX(FM_Active,MATCH($A29,FM_Mat,0))*IF(INDEX(FM_D10,MATCH($A29,FM_Mat,0))="D10",0.1,1) | M29: =IF(K29<L29,"LOW","OK") | N29: =IF(K29<L29,A29,"") | O29: =IF(N29="",O28,IF(O28="",N29,O28&", "&N29))
A30: DPG (Dipropylene Glycol) | B30: 500 | C30: g | D30: 1 | F30: =IF(C30="ml",B30*D30*E30,B30*D30) | G30: 50 | H30: =G30*D30 | I30: =IF(F30=0,0,H30/F30) | J30: =TotalConcUsedG*D10ActivePct*0.9 | K30: =F30-J30 | L30: =2*DefaultBatchConcG*D10ActivePct*0.9 | M30: =IF(K30<L30,"LOW","OK") | N30: =IF(K30<L30,A30,"") | O30: =IF(N30="",O29,IF(O29="",N30,O29&", "&N30))
A31: Alcohol 190 proof SDA 40B | B31: 1000 | C31: ml | D31: 1 | E31: 0.81 | F31: =IF(C31="ml",B31*D31*E31,B31*D31) | G31: 150 | H31: =G31*D31 | I31: =IF(F31=0,0,H31/F31) | J31: =AlcoholUsedG | K31: =F31-J31 | L31: =2*DefaultBatchAlcG | M31: =IF(K31<L31,"LOW","OK") | N31: =IF(K31<L31,A31,"") | O31: =IF(N31="",O30,IF(O30="",N31,O30&", "&N31))
A32: TOTAL PAID (SAR) | H32: =SUM(H4:H31)

Sheet Production Log
A1: PRODUCTION LOG
A2: One row per batch. Copy 'Concentrate (g)' and 'Alcohol (g)' from the Batch Calculator — Inventory and the Maceration Tracker update automatically.
A3: Maceration default (days): | C3: 42 | D3: Σ concentrate used (g): | F3: =SUM(LogConcG) | G3: Σ alcohol used (g): | I3: =SUM(LogAlcG)
A4: Date | B4: Batch ID | C4: Format | D4: Size | E4: Unit | F4: Conc % | G4: Concentrate (g) | H4: Alcohol (g) | I4: Macer. start | J4: Target end | K4: Status | L4: Notes
J5: =IF($I5="","",$I5+MacDays) | M5: =IF(AND($K5="Macerating",$I5<>""),$I5,"")
J6: =IF($I6="","",$I6+MacDays) | M6: =IF(AND($K6="Macerating",$I6<>""),$I6,"")
J7: =IF($I7="","",$I7+MacDays) | M7: =IF(AND($K7="Macerating",$I7<>""),$I7,"")
J8: =IF($I8="","",$I8+MacDays) | M8: =IF(AND($K8="Macerating",$I8<>""),$I8,"")
J9: =IF($I9="","",$I9+MacDays) | M9: =IF(AND($K9="Macerating",$I9<>""),$I9,"")
J10: =IF($I10="","",$I10+MacDays) | M10: =IF(AND($K10="Macerating",$I10<>""),$I10,"")
J11: =IF($I11="","",$I11+MacDays) | M11: =IF(AND($K11="Macerating",$I11<>""),$I11,"")
J12: =IF($I12="","",$I12+MacDays) | M12: =IF(AND($K12="Macerating",$I12<>""),$I12,"")
J13: =IF($I13="","",$I13+MacDays) | M13: =IF(AND($K13="Macerating",$I13<>""),$I13,"")
J14: =IF($I14="","",$I14+MacDays) | M14: =IF(AND($K14="Macerating",$I14<>""),$I14,"")
J15: =IF($I15="","",$I15+MacDays) | M15: =IF(AND($K15="Macerating",$I15<>""),$I15,"")
J16: =IF($I16="","",$I16+MacDays) | M16: =IF(AND($K16="Macerating",$I16<>""),$I16,"")
... J44: =IF($I44="","",$I44+MacDays) | M44: =IF(AND($K44="Macerating",$I44<>""),$I44,"")

Sheet Maceration Tracker
A1: MACERATION TRACKER
A2: Auto-view of the Production Log. Amber = early (< 2 weeks) · Green = ready window (4–8 weeks).
A4: Batch ID | B4: Format | C4: Start | D4: Target end | E4: Days elapsed | F4: Days remaining | G4: Weeks | H4: Status | I4: Readiness
A5: =IF('Production Log'!B5="","",'Production Log'!B5) | B5: =IF('Production Log'!C5="","",'Production Log'!C5) | C5: =IF('Production Log'!I5="","",'Production Log'!I5) | D5: =IF('Production Log'!J5="","",'Production Log'!J5) | E5: =IF($C5="","",TODAY()-$C5) | F5: =IF($D5="","",$D5-TODAY()) | G5: =IF($C5="","",(TODAY()-$C5)/7) | H5: =IF('Production Log'!K5="","",'Production Log'!K5) | I5: =IF($A5="","",IF($H5="Bottled","BOTTLED ✓",IF($C5="","awaiting start date",IF(TODAY()-$C5>=56,"PAST WINDOW — bottle now",IF(TODAY()-$C5>=28,"READY WINDOW (4–8 wk)",IF(TODAY()-$C5>=14,"developing","early — keep dark & cool"))))))
A6: =IF('Production Log'!B6="","",'Production Log'!B6) | B6: =IF('Production Log'!C6="","",'Production Log'!C6) | C6: =IF('Production Log'!I6="","",'Production Log'!I6) | D6: =IF('Production Log'!J6="","",'Production Log'!J6) | E6: =IF($C6="","",TODAY()-$C6) | F6: =IF($D6="","",$D6-TODAY()) | G6: =IF($C6="","",(TODAY()-$C6)/7) | H6: =IF('Production Log'!K6="","",'Production Log'!K6) | I6: =IF($A6="","",IF($H6="Bottled","BOTTLED ✓",IF($C6="","awaiting start date",IF(TODAY()-$C6>=56,"PAST WINDOW — bottle now",IF(TODAY()-$C6>=28,"READY WINDOW (4–8 wk)",IF(TODAY()-$C6>=14,"developing","early — keep dark & cool"))))))
A7: =IF('Production Log'!B7="","",'Production Log'!B7) | B7: =IF('Production Log'!C7="","",'Production Log'!C7) | C7: =IF('Production Log'!I7="","",'Production Log'!I7) | D7: =IF('Production Log'!J7="","",'Production Log'!J7) | E7: =IF($C7="","",TODAY()-$C7) | F7: =IF($D7="","",$D7-TODAY()) | G7: =IF($C7="","",(TODAY()-$C7)/7) | H7: =IF('Production Log'!K7="","",'Production Log'!K7) | I7: =IF($A7="","",IF($H7="Bottled","BOTTLED ✓",IF($C7="","awaiting start date",IF(TODAY()-$C7>=56,"PAST WINDOW — bottle now",IF(TODAY()-$C7>=28,"READY WINDOW (4–8 wk)",IF(TODAY()-$C7>=14,"developing","early — keep dark & cool"))))))
A8: =IF('Production Log'!B8="","",'Production Log'!B8) | B8: =IF('Production Log'!C8="","",'Production Log'!C8) | C8: =IF('Production Log'!I8="","",'Production Log'!I8) | D8: =IF('Production Log'!J8="","",'Production Log'!J8) | E8: =IF($C8="","",TODAY()-$C8) | F8: =IF($D8="","",$D8-TODAY()) | G8: =IF($C8="","",(TODAY()-$C8)/7) | H8: =IF('Production Log'!K8="","",'Production Log'!K8) | I8: =IF($A8="","",IF($H8="Bottled","BOTTLED ✓",IF($C8="","awaiting start date",IF(TODAY()-$C8>=56,"PAST WINDOW — bottle now",IF(TODAY()-$C8>=28,"READY WINDOW (4–8 wk)",IF(TODAY()-$C8>=14,"developing","early — keep dark & cool"))))))
A9: =IF('Production Log'!B9="","",'Production Log'!B9) | B9: =IF('Production Log'!C9="","",'Production Log'!C9) | C9: =IF('Production Log'!I9="","",'Production Log'!I9) | D9: =IF('Production Log'!J9="","",'Production Log'!J9) | E9: =IF($C9="","",TODAY()-$C9) | F9: =IF($D9="","",$D9-TODAY()) | G9: =IF($C9="","",(TODAY()-$C9)/7) | H9: =IF('Production Log'!K9="","",'Production Log'!K9) | I9: =IF($A9="","",IF($H9="Bottled","BOTTLED ✓",IF($C9="","awaiting start date",IF(TODAY()-$C9>=56,"PAST WINDOW — bottle now",IF(TODAY()-$C9>=28,"READY WINDOW (4–8 wk)",IF(TODAY()-$C9>=14,"developing","early — keep dark & cool"))))))
A10: =IF('Production Log'!B10="","",'Production Log'!B10) | B10: =IF('Production Log'!C10="","",'Production Log'!C10) | C10: =IF('Production Log'!I10="","",'Production Log'!I10) | D10: =IF('Production Log'!J10="","",'Production Log'!J10) | E10: =IF($C10="","",TODAY()-$C10) | F10: =IF($D10="","",$D10-TODAY()) | G10: =IF($C10="","",(TODAY()-$C10)/7) | H10: =IF('Production Log'!K10="","",'Production Log'!K10) | I10: =IF($A10="","",IF($H10="Bottled","BOTTLED ✓",IF($C10="","awaiting start date",IF(TODAY()-$C10>=56,"PAST WINDOW — bottle now",IF(TODAY()-$C10>=28,"READY WINDOW (4–8 wk)",IF(TODAY()-$C10>=14,"developing","early — keep dark & cool"))))))
A11: =IF('Production Log'!B11="","",'Production Log'!B11) | B11: =IF('Production Log'!C11="","",'Production Log'!C11) | C11: =IF('Production Log'!I11="","",'Production Log'!I11) | D11: =IF('Production Log'!J11="","",'Production Log'!J11) | E11: =IF($C11="","",TODAY()-$C11) | F11: =IF($D11="","",$D11-TODAY()) | G11: =IF($C11="","",(TODAY()-$C11)/7) | H11: =IF('Production Log'!K11="","",'Production Log'!K11) | I11: =IF($A11="","",IF($H11="Bottled","BOTTLED ✓",IF($C11="","awaiting start date",IF(TODAY()-$C11>=56,"PAST WINDOW — bottle now",IF(TODAY()-$C11>=28,"READY WINDOW (4–8 wk)",IF(TODAY()-$C11>=14,"developing","early — keep dark & cool"))))))
A12: =IF('Production Log'!B12="","",'Production Log'!B12) | B12: =IF('Production Log'!C12="","",'Production Log'!C12) | C12: =IF('Production Log'!I12="","",'Production Log'!I12) | D12: =IF('Production Log'!J12="","",'Production Log'!J12) | E12: =IF($C12="","",TODAY()-$C12) | F12: =IF($D12="","",$D12-TODAY()) | G12: =IF($C12="","",(TODAY()-$C12)/7) | H12: =IF('Production Log'!K12="","",'Production Log'!K12) | I12: =IF($A12="","",IF($H12="Bottled","BOTTLED ✓",IF($C12="","awaiting start date",IF(TODAY()-$C12>=56,"PAST WINDOW — bottle now",IF(TODAY()-$C12>=28,"READY WINDOW (4–8 wk)",IF(TODAY()-$C12>=14,"developing","early — keep dark & cool"))))))
A13: =IF('Production Log'!B13="","",'Production Log'!B13) | B13: =IF('Production Log'!C13="","",'Production Log'!C13) | C13: =IF('Production Log'!I13="","",'Production Log'!I13) | D13: =IF('Production Log'!J13="","",'Production Log'!J13) | E13: =IF($C13="","",TODAY()-$C13) | F13: =IF($D13="","",$D13-TODAY()) | G13: =IF($C13="","",(TODAY()-$C13)/7) | H13: =IF('Production Log'!K13="","",'Production Log'!K13) | I13: =IF($A13="","",IF($H13="Bottled","BOTTLED ✓",IF($C13="","awaiting start date",IF(TODAY()-$C13>=56,"PAST WINDOW — bottle now",IF(TODAY()-$C13>=28,"READY WINDOW (4–8 wk)",IF(TODAY()-$C13>=14,"developing","early — keep dark & cool"))))))
A14: =IF('Production Log'!B14="","",'Production Log'!B14) | B14: =IF('Production Log'!C14="","",'Production Log'!C14) | C14: =IF('Production Log'!I14="","",'Production Log'!I14) | D14: =IF('Production Log'!J14="","",'Production Log'!J14) | E14: =IF($C14="","",TODAY()-$C14) | F14: =IF($D14="","",$D14-TODAY()) | G14: =IF($C14="","",(TODAY()-$C14)/7) | H14: =IF('Production Log'!K14="","",'Production Log'!K14) | I14: =IF($A14="","",IF($H14="Bottled","BOTTLED ✓",IF($C14="","awaiting start date",IF(TODAY()-$C14>=56,"PAST WINDOW — bottle now",IF(TODAY()-$C14>=28,"READY WINDOW (4–8 wk)",IF(TODAY()-$C14>=14,"developing","early — keep dark & cool"))))))
A15: =IF('Production Log'!B15="","",'Production Log'!B15) | B15: =IF('Production Log'!C15="","",'Production Log'!C15) | C15: =IF('Production Log'!I15="","",'Production Log'!I15) | D15: =IF('Production Log'!J15="","",'Production Log'!J15) | E15: =IF($C15="","",TODAY()-$C15) | F15: =IF($D15="","",$D15-TODAY()) | G15: =IF($C15="","",(TODAY()-$C15)/7) | H15: =IF('Production Log'!K15="","",'Production Log'!K15) | I15: =IF($A15="","",IF($H15="Bottled","BOTTLED ✓",IF($C15="","awaiting start date",IF(TODAY()-$C15>=56,"PAST WINDOW — bottle now",IF(TODAY()-$C15>=28,"READY WINDOW (4–8 wk)",IF(TODAY()-$C15>=14,"developing","early — keep dark & cool"))))))
A16: =IF('Production Log'!B16="","",'Production Log'!B16) | B16: =IF('Production Log'!C16="","",'Production Log'!C16) | C16: =IF('Production Log'!I16="","",'Production Log'!I16) | D16: =IF('Production Log'!J16="","",'Production Log'!J16) | E16: =IF($C16="","",TODAY()-$C16) | F16: =IF($D16="","",$D16-TODAY()) | G16: =IF($C16="","",(TODAY()-$C16)/7) | H16: =IF('Production Log'!K16="","",'Production Log'!K16) | I16: =IF($A16="","",IF($H16="Bottled","BOTTLED ✓",IF($C16="","awaiting start date",IF(TODAY()-$C16>=56,"PAST WINDOW — bottle now",IF(TODAY()-$C16>=28,"READY WINDOW (4–8 wk)",IF(TODAY()-$C16>=14,"developing","early — keep dark & cool"))))))
... A44: =IF('Production Log'!B44="","",'Production Log'!B44) | B44: =IF('Production Log'!C44="","",'Production Log'!C44) | C44: =IF('Production Log'!I44="","",'Production Log'!I44) | D44: =IF('Production Log'!J44="","",'Production Log'!J44) | E44: =IF($C44="","",TODAY()-$C44) | F44: =IF($D44="","",$D44-TODAY()) | G44: =IF($C44="","",(TODAY()-$C44)/7) | H44: =IF('Production Log'!K44="","",'Production Log'!K44) | I44: =IF($A44="","",IF($H44="Bottled","BOTTLED ✓",IF($C44="","awaiting start date",IF(TODAY()-$C44>=56,"PAST WINDOW — bottle now",IF(TODAY()-$C44>=28,"READY WINDOW (4–8 wk)",IF(TODAY()-$C44>=14,"developing","early — keep dark & cool"))))))

Sheet Cost Analysis
A1: COST ANALYSIS
A2: Shipping is allocated proportionally over all materials via the load factor. All figures update live.
A3: A · CAPITAL
A4: Materials purchased (SAR) | C4: =SUM(Inv_TotalPaid) | D4: from Inventory
A5: International shipping (SAR) | C5: 351 | D5: allocated proportionally below
A6: TOTAL CAPITAL (SAR) | C6: =C4+C5
A7: Shipping load factor | C7: =1+ShippingSAR/MaterialsTotalSAR | D7: multiplier applied to material costs
A9: B · CONCENTRATE COST
A10: DPG price (SAR/g) | C10: =INDEX(Inv_PricePerG,MATCH("DPG (Dipropylene Glycol)",Inv_Mat,0)) | D10: carrier for the D10 dilutions
A11: Concentrate cost (SAR/g) | C11: =SUMPRODUCT(FM_Active,FM_CostG) | D11: formula-weighted from Inventory prices; D10 lines = 10% neat + 90% DPG
A12: … incl. shipping (SAR/g) | C12: =ConcCostPerG*ShipLoad | D12: used everywhere costs are quoted
A14: C · AUXILIARY COSTS (SAR/g — editable estimates)
A15: Component | C15: SAR/g | D15: Note
A16: Alcohol 190 proof SDA 40B | C16: =INDEX(Inv_PricePerG,MATCH("Alcohol 190 proof SDA 40B",Inv_Mat,0))*ShipLoad | D16: from Inventory × shipping load
A17: Distilled water | C17: 0.01 | D17: estimate — edit to actual
A18: Glycerin | C18: 0.05 | D18: estimate — edit to actual
A19: Polysorbate 20 | C19: 0.1 | D19: estimate — edit to actual
A20: Preservative (broad-spectrum) | C20: 0.4 | D20: estimate — edit to actual
A21: Unscented cream base | C21: 0.08 | D21: estimate — edit to actual
A22: Emulsifying Wax NF | C22: 0.15 | D22: estimate — edit to actual
A23: Cetearyl alcohol | C23: 0.1 | D23: estimate — edit to actual
A24: Carrier oil (light) | C24: 0.06 | D24: estimate — edit to actual
A25: Shea / mango butter | C25: 0.08 | D25: estimate — edit to actual
A26: Vitamin E | C26: 0.5 | D26: estimate — edit to actual
A28: D · COST PER BOTTLE / JAR (finished product)
A29: Product | B29: Size | C29: Unit | D29: Density | E29: Total (g) | F29: Conc % | G29: Conc (g) | H29: Cost SAR | I29: SAR per ml / g
A30: Eau de Parfum | B30: 30 | C30: ml | D30: 0.85 | E30: =IF(C30="ml",B30*D30,B30) | F30: 0.2 | G30: =E30*F30 | H30: =G30*ConcCostPerGLoaded+(E30-G30)*$C$16 | I30: =H30/B30
A31: Eau de Parfum | B31: 50 | C31: ml | D31: 0.85 | E31: =IF(C31="ml",B31*D31,B31) | F31: 0.2 | G31: =E31*F31 | H31: =G31*ConcCostPerGLoaded+(E31-G31)*$C$16 | I31: =H31/B31
A32: Eau de Parfum | B32: 100 | C32: ml | D32: 0.85 | E32: =IF(C32="ml",B32*D32,B32) | F32: 0.2 | G32: =E32*F32 | H32: =G32*ConcCostPerGLoaded+(E32-G32)*$C$16 | I32: =H32/B32
A33: Extrait de Parfum | B33: 50 | C33: ml | D33: 0.85 | E33: =IF(C33="ml",B33*D33,B33) | F33: 0.28 | G33: =E33*F33 | H33: =G33*ConcCostPerGLoaded+(E33-G33)*$C$16 | I33: =H33/B33
A34: Alcohol Body Mist | B34: 100 | C34: ml | D34: 0.87 | E34: =IF(C34="ml",B34*D34,B34) | F34: 0.05 | G34: =E34*F34 | H34: =G34*ConcCostPerGLoaded+(E34-G34-E34*0.02-E34*0.05)*$C$16+E34*0.02*$C$18+E34*0.05*$C$17 | I34: =H34/B34
A35: Water-Based Mist | B35: 100 | C35: g | E35: =IF(C35="ml",B35*D35,B35) | F35: 0.025 | G35: =E35*F35 | H35: =G35*ConcCostPerGLoaded+G35*4*$C$19+E35*0.025*$C$18+E35*0.008*$C$20+(E35-G35-G35*4-E35*0.025-E35*0.008)*$C$17 | I35: =H35/B35
A36: Cream Route 1 | B36: 100 | C36: g | E36: =IF(C36="ml",B36*D36,B36) | F36: 0.01 | G36: =E36*F36 | H36: =G36*ConcCostPerGLoaded+(E36-G36)*$C$21 | I36: =H36/B36
A37: Cream Route 2 | B37: 100 | C37: g | E37: =IF(C37="ml",B37*D37,B37) | F37: 0.01 | G37: =E37*F37 | H37: =G37*ConcCostPerGLoaded+E37*(0.03*$C$18+0.05*$C$22+0.02*$C$23+0.15*$C$24+0.05*$C$25+0.01*$C$20+0.005*$C$26)+(E37-G37-E37*0.315)*$C$17 | I37: =H37/B37
A39: E · REMAINING STOCK VALUE
A40: Stock value at purchase prices (SAR) | C40: =SUMPRODUCT(Inv_OnHand,Inv_PricePerG)
A41: … incl. shipping allocation (SAR) | C41: =StockValueSAR*ShipLoad

Sheet Yield & Capacity
A1: YIELD & CAPACITY
A2: How many bottles your CURRENT inventory can make. Every cell is live — it updates as you log batches and as prices change.
A3: 1 · ASSUMPTIONS
A4: Concentrate % | C4: 0.28 | D4: 28% = Extrait (default). Set 20% to model EDP.
A5: Finished density (g/ml) | C5: 0.85 | D5: converts bottle ml → grams
A6: Bench-loss allowance % | C6: 0 | D6: residue lost in beakers/pipettes; try 5% for realism
A7: Stock basis | C7: On hand | D7: ‘On hand’ = live remaining stock · ‘Purchased’ = total bought
A9: 2 · CURRENT LIMITS
B10: MAX CONCENTRATE (g) | C10: USABLE AFTER LOSS (g) | D10: ALCOHOL ON HAND (g) | E10: DPG ON HAND (g) | F10: LIMITING MATERIAL
B11: =MIN($F$27:$F$52) | C11: =$B$11*(1-YC_Loss) | D11: =IF(YC_Basis="On hand",INDEX(Inv_OnHand,MATCH("Alcohol 190 proof SDA 40B",Inv_Mat,0)),INDEX(Inv_GramsBought,MATCH("Alcohol 190 proof SDA 40B",Inv_Mat,0))) | E11: =IF(YC_Basis="On hand",INDEX(Inv_OnHand,MATCH("DPG (Dipropylene Glycol)",Inv_Mat,0)),INDEX(Inv_GramsBought,MATCH("DPG (Dipropylene Glycol)",Inv_Mat,0))) | F11: =IF(COUNT($F$27:$F$52)=0,"—",INDEX($A$27:$A$52,MATCH($B$11,$F$27:$F$52,0)))
A13: 3 · BOTTLE YIELD
A14: ="At "&TEXT(YC_ConcPct,"0%")&" concentrate ("&IF(YC_ConcPct>=0.25,"Extrait",IF(YC_ConcPct>=0.15,"EDP","light"))&"), "&TEXT(YC_Density,"0.00")&" g/ml, "&TEXT(YC_Loss,"0%")&" bench loss, stock basis: "&YC_Basis
A15: Bottle size (ml) | B15: Conc / bottle (g) | C15: Alcohol / bottle (g) | D15: Bottles by conc. | E15: Bottles by alcohol | F15: BOTTLES | G15: Cost / bottle (SAR) | H15: Batch materials (SAR) | I15: Limiting factor
A16: 10 | B16: =$A16*YC_Density*YC_ConcPct | C16: =$A16*YC_Density*(1-YC_ConcPct) | D16: =IF(B16=0,"",YC_UsableConc/B16) | E16: =IF(C16=0,"",YC_AlcOnHand/C16) | F16: =FLOOR(MIN(D16,E16),1) | G16: =B16*ConcCostPerGLoaded+C16*AlcCostPerG | H16: =F16*G16 | I16: =IF(D16<=E16,"concentrate ("&YC_LimitMat&")","alcohol")
A17: 20 | B17: =$A17*YC_Density*YC_ConcPct | C17: =$A17*YC_Density*(1-YC_ConcPct) | D17: =IF(B17=0,"",YC_UsableConc/B17) | E17: =IF(C17=0,"",YC_AlcOnHand/C17) | F17: =FLOOR(MIN(D17,E17),1) | G17: =B17*ConcCostPerGLoaded+C17*AlcCostPerG | H17: =F17*G17 | I17: =IF(D17<=E17,"concentrate ("&YC_LimitMat&")","alcohol")
A18: 30 | B18: =$A18*YC_Density*YC_ConcPct | C18: =$A18*YC_Density*(1-YC_ConcPct) | D18: =IF(B18=0,"",YC_UsableConc/B18) | E18: =IF(C18=0,"",YC_AlcOnHand/C18) | F18: =FLOOR(MIN(D18,E18),1) | G18: =B18*ConcCostPerGLoaded+C18*AlcCostPerG | H18: =F18*G18 | I18: =IF(D18<=E18,"concentrate ("&YC_LimitMat&")","alcohol")
A19: 50 | B19: =$A19*YC_Density*YC_ConcPct | C19: =$A19*YC_Density*(1-YC_ConcPct) | D19: =IF(B19=0,"",YC_UsableConc/B19) | E19: =IF(C19=0,"",YC_AlcOnHand/C19) | F19: =FLOOR(MIN(D19,E19),1) | G19: =B19*ConcCostPerGLoaded+C19*AlcCostPerG | H19: =F19*G19 | I19: =IF(D19<=E19,"concentrate ("&YC_LimitMat&")","alcohol")
A20: 70 | B20: =$A20*YC_Density*YC_ConcPct | C20: =$A20*YC_Density*(1-YC_ConcPct) | D20: =IF(B20=0,"",YC_UsableConc/B20) | E20: =IF(C20=0,"",YC_AlcOnHand/C20) | F20: =FLOOR(MIN(D20,E20),1) | G20: =B20*ConcCostPerGLoaded+C20*AlcCostPerG | H20: =F20*G20 | I20: =IF(D20<=E20,"concentrate ("&YC_LimitMat&")","alcohol")
A21: 100 | B21: =$A21*YC_Density*YC_ConcPct | C21: =$A21*YC_Density*(1-YC_ConcPct) | D21: =IF(B21=0,"",YC_UsableConc/B21) | E21: =IF(C21=0,"",YC_AlcOnHand/C21) | F21: =FLOOR(MIN(D21,E21),1) | G21: =B21*ConcCostPerGLoaded+C21*AlcCostPerG | H21: =F21*G21 | I21: =IF(D21<=E21,"concentrate ("&YC_LimitMat&")","alcohol")
A22: ="To make more, buy more "&YC_LimitMat&" — it runs out first. See the material-by-material table below for the next bottlenecks."
A24: 4 · MATERIAL-BY-MATERIAL CAPACITY (which runs out first)
A26: Material | B26: Phase | C26: Active % | D26: Stock (g) | E26: Neat / g conc | F26: Max concentrate (g) | G26: Max 50 ml bottles
A27: ='Formula Master'!$B$7 | B27: ='Formula Master'!$A$7 | C27: ='Formula Master'!$F$7 | D27: =IF(YC_Basis="On hand",INDEX(Inv_OnHand,MATCH($A27,Inv_Mat,0)),INDEX(Inv_GramsBought,MATCH($A27,Inv_Mat,0))) | E27: =C27*IF('Formula Master'!$D$7="D10",0.1,1) | F27: =IF(E27<=0,"",MAX(D27,0)/E27) | G27: =IF(F27="","",FLOOR(F27/(50*YC_Density*YC_ConcPct),1))
A28: ='Formula Master'!$B$8 | B28: ='Formula Master'!$A$8 | C28: ='Formula Master'!$F$8 | D28: =IF(YC_Basis="On hand",INDEX(Inv_OnHand,MATCH($A28,Inv_Mat,0)),INDEX(Inv_GramsBought,MATCH($A28,Inv_Mat,0))) | E28: =C28*IF('Formula Master'!$D$8="D10",0.1,1) | F28: =IF(E28<=0,"",MAX(D28,0)/E28) | G28: =IF(F28="","",FLOOR(F28/(50*YC_Density*YC_ConcPct),1))
A29: ='Formula Master'!$B$9 | B29: ='Formula Master'!$A$9 | C29: ='Formula Master'!$F$9 | D29: =IF(YC_Basis="On hand",INDEX(Inv_OnHand,MATCH($A29,Inv_Mat,0)),INDEX(Inv_GramsBought,MATCH($A29,Inv_Mat,0))) | E29: =C29*IF('Formula Master'!$D$9="D10",0.1,1) | F29: =IF(E29<=0,"",MAX(D29,0)/E29) | G29: =IF(F29="","",FLOOR(F29/(50*YC_Density*YC_ConcPct),1))
A30: ='Formula Master'!$B$10 | B30: ='Formula Master'!$A$10 | C30: ='Formula Master'!$F$10 | D30: =IF(YC_Basis="On hand",INDEX(Inv_OnHand,MATCH($A30,Inv_Mat,0)),INDEX(Inv_GramsBought,MATCH($A30,Inv_Mat,0))) | E30: =C30*IF('Formula Master'!$D$10="D10",0.1,1) | F30: =IF(E30<=0,"",MAX(D30,0)/E30) | G30: =IF(F30="","",FLOOR(F30/(50*YC_Density*YC_ConcPct),1))
A31: ='Formula Master'!$B$11 | B31: ='Formula Master'!$A$11 | C31: ='Formula Master'!$F$11 | D31: =IF(YC_Basis="On hand",INDEX(Inv_OnHand,MATCH($A31,Inv_Mat,0)),INDEX(Inv_GramsBought,MATCH($A31,Inv_Mat,0))) | E31: =C31*IF('Formula Master'!$D$11="D10",0.1,1) | F31: =IF(E31<=0,"",MAX(D31,0)/E31) | G31: =IF(F31="","",FLOOR(F31/(50*YC_Density*YC_ConcPct),1))
A32: ='Formula Master'!$B$12 | B32: ='Formula Master'!$A$12 | C32: ='Formula Master'!$F$12 | D32: =IF(YC_Basis="On hand",INDEX(Inv_OnHand,MATCH($A32,Inv_Mat,0)),INDEX(Inv_GramsBought,MATCH($A32,Inv_Mat,0))) | E32: =C32*IF('Formula Master'!$D$12="D10",0.1,1) | F32: =IF(E32<=0,"",MAX(D32,0)/E32) | G32: =IF(F32="","",FLOOR(F32/(50*YC_Density*YC_ConcPct),1))
A33: ='Formula Master'!$B$13 | B33: ='Formula Master'!$A$13 | C33: ='Formula Master'!$F$13 | D33: =IF(YC_Basis="On hand",INDEX(Inv_OnHand,MATCH($A33,Inv_Mat,0)),INDEX(Inv_GramsBought,MATCH($A33,Inv_Mat,0))) | E33: =C33*IF('Formula Master'!$D$13="D10",0.1,1) | F33: =IF(E33<=0,"",MAX(D33,0)/E33) | G33: =IF(F33="","",FLOOR(F33/(50*YC_Density*YC_ConcPct),1))
A34: ='Formula Master'!$B$14 | B34: ='Formula Master'!$A$14 | C34: ='Formula Master'!$F$14 | D34: =IF(YC_Basis="On hand",INDEX(Inv_OnHand,MATCH($A34,Inv_Mat,0)),INDEX(Inv_GramsBought,MATCH($A34,Inv_Mat,0))) | E34: =C34*IF('Formula Master'!$D$14="D10",0.1,1) | F34: =IF(E34<=0,"",MAX(D34,0)/E34) | G34: =IF(F34="","",FLOOR(F34/(50*YC_Density*YC_ConcPct),1))
A35: ='Formula Master'!$B$15 | B35: ='Formula Master'!$A$15 | C35: ='Formula Master'!$F$15 | D35: =IF(YC_Basis="On hand",INDEX(Inv_OnHand,MATCH($A35,Inv_Mat,0)),INDEX(Inv_GramsBought,MATCH($A35,Inv_Mat,0))) | E35: =C35*IF('Formula Master'!$D$15="D10",0.1,1) | F35: =IF(E35<=0,"",MAX(D35,0)/E35) | G35: =IF(F35="","",FLOOR(F35/(50*YC_Density*YC_ConcPct),1))
A36: ='Formula Master'!$B$16 | B36: ='Formula Master'!$A$16 | C36: ='Formula Master'!$F$16 | D36: =IF(YC_Basis="On hand",INDEX(Inv_OnHand,MATCH($A36,Inv_Mat,0)),INDEX(Inv_GramsBought,MATCH($A36,Inv_Mat,0))) | E36: =C36*IF('Formula Master'!$D$16="D10",0.1,1) | F36: =IF(E36<=0,"",MAX(D36,0)/E36) | G36: =IF(F36="","",FLOOR(F36/(50*YC_Density*YC_ConcPct),1))
A37: ='Formula Master'!$B$17 | B37: ='Formula Master'!$A$17 | C37: ='Formula Master'!$F$17 | D37: =IF(YC_Basis="On hand",INDEX(Inv_OnHand,MATCH($A37,Inv_Mat,0)),INDEX(Inv_GramsBought,MATCH($A37,Inv_Mat,0))) | E37: =C37*IF('Formula Master'!$D$17="D10",0.1,1) | F37: =IF(E37<=0,"",MAX(D37,0)/E37) | G37: =IF(F37="","",FLOOR(F37/(50*YC_Density*YC_ConcPct),1))
A38: ='Formula Master'!$B$18 | B38: ='Formula Master'!$A$18 | C38: ='Formula Master'!$F$18 | D38: =IF(YC_Basis="On hand",INDEX(Inv_OnHand,MATCH($A38,Inv_Mat,0)),INDEX(Inv_GramsBought,MATCH($A38,Inv_Mat,0))) | E38: =C38*IF('Formula Master'!$D$18="D10",0.1,1) | F38: =IF(E38<=0,"",MAX(D38,0)/E38) | G38: =IF(F38="","",FLOOR(F38/(50*YC_Density*YC_ConcPct),1))
A39: ='Formula Master'!$B$19 | B39: ='Formula Master'!$A$19 | C39: ='Formula Master'!$F$19 | D39: =IF(YC_Basis="On hand",INDEX(Inv_OnHand,MATCH($A39,Inv_Mat,0)),INDEX(Inv_GramsBought,MATCH($A39,Inv_Mat,0))) | E39: =C39*IF('Formula Master'!$D$19="D10",0.1,1) | F39: =IF(E39<=0,"",MAX(D39,0)/E39) | G39: =IF(F39="","",FLOOR(F39/(50*YC_Density*YC_ConcPct),1))
A40: ='Formula Master'!$B$20 | B40: ='Formula Master'!$A$20 | C40: ='Formula Master'!$F$20 | D40: =IF(YC_Basis="On hand",INDEX(Inv_OnHand,MATCH($A40,Inv_Mat,0)),INDEX(Inv_GramsBought,MATCH($A40,Inv_Mat,0))) | E40: =C40*IF('Formula Master'!$D$20="D10",0.1,1) | F40: =IF(E40<=0,"",MAX(D40,0)/E40) | G40: =IF(F40="","",FLOOR(F40/(50*YC_Density*YC_ConcPct),1))
A41: ='Formula Master'!$B$21 | B41: ='Formula Master'!$A$21 | C41: ='Formula Master'!$F$21 | D41: =IF(YC_Basis="On hand",INDEX(Inv_OnHand,MATCH($A41,Inv_Mat,0)),INDEX(Inv_GramsBought,MATCH($A41,Inv_Mat,0))) | E41: =C41*IF('Formula Master'!$D$21="D10",0.1,1) | F41: =IF(E41<=0,"",MAX(D41,0)/E41) | G41: =IF(F41="","",FLOOR(F41/(50*YC_Density*YC_ConcPct),1))
A42: ='Formula Master'!$B$22 | B42: ='Formula Master'!$A$22 | C42: ='Formula Master'!$F$22 | D42: =IF(YC_Basis="On hand",INDEX(Inv_OnHand,MATCH($A42,Inv_Mat,0)),INDEX(Inv_GramsBought,MATCH($A42,Inv_Mat,0))) | E42: =C42*IF('Formula Master'!$D$22="D10",0.1,1) | F42: =IF(E42<=0,"",MAX(D42,0)/E42) | G42: =IF(F42="","",FLOOR(F42/(50*YC_Density*YC_ConcPct),1))
A43: ='Formula Master'!$B$23 | B43: ='Formula Master'!$A$23 | C43: ='Formula Master'!$F$23 | D43: =IF(YC_Basis="On hand",INDEX(Inv_OnHand,MATCH($A43,Inv_Mat,0)),INDEX(Inv_GramsBought,MATCH($A43,Inv_Mat,0))) | E43: =C43*IF('Formula Master'!$D$23="D10",0.1,1) | F43: =IF(E43<=0,"",MAX(D43,0)/E43) | G43: =IF(F43="","",FLOOR(F43/(50*YC_Density*YC_ConcPct),1))
A44: ='Formula Master'!$B$24 | B44: ='Formula Master'!$A$24 | C44: ='Formula Master'!$F$24 | D44: =IF(YC_Basis="On hand",INDEX(Inv_OnHand,MATCH($A44,Inv_Mat,0)),INDEX(Inv_GramsBought,MATCH($A44,Inv_Mat,0))) | E44: =C44*IF('Formula Master'!$D$24="D10",0.1,1) | F44: =IF(E44<=0,"",MAX(D44,0)/E44) | G44: =IF(F44="","",FLOOR(F44/(50*YC_Density*YC_ConcPct),1))
...

Sheet Process Reference
A1: PROCESS REFERENCE — SOPs
A2: Concise bench procedures. Work clean, work in grams, label everything.
A4: GOLDEN RULES
B5: Weigh in GRAMS on a 0.01 g scale — never count drops. Record every weight as you go.
B6: Sanitize glassware and tools with alcohol before each session. Change one variable at a time between trials.
B7: Label every container: ASMR · content · strength · date. Store everything dark and cool.
A9: EXTRAIT DE PARFUM 28% — THE MAIN PROCEDURE (alcohol)
B10: For a 50 ml bottle you will make 42.5 g of juice = 11.9 g concentrate + 30.6 g alcohol. Tip: making the full 5-bottle run at once (≈59.5 g concentrate) makes the tiny weights easier and wastes less.
B11: STEP 1 · PREP D10 DILUTIONS (a day ahead). Five ingredients are used as a 10%-in-DPG dilution: Pink Peppercorn, Floralozone, Safraleine, and (if kept) Irone Alpha + Javanol. For each, weigh 1.0 g neat + 9.0 g DPG = 10 g. See the Dilution Prep tab.
B12: STEP 2 · SET THE BATCH. On the Batch Calculator choose Extrait de Parfum, 50 ml, 28%. Print the Batch Sheet (one A4 page).
B13: STEP 3 · WEIGH THE CONCENTRATE, base first. Tare a clean glass beaker on a 0.01 g scale. Weigh BASE → HEART → TOP exactly as printed, taring between each and ticking every line. Weigh the D10 items as their dilution weight (the sheet's 'Weigh (g)' column).
B14: STEP 4 · MARRY. Stir gently 2–3 min until uniform. Cap and rest the neat concentrate 24–48 h in the dark — this lets the accord bloom before alcohol.
B15: STEP 5 · DILUTE. Weigh 30.6 g alcohol (190 proof SDA 40B) into the concentrate — not the other way round. Optional: up to 3% distilled water. Stir 1–2 min, cap.
B16: STEP 6 · MACERATE 4–8 weeks, dark and cool (a cupboard is fine). Swirl briefly once a day the first week. At 28% the extra weeks genuinely deepen the drydown — do not rush this.
B17: STEP 7 · COLD-CRASH. Chill 24 h in the fridge (~4 °C) so waxes/insolubles drop out.
B18: STEP 8 · FILTER cold through a coffee filter (or 0.45 µm) into the final bottle while still cold.
B19: STEP 9 · BOTTLE, label, and set the batch to 'Bottled' in the Production Log. Patch-test on skin before regular wear.
A21: ALCOHOL BODY MIST
